2020-04-24 14:40:24,693 -  nornir.core -     INFO -        run() - Running task 'napalm_get' with args {'getters': ['facts']} on 2 hosts
2020-04-24 14:47:27,214 -  nornir.core -     INFO -        run() - Running task 'napalm_get' with args {'getters': ['facts']} on 2 hosts
2020-04-24 14:48:09,157 -  nornir.core -     INFO -        run() - Running task 'napalm_get' with args {'getters': ['facts']} on 2 hosts
2020-04-24 14:49:43,012 -  nornir.core -     INFO -        run() - Running task 'napalm_get' with args {'getters': ['facts']} on 2 hosts
2020-04-24 14:51:47,581 -  nornir.core -     INFO -        run() - Running task 'napalm_get' with args {'getters': ['facts']} on 5 hosts
2020-04-24 14:52:16,623 - nornir.core.task -    ERROR -      start() - Host 'r4': task 'napalm_get' failed with traceback:
Traceback (most recent call last):
  File "/home/gns3/workspace/Nornir/.venv/lib/python3.6/site-packages/paramiko/channel.py", line 699, in recv
    out = self.in_buffer.read(nbytes, self.timeout)
  File "/home/gns3/workspace/Nornir/.venv/lib/python3.6/site-packages/paramiko/buffered_pipe.py", line 164, in read
    raise PipeTimeout()
paramiko.buffered_pipe.PipeTimeout

During handling of the above exception, another exception occurred:

Traceback (most recent call last):
  File "/home/gns3/workspace/Nornir/.venv/lib/python3.6/site-packages/netmiko/base_connection.py", line 550, in _read_channel_expect
    new_data = self.remote_conn.recv(MAX_BUFFER)
  File "/home/gns3/workspace/Nornir/.venv/lib/python3.6/site-packages/paramiko/channel.py", line 701, in recv
    raise socket.timeout()
socket.timeout

During handling of the above exception, another exception occurred:

Traceback (most recent call last):
  File "/home/gns3/workspace/Nornir/.venv/lib/python3.6/site-packages/nornir/core/task.py", line 85, in start
    r = self.task(self, **self.params)
  File "/home/gns3/workspace/Nornir/.venv/lib/python3.6/site-packages/nornir/plugins/tasks/networking/napalm_get.py", line 61, in napalm_get
    result[g] = method(**options)
  File "/home/gns3/workspace/Nornir/.venv/lib/python3.6/site-packages/napalm/iosxr/iosxr.py", line 163, in get_facts
    facts_rpc_reply = ETREE.fromstring(self.device.make_rpc_call(facts_rpc_request))
  File "/home/gns3/workspace/Nornir/.venv/lib/python3.6/site-packages/pyIOSXR/iosxr.py", line 151, in make_rpc_call
    result = self._execute_rpc(rpc_command)
  File "/home/gns3/workspace/Nornir/.venv/lib/python3.6/site-packages/pyIOSXR/iosxr.py", line 365, in _execute_rpc
    response = self._send_command(xml_rpc_command, delay_factor=delay_factor)
  File "/home/gns3/workspace/Nornir/.venv/lib/python3.6/site-packages/pyIOSXR/iosxr.py", line 275, in _send_command
    max_loops=max_loops)
  File "/home/gns3/workspace/Nornir/.venv/lib/python3.6/site-packages/netmiko/base_connection.py", line 1470, in send_command_expect
    return self.send_command(*args, **kwargs)
  File "/home/gns3/workspace/Nornir/.venv/lib/python3.6/site-packages/netmiko/utilities.py", line 347, in wrapper_decorator
    return func(self, *args, **kwargs)
  File "/home/gns3/workspace/Nornir/.venv/lib/python3.6/site-packages/netmiko/base_connection.py", line 1389, in send_command
    new_data = self.read_until_pattern(pattern=re.escape(cmd))
  File "/home/gns3/workspace/Nornir/.venv/lib/python3.6/site-packages/netmiko/base_connection.py", line 627, in read_until_pattern
    return self._read_channel_expect(*args, **kwargs)
  File "/home/gns3/workspace/Nornir/.venv/lib/python3.6/site-packages/netmiko/base_connection.py", line 561, in _read_channel_expect
    "Timed-out reading channel, data not available."
netmiko.ssh_exception.NetmikoTimeoutException: Timed-out reading channel, data not available.

2020-04-24 14:56:05,062 -  nornir.core -     INFO -        run() - Running task 'napalm_get' with args {'getters': ['facts']} on 5 hosts
2020-04-24 14:56:33,839 - nornir.core.task -    ERROR -      start() - Host 'r4': task 'napalm_get' failed with traceback:
Traceback (most recent call last):
  File "/home/gns3/workspace/Nornir/.venv/lib/python3.6/site-packages/paramiko/channel.py", line 699, in recv
    out = self.in_buffer.read(nbytes, self.timeout)
  File "/home/gns3/workspace/Nornir/.venv/lib/python3.6/site-packages/paramiko/buffered_pipe.py", line 164, in read
    raise PipeTimeout()
paramiko.buffered_pipe.PipeTimeout

During handling of the above exception, another exception occurred:

Traceback (most recent call last):
  File "/home/gns3/workspace/Nornir/.venv/lib/python3.6/site-packages/netmiko/base_connection.py", line 550, in _read_channel_expect
    new_data = self.remote_conn.recv(MAX_BUFFER)
  File "/home/gns3/workspace/Nornir/.venv/lib/python3.6/site-packages/paramiko/channel.py", line 701, in recv
    raise socket.timeout()
socket.timeout

During handling of the above exception, another exception occurred:

Traceback (most recent call last):
  File "/home/gns3/workspace/Nornir/.venv/lib/python3.6/site-packages/nornir/core/task.py", line 85, in start
    r = self.task(self, **self.params)
  File "/home/gns3/workspace/Nornir/.venv/lib/python3.6/site-packages/nornir/plugins/tasks/networking/napalm_get.py", line 61, in napalm_get
    result[g] = method(**options)
  File "/home/gns3/workspace/Nornir/.venv/lib/python3.6/site-packages/napalm/iosxr/iosxr.py", line 163, in get_facts
    facts_rpc_reply = ETREE.fromstring(self.device.make_rpc_call(facts_rpc_request))
  File "/home/gns3/workspace/Nornir/.venv/lib/python3.6/site-packages/pyIOSXR/iosxr.py", line 151, in make_rpc_call
    result = self._execute_rpc(rpc_command)
  File "/home/gns3/workspace/Nornir/.venv/lib/python3.6/site-packages/pyIOSXR/iosxr.py", line 365, in _execute_rpc
    response = self._send_command(xml_rpc_command, delay_factor=delay_factor)
  File "/home/gns3/workspace/Nornir/.venv/lib/python3.6/site-packages/pyIOSXR/iosxr.py", line 275, in _send_command
    max_loops=max_loops)
  File "/home/gns3/workspace/Nornir/.venv/lib/python3.6/site-packages/netmiko/base_connection.py", line 1470, in send_command_expect
    return self.send_command(*args, **kwargs)
  File "/home/gns3/workspace/Nornir/.venv/lib/python3.6/site-packages/netmiko/utilities.py", line 347, in wrapper_decorator
    return func(self, *args, **kwargs)
  File "/home/gns3/workspace/Nornir/.venv/lib/python3.6/site-packages/netmiko/base_connection.py", line 1389, in send_command
    new_data = self.read_until_pattern(pattern=re.escape(cmd))
  File "/home/gns3/workspace/Nornir/.venv/lib/python3.6/site-packages/netmiko/base_connection.py", line 627, in read_until_pattern
    return self._read_channel_expect(*args, **kwargs)
  File "/home/gns3/workspace/Nornir/.venv/lib/python3.6/site-packages/netmiko/base_connection.py", line 561, in _read_channel_expect
    "Timed-out reading channel, data not available."
netmiko.ssh_exception.NetmikoTimeoutException: Timed-out reading channel, data not available.

2020-04-24 14:56:52,343 -  nornir.core -     INFO -        run() - Running task 'napalm_get' with args {'getters': ['facts']} on 1 hosts
2020-04-24 14:57:20,634 - nornir.core.task -    ERROR -      start() - Host 'r4': task 'napalm_get' failed with traceback:
Traceback (most recent call last):
  File "/home/gns3/workspace/Nornir/.venv/lib/python3.6/site-packages/paramiko/channel.py", line 699, in recv
    out = self.in_buffer.read(nbytes, self.timeout)
  File "/home/gns3/workspace/Nornir/.venv/lib/python3.6/site-packages/paramiko/buffered_pipe.py", line 164, in read
    raise PipeTimeout()
paramiko.buffered_pipe.PipeTimeout

During handling of the above exception, another exception occurred:

Traceback (most recent call last):
  File "/home/gns3/workspace/Nornir/.venv/lib/python3.6/site-packages/netmiko/base_connection.py", line 550, in _read_channel_expect
    new_data = self.remote_conn.recv(MAX_BUFFER)
  File "/home/gns3/workspace/Nornir/.venv/lib/python3.6/site-packages/paramiko/channel.py", line 701, in recv
    raise socket.timeout()
socket.timeout

During handling of the above exception, another exception occurred:

Traceback (most recent call last):
  File "/home/gns3/workspace/Nornir/.venv/lib/python3.6/site-packages/nornir/core/task.py", line 85, in start
    r = self.task(self, **self.params)
  File "/home/gns3/workspace/Nornir/.venv/lib/python3.6/site-packages/nornir/plugins/tasks/networking/napalm_get.py", line 61, in napalm_get
    result[g] = method(**options)
  File "/home/gns3/workspace/Nornir/.venv/lib/python3.6/site-packages/napalm/iosxr/iosxr.py", line 163, in get_facts
    facts_rpc_reply = ETREE.fromstring(self.device.make_rpc_call(facts_rpc_request))
  File "/home/gns3/workspace/Nornir/.venv/lib/python3.6/site-packages/pyIOSXR/iosxr.py", line 151, in make_rpc_call
    result = self._execute_rpc(rpc_command)
  File "/home/gns3/workspace/Nornir/.venv/lib/python3.6/site-packages/pyIOSXR/iosxr.py", line 365, in _execute_rpc
    response = self._send_command(xml_rpc_command, delay_factor=delay_factor)
  File "/home/gns3/workspace/Nornir/.venv/lib/python3.6/site-packages/pyIOSXR/iosxr.py", line 275, in _send_command
    max_loops=max_loops)
  File "/home/gns3/workspace/Nornir/.venv/lib/python3.6/site-packages/netmiko/base_connection.py", line 1470, in send_command_expect
    return self.send_command(*args, **kwargs)
  File "/home/gns3/workspace/Nornir/.venv/lib/python3.6/site-packages/netmiko/utilities.py", line 347, in wrapper_decorator
    return func(self, *args, **kwargs)
  File "/home/gns3/workspace/Nornir/.venv/lib/python3.6/site-packages/netmiko/base_connection.py", line 1389, in send_command
    new_data = self.read_until_pattern(pattern=re.escape(cmd))
  File "/home/gns3/workspace/Nornir/.venv/lib/python3.6/site-packages/netmiko/base_connection.py", line 627, in read_until_pattern
    return self._read_channel_expect(*args, **kwargs)
  File "/home/gns3/workspace/Nornir/.venv/lib/python3.6/site-packages/netmiko/base_connection.py", line 561, in _read_channel_expect
    "Timed-out reading channel, data not available."
netmiko.ssh_exception.NetmikoTimeoutException: Timed-out reading channel, data not available.

2020-04-24 15:08:30,393 -  nornir.core -     INFO -        run() - Running task 'hi' with args {} on 5 hosts
2020-04-24 15:08:48,180 -  nornir.core -     INFO -        run() - Running task 'hi' with args {} on 5 hosts
2020-04-24 15:08:51,577 -  nornir.core -     INFO -        run() - Running task 'hi' with args {} on 5 hosts
2020-04-24 15:39:10,231 -  nornir.core -     INFO -        run() - Running task 'hi' with args {} on 5 hosts
2020-04-24 15:39:10,235 -  nornir.core -     INFO -        run() - Running task 'show_commands' with args {} on 2 hosts
2020-04-24 15:39:11,018 - nornir.core.task -    ERROR -      start() - Host 'r1': task 'napalm_cli' failed with traceback:
Traceback (most recent call last):
  File "/home/gns3/workspace/Nornir/.venv/lib/python3.6/site-packages/nornir/core/task.py", line 85, in start
    r = self.task(self, **self.params)
  File "/home/gns3/workspace/Nornir/.venv/lib/python3.6/site-packages/nornir/plugins/tasks/networking/napalm_cli.py", line 18, in napalm_cli
    result = device.cli(commands)
  File "/home/gns3/workspace/Nornir/.venv/lib/python3.6/site-packages/napalm/junos/junos.py", line 956, in cli
    raise TypeError("Please enter a valid list of commands!")
TypeError: Please enter a valid list of commands!

2020-04-24 15:39:11,019 - nornir.core.task -    ERROR -      start() - Host 'r1': task 'show_commands' failed with traceback:
Traceback (most recent call last):
  File "/home/gns3/workspace/Nornir/.venv/lib/python3.6/site-packages/nornir/core/task.py", line 85, in start
    r = self.task(self, **self.params)
  File "explore.py", line 24, in show_commands
    task.run(task=networking.napalm_cli, commands="show ip int bri")
  File "/home/gns3/workspace/Nornir/.venv/lib/python3.6/site-packages/nornir/core/task.py", line 147, in run
    raise NornirSubTaskError(task=task, result=r)
nornir.core.exceptions.NornirSubTaskError: Subtask: <function napalm_cli at 0x7f3122dd38c8> (failed)


2020-04-24 15:39:11,114 - nornir.core.task -    ERROR -      start() - Host 'r2': task 'napalm_cli' failed with traceback:
Traceback (most recent call last):
  File "/home/gns3/workspace/Nornir/.venv/lib/python3.6/site-packages/nornir/core/task.py", line 85, in start
    r = self.task(self, **self.params)
  File "/home/gns3/workspace/Nornir/.venv/lib/python3.6/site-packages/nornir/plugins/tasks/networking/napalm_cli.py", line 18, in napalm_cli
    result = device.cli(commands)
  File "/home/gns3/workspace/Nornir/.venv/lib/python3.6/site-packages/napalm/junos/junos.py", line 956, in cli
    raise TypeError("Please enter a valid list of commands!")
TypeError: Please enter a valid list of commands!

2020-04-24 15:39:11,115 - nornir.core.task -    ERROR -      start() - Host 'r2': task 'show_commands' failed with traceback:
Traceback (most recent call last):
  File "/home/gns3/workspace/Nornir/.venv/lib/python3.6/site-packages/nornir/core/task.py", line 85, in start
    r = self.task(self, **self.params)
  File "explore.py", line 24, in show_commands
    task.run(task=networking.napalm_cli, commands="show ip int bri")
  File "/home/gns3/workspace/Nornir/.venv/lib/python3.6/site-packages/nornir/core/task.py", line 147, in run
    raise NornirSubTaskError(task=task, result=r)
nornir.core.exceptions.NornirSubTaskError: Subtask: <function napalm_cli at 0x7f3122dd38c8> (failed)


2020-04-24 15:40:09,763 -  nornir.core -     INFO -        run() - Running task 'hi' with args {} on 5 hosts
2020-04-24 15:40:09,767 -  nornir.core -     INFO -        run() - Running task 'show_commands' with args {} on 2 hosts
2020-04-24 15:40:10,524 - nornir.core.task -    ERROR -      start() - Host 'r1': task 'napalm_cli' failed with traceback:
Traceback (most recent call last):
  File "/home/gns3/workspace/Nornir/.venv/lib/python3.6/site-packages/nornir/core/task.py", line 85, in start
    r = self.task(self, **self.params)
  File "/home/gns3/workspace/Nornir/.venv/lib/python3.6/site-packages/nornir/plugins/tasks/networking/napalm_cli.py", line 18, in napalm_cli
    result = device.cli(commands)
  File "/home/gns3/workspace/Nornir/.venv/lib/python3.6/site-packages/napalm/junos/junos.py", line 956, in cli
    raise TypeError("Please enter a valid list of commands!")
TypeError: Please enter a valid list of commands!

2020-04-24 15:40:10,524 - nornir.core.task -    ERROR -      start() - Host 'r1': task 'show_commands' failed with traceback:
Traceback (most recent call last):
  File "/home/gns3/workspace/Nornir/.venv/lib/python3.6/site-packages/nornir/core/task.py", line 85, in start
    r = self.task(self, **self.params)
  File "explore.py", line 24, in show_commands
    task.run(task=networking.napalm_cli, commands="show ip int bri")
  File "/home/gns3/workspace/Nornir/.venv/lib/python3.6/site-packages/nornir/core/task.py", line 147, in run
    raise NornirSubTaskError(task=task, result=r)
nornir.core.exceptions.NornirSubTaskError: Subtask: <function napalm_cli at 0x7fd2e39338c8> (failed)


2020-04-24 15:40:10,642 - nornir.core.task -    ERROR -      start() - Host 'r2': task 'napalm_cli' failed with traceback:
Traceback (most recent call last):
  File "/home/gns3/workspace/Nornir/.venv/lib/python3.6/site-packages/nornir/core/task.py", line 85, in start
    r = self.task(self, **self.params)
  File "/home/gns3/workspace/Nornir/.venv/lib/python3.6/site-packages/nornir/plugins/tasks/networking/napalm_cli.py", line 18, in napalm_cli
    result = device.cli(commands)
  File "/home/gns3/workspace/Nornir/.venv/lib/python3.6/site-packages/napalm/junos/junos.py", line 956, in cli
    raise TypeError("Please enter a valid list of commands!")
TypeError: Please enter a valid list of commands!

2020-04-24 15:40:10,642 - nornir.core.task -    ERROR -      start() - Host 'r2': task 'show_commands' failed with traceback:
Traceback (most recent call last):
  File "/home/gns3/workspace/Nornir/.venv/lib/python3.6/site-packages/nornir/core/task.py", line 85, in start
    r = self.task(self, **self.params)
  File "explore.py", line 24, in show_commands
    task.run(task=networking.napalm_cli, commands="show ip int bri")
  File "/home/gns3/workspace/Nornir/.venv/lib/python3.6/site-packages/nornir/core/task.py", line 147, in run
    raise NornirSubTaskError(task=task, result=r)
nornir.core.exceptions.NornirSubTaskError: Subtask: <function napalm_cli at 0x7fd2e39338c8> (failed)


2020-04-24 15:40:58,509 -  nornir.core -     INFO -        run() - Running task 'hi' with args {} on 5 hosts
2020-04-24 15:40:58,513 -  nornir.core -     INFO -        run() - Running task 'show_commands' with args {} on 2 hosts
2020-04-24 15:44:23,300 -  nornir.core -     INFO -        run() - Running task 'hi' with args {} on 5 hosts
2020-04-24 15:44:23,303 -  nornir.core -     INFO -        run() - Running task 'show_commands' with args {} on 2 hosts
2020-04-24 16:08:04,904 -  nornir.core -     INFO -        run() - Running task 'hi' with args {} on 5 hosts
2020-04-24 16:08:04,908 -  nornir.core -     INFO -        run() - Running task 'show_commands' with args {} on 2 hosts
2020-04-24 16:10:12,365 -  nornir.core -     INFO -        run() - Running task 'hi' with args {} on 5 hosts
2020-04-24 16:10:12,369 -  nornir.core -     INFO -        run() - Running task 'show_commands' with args {} on 2 hosts
2020-04-24 16:33:43,041 -  nornir.core -     INFO -        run() - Running task 'basic_configuration' with args {} on 2 hosts
2020-04-24 16:33:44,060 - nornir.core.task -    ERROR -      start() - Host 'r1': task 'Loading Configuration on the device' failed with traceback:
Traceback (most recent call last):
  File "/home/gns3/workspace/Nornir/.venv/lib/python3.6/site-packages/jnpr/junos/device.py", line 777, in execute
    ignore_warning=ignore_warning)
  File "/home/gns3/workspace/Nornir/.venv/lib/python3.6/site-packages/jnpr/junos/decorators.py", line 169, in wrapper
    raise ex
  File "/home/gns3/workspace/Nornir/.venv/lib/python3.6/site-packages/jnpr/junos/decorators.py", line 116, in wrapper
    rsp = function(self, *args, **kwargs)
  File "/home/gns3/workspace/Nornir/.venv/lib/python3.6/site-packages/jnpr/junos/device.py", line 1339, in _rpc_reply
    return self._conn.rpc(rpc_cmd_e)._NCElement__doc
  File "/home/gns3/workspace/Nornir/.venv/lib/python3.6/site-packages/ncclient/manager.py", line 236, in execute
    huge_tree=self._huge_tree).request(*args, **kwds)
  File "/home/gns3/workspace/Nornir/.venv/lib/python3.6/site-packages/ncclient/operations/third_party/juniper/rpc.py", line 52, in request
    return self._request(rpc)
  File "/home/gns3/workspace/Nornir/.venv/lib/python3.6/site-packages/ncclient/operations/rpc.py", line 348, in _request
    raise self._reply.error
ncclient.operations.rpc.RPCError: syntax error, expecting '}', ';', or '{'

During handling of the above exception, another exception occurred:

Traceback (most recent call last):
  File "/home/gns3/workspace/Nornir/.venv/lib/python3.6/site-packages/jnpr/junos/utils/config.py", line 456, in try_load
    **rpc_xattrs)
  File "/home/gns3/workspace/Nornir/.venv/lib/python3.6/site-packages/jnpr/junos/rpcmeta.py", line 277, in load_config
    return self._junos.execute(rpc, ignore_warning=ignore_warning)
  File "/home/gns3/workspace/Nornir/.venv/lib/python3.6/site-packages/jnpr/junos/decorators.py", line 76, in wrapper
    return function(*args, **kwargs)
  File "/home/gns3/workspace/Nornir/.venv/lib/python3.6/site-packages/jnpr/junos/decorators.py", line 31, in wrapper
    return function(*args, **kwargs)
  File "/home/gns3/workspace/Nornir/.venv/lib/python3.6/site-packages/jnpr/junos/device.py", line 797, in execute
    errs=ex)
jnpr.junos.exception.RpcError: RpcError(severity: error, bad_element: None, message: syntax error, expecting '}', ';', or '{')

During handling of the above exception, another exception occurred:

Traceback (most recent call last):
  File "/home/gns3/workspace/Nornir/.venv/lib/python3.6/site-packages/napalm/junos/junos.py", line 241, in _load_candidate
    ignore_warning=self.ignore_warning,
  File "/home/gns3/workspace/Nornir/.venv/lib/python3.6/site-packages/jnpr/junos/utils/config.py", line 539, in load
    ignore_warning=ignore_warning)
  File "/home/gns3/workspace/Nornir/.venv/lib/python3.6/site-packages/jnpr/junos/utils/config.py", line 460, in try_load
    raise ConfigLoadError(cmd=err.cmd, rsp=err.rsp, errs=err.errs)
jnpr.junos.exception.ConfigLoadError: ConfigLoadError(severity: error, bad_element: None, message: error: syntax error, expecting '}', ';', or '{')

During handling of the above exception, another exception occurred:

Traceback (most recent call last):
  File "/home/gns3/workspace/Nornir/.venv/lib/python3.6/site-packages/nornir/core/task.py", line 85, in start
    r = self.task(self, **self.params)
  File "/home/gns3/workspace/Nornir/.venv/lib/python3.6/site-packages/nornir/plugins/tasks/networking/napalm_configure.py", line 32, in napalm_configure
    device.load_merge_candidate(filename=filename, config=configuration)
  File "/home/gns3/workspace/Nornir/.venv/lib/python3.6/site-packages/napalm/junos/junos.py", line 257, in load_merge_candidate
    self._load_candidate(filename, config, False)
  File "/home/gns3/workspace/Nornir/.venv/lib/python3.6/site-packages/napalm/junos/junos.py", line 247, in _load_candidate
    raise MergeConfigException(e.errs)
napalm.base.exceptions.MergeConfigException: [{'severity': 'error', 'source': None, 'edit_path': None, 'bad_element': None, 'message': "syntax error, expecting '}', ';', or '{'"}]

2020-04-24 16:33:44,061 - nornir.core.task -    ERROR -      start() - Host 'r1': task 'basic_configuration' failed with traceback:
Traceback (most recent call last):
  File "/home/gns3/workspace/Nornir/.venv/lib/python3.6/site-packages/nornir/core/task.py", line 85, in start
    r = self.task(self, **self.params)
  File "explore.py", line 23, in basic_configuration
    replace=False, configuration=task.host["config"])
  File "/home/gns3/workspace/Nornir/.venv/lib/python3.6/site-packages/nornir/core/task.py", line 147, in run
    raise NornirSubTaskError(task=task, result=r)
nornir.core.exceptions.NornirSubTaskError: Subtask: <function napalm_configure at 0x7f97775ba950> (failed)


2020-04-24 16:33:44,143 - nornir.core.task -    ERROR -      start() - Host 'r2': task 'Loading Configuration on the device' failed with traceback:
Traceback (most recent call last):
  File "/home/gns3/workspace/Nornir/.venv/lib/python3.6/site-packages/jnpr/junos/device.py", line 777, in execute
    ignore_warning=ignore_warning)
  File "/home/gns3/workspace/Nornir/.venv/lib/python3.6/site-packages/jnpr/junos/decorators.py", line 169, in wrapper
    raise ex
  File "/home/gns3/workspace/Nornir/.venv/lib/python3.6/site-packages/jnpr/junos/decorators.py", line 116, in wrapper
    rsp = function(self, *args, **kwargs)
  File "/home/gns3/workspace/Nornir/.venv/lib/python3.6/site-packages/jnpr/junos/device.py", line 1339, in _rpc_reply
    return self._conn.rpc(rpc_cmd_e)._NCElement__doc
  File "/home/gns3/workspace/Nornir/.venv/lib/python3.6/site-packages/ncclient/manager.py", line 236, in execute
    huge_tree=self._huge_tree).request(*args, **kwds)
  File "/home/gns3/workspace/Nornir/.venv/lib/python3.6/site-packages/ncclient/operations/third_party/juniper/rpc.py", line 52, in request
    return self._request(rpc)
  File "/home/gns3/workspace/Nornir/.venv/lib/python3.6/site-packages/ncclient/operations/rpc.py", line 348, in _request
    raise self._reply.error
ncclient.operations.rpc.RPCError: syntax error, expecting '}', ';', or '{'

During handling of the above exception, another exception occurred:

Traceback (most recent call last):
  File "/home/gns3/workspace/Nornir/.venv/lib/python3.6/site-packages/jnpr/junos/utils/config.py", line 456, in try_load
    **rpc_xattrs)
  File "/home/gns3/workspace/Nornir/.venv/lib/python3.6/site-packages/jnpr/junos/rpcmeta.py", line 277, in load_config
    return self._junos.execute(rpc, ignore_warning=ignore_warning)
  File "/home/gns3/workspace/Nornir/.venv/lib/python3.6/site-packages/jnpr/junos/decorators.py", line 76, in wrapper
    return function(*args, **kwargs)
  File "/home/gns3/workspace/Nornir/.venv/lib/python3.6/site-packages/jnpr/junos/decorators.py", line 31, in wrapper
    return function(*args, **kwargs)
  File "/home/gns3/workspace/Nornir/.venv/lib/python3.6/site-packages/jnpr/junos/device.py", line 797, in execute
    errs=ex)
jnpr.junos.exception.RpcError: RpcError(severity: error, bad_element: None, message: syntax error, expecting '}', ';', or '{')

During handling of the above exception, another exception occurred:

Traceback (most recent call last):
  File "/home/gns3/workspace/Nornir/.venv/lib/python3.6/site-packages/napalm/junos/junos.py", line 241, in _load_candidate
    ignore_warning=self.ignore_warning,
  File "/home/gns3/workspace/Nornir/.venv/lib/python3.6/site-packages/jnpr/junos/utils/config.py", line 539, in load
    ignore_warning=ignore_warning)
  File "/home/gns3/workspace/Nornir/.venv/lib/python3.6/site-packages/jnpr/junos/utils/config.py", line 460, in try_load
    raise ConfigLoadError(cmd=err.cmd, rsp=err.rsp, errs=err.errs)
jnpr.junos.exception.ConfigLoadError: ConfigLoadError(severity: error, bad_element: None, message: error: syntax error, expecting '}', ';', or '{')

During handling of the above exception, another exception occurred:

Traceback (most recent call last):
  File "/home/gns3/workspace/Nornir/.venv/lib/python3.6/site-packages/nornir/core/task.py", line 85, in start
    r = self.task(self, **self.params)
  File "/home/gns3/workspace/Nornir/.venv/lib/python3.6/site-packages/nornir/plugins/tasks/networking/napalm_configure.py", line 32, in napalm_configure
    device.load_merge_candidate(filename=filename, config=configuration)
  File "/home/gns3/workspace/Nornir/.venv/lib/python3.6/site-packages/napalm/junos/junos.py", line 257, in load_merge_candidate
    self._load_candidate(filename, config, False)
  File "/home/gns3/workspace/Nornir/.venv/lib/python3.6/site-packages/napalm/junos/junos.py", line 247, in _load_candidate
    raise MergeConfigException(e.errs)
napalm.base.exceptions.MergeConfigException: [{'severity': 'error', 'source': None, 'edit_path': None, 'bad_element': None, 'message': "syntax error, expecting '}', ';', or '{'"}]

2020-04-24 16:33:44,143 - nornir.core.task -    ERROR -      start() - Host 'r2': task 'basic_configuration' failed with traceback:
Traceback (most recent call last):
  File "/home/gns3/workspace/Nornir/.venv/lib/python3.6/site-packages/nornir/core/task.py", line 85, in start
    r = self.task(self, **self.params)
  File "explore.py", line 23, in basic_configuration
    replace=False, configuration=task.host["config"])
  File "/home/gns3/workspace/Nornir/.venv/lib/python3.6/site-packages/nornir/core/task.py", line 147, in run
    raise NornirSubTaskError(task=task, result=r)
nornir.core.exceptions.NornirSubTaskError: Subtask: <function napalm_configure at 0x7f97775ba950> (failed)


2020-04-24 16:37:50,607 -  nornir.core -     INFO -        run() - Running task 'basic_configuration' with args {} on 2 hosts
2020-04-24 16:37:51,603 - nornir.core.task -    ERROR -      start() - Host 'r1': task 'Loading Configuration on the device' failed with traceback:
Traceback (most recent call last):
  File "/home/gns3/workspace/Nornir/.venv/lib/python3.6/site-packages/jnpr/junos/device.py", line 777, in execute
    ignore_warning=ignore_warning)
  File "/home/gns3/workspace/Nornir/.venv/lib/python3.6/site-packages/jnpr/junos/decorators.py", line 169, in wrapper
    raise ex
  File "/home/gns3/workspace/Nornir/.venv/lib/python3.6/site-packages/jnpr/junos/decorators.py", line 116, in wrapper
    rsp = function(self, *args, **kwargs)
  File "/home/gns3/workspace/Nornir/.venv/lib/python3.6/site-packages/jnpr/junos/device.py", line 1339, in _rpc_reply
    return self._conn.rpc(rpc_cmd_e)._NCElement__doc
  File "/home/gns3/workspace/Nornir/.venv/lib/python3.6/site-packages/ncclient/manager.py", line 236, in execute
    huge_tree=self._huge_tree).request(*args, **kwds)
  File "/home/gns3/workspace/Nornir/.venv/lib/python3.6/site-packages/ncclient/operations/third_party/juniper/rpc.py", line 52, in request
    return self._request(rpc)
  File "/home/gns3/workspace/Nornir/.venv/lib/python3.6/site-packages/ncclient/operations/rpc.py", line 348, in _request
    raise self._reply.error
ncclient.operations.rpc.RPCError: syntax error

During handling of the above exception, another exception occurred:

Traceback (most recent call last):
  File "/home/gns3/workspace/Nornir/.venv/lib/python3.6/site-packages/jnpr/junos/utils/config.py", line 456, in try_load
    **rpc_xattrs)
  File "/home/gns3/workspace/Nornir/.venv/lib/python3.6/site-packages/jnpr/junos/rpcmeta.py", line 277, in load_config
    return self._junos.execute(rpc, ignore_warning=ignore_warning)
  File "/home/gns3/workspace/Nornir/.venv/lib/python3.6/site-packages/jnpr/junos/decorators.py", line 76, in wrapper
    return function(*args, **kwargs)
  File "/home/gns3/workspace/Nornir/.venv/lib/python3.6/site-packages/jnpr/junos/decorators.py", line 31, in wrapper
    return function(*args, **kwargs)
  File "/home/gns3/workspace/Nornir/.venv/lib/python3.6/site-packages/jnpr/junos/device.py", line 797, in execute
    errs=ex)
jnpr.junos.exception.RpcError: RpcError(severity: error, bad_element: base.j2, message: syntax error)

During handling of the above exception, another exception occurred:

Traceback (most recent call last):
  File "/home/gns3/workspace/Nornir/.venv/lib/python3.6/site-packages/napalm/junos/junos.py", line 241, in _load_candidate
    ignore_warning=self.ignore_warning,
  File "/home/gns3/workspace/Nornir/.venv/lib/python3.6/site-packages/jnpr/junos/utils/config.py", line 539, in load
    ignore_warning=ignore_warning)
  File "/home/gns3/workspace/Nornir/.venv/lib/python3.6/site-packages/jnpr/junos/utils/config.py", line 460, in try_load
    raise ConfigLoadError(cmd=err.cmd, rsp=err.rsp, errs=err.errs)
jnpr.junos.exception.ConfigLoadError: ConfigLoadError(severity: error, bad_element: base.j2, message: error: syntax error)

During handling of the above exception, another exception occurred:

Traceback (most recent call last):
  File "/home/gns3/workspace/Nornir/.venv/lib/python3.6/site-packages/nornir/core/task.py", line 85, in start
    r = self.task(self, **self.params)
  File "/home/gns3/workspace/Nornir/.venv/lib/python3.6/site-packages/nornir/plugins/tasks/networking/napalm_configure.py", line 32, in napalm_configure
    device.load_merge_candidate(filename=filename, config=configuration)
  File "/home/gns3/workspace/Nornir/.venv/lib/python3.6/site-packages/napalm/junos/junos.py", line 257, in load_merge_candidate
    self._load_candidate(filename, config, False)
  File "/home/gns3/workspace/Nornir/.venv/lib/python3.6/site-packages/napalm/junos/junos.py", line 247, in _load_candidate
    raise MergeConfigException(e.errs)
napalm.base.exceptions.MergeConfigException: [{'severity': 'error', 'source': None, 'edit_path': None, 'bad_element': 'base.j2', 'message': 'syntax error'}]

2020-04-24 16:37:51,603 - nornir.core.task -    ERROR -      start() - Host 'r1': task 'basic_configuration' failed with traceback:
Traceback (most recent call last):
  File "/home/gns3/workspace/Nornir/.venv/lib/python3.6/site-packages/nornir/core/task.py", line 85, in start
    r = self.task(self, **self.params)
  File "explore.py", line 24, in basic_configuration
    replace=False, configuration=task.host["config"])
  File "/home/gns3/workspace/Nornir/.venv/lib/python3.6/site-packages/nornir/core/task.py", line 147, in run
    raise NornirSubTaskError(task=task, result=r)
nornir.core.exceptions.NornirSubTaskError: Subtask: <function napalm_configure at 0x7fb0ed798950> (failed)


2020-04-24 16:37:51,721 - nornir.core.task -    ERROR -      start() - Host 'r2': task 'Loading Configuration on the device' failed with traceback:
Traceback (most recent call last):
  File "/home/gns3/workspace/Nornir/.venv/lib/python3.6/site-packages/jnpr/junos/device.py", line 777, in execute
    ignore_warning=ignore_warning)
  File "/home/gns3/workspace/Nornir/.venv/lib/python3.6/site-packages/jnpr/junos/decorators.py", line 169, in wrapper
    raise ex
  File "/home/gns3/workspace/Nornir/.venv/lib/python3.6/site-packages/jnpr/junos/decorators.py", line 116, in wrapper
    rsp = function(self, *args, **kwargs)
  File "/home/gns3/workspace/Nornir/.venv/lib/python3.6/site-packages/jnpr/junos/device.py", line 1339, in _rpc_reply
    return self._conn.rpc(rpc_cmd_e)._NCElement__doc
  File "/home/gns3/workspace/Nornir/.venv/lib/python3.6/site-packages/ncclient/manager.py", line 236, in execute
    huge_tree=self._huge_tree).request(*args, **kwds)
  File "/home/gns3/workspace/Nornir/.venv/lib/python3.6/site-packages/ncclient/operations/third_party/juniper/rpc.py", line 52, in request
    return self._request(rpc)
  File "/home/gns3/workspace/Nornir/.venv/lib/python3.6/site-packages/ncclient/operations/rpc.py", line 348, in _request
    raise self._reply.error
ncclient.operations.rpc.RPCError: syntax error

During handling of the above exception, another exception occurred:

Traceback (most recent call last):
  File "/home/gns3/workspace/Nornir/.venv/lib/python3.6/site-packages/jnpr/junos/utils/config.py", line 456, in try_load
    **rpc_xattrs)
  File "/home/gns3/workspace/Nornir/.venv/lib/python3.6/site-packages/jnpr/junos/rpcmeta.py", line 277, in load_config
    return self._junos.execute(rpc, ignore_warning=ignore_warning)
  File "/home/gns3/workspace/Nornir/.venv/lib/python3.6/site-packages/jnpr/junos/decorators.py", line 76, in wrapper
    return function(*args, **kwargs)
  File "/home/gns3/workspace/Nornir/.venv/lib/python3.6/site-packages/jnpr/junos/decorators.py", line 31, in wrapper
    return function(*args, **kwargs)
  File "/home/gns3/workspace/Nornir/.venv/lib/python3.6/site-packages/jnpr/junos/device.py", line 797, in execute
    errs=ex)
jnpr.junos.exception.RpcError: RpcError(severity: error, bad_element: base.j2, message: syntax error)

During handling of the above exception, another exception occurred:

Traceback (most recent call last):
  File "/home/gns3/workspace/Nornir/.venv/lib/python3.6/site-packages/napalm/junos/junos.py", line 241, in _load_candidate
    ignore_warning=self.ignore_warning,
  File "/home/gns3/workspace/Nornir/.venv/lib/python3.6/site-packages/jnpr/junos/utils/config.py", line 539, in load
    ignore_warning=ignore_warning)
  File "/home/gns3/workspace/Nornir/.venv/lib/python3.6/site-packages/jnpr/junos/utils/config.py", line 460, in try_load
    raise ConfigLoadError(cmd=err.cmd, rsp=err.rsp, errs=err.errs)
jnpr.junos.exception.ConfigLoadError: ConfigLoadError(severity: error, bad_element: base.j2, message: error: syntax error)

During handling of the above exception, another exception occurred:

Traceback (most recent call last):
  File "/home/gns3/workspace/Nornir/.venv/lib/python3.6/site-packages/nornir/core/task.py", line 85, in start
    r = self.task(self, **self.params)
  File "/home/gns3/workspace/Nornir/.venv/lib/python3.6/site-packages/nornir/plugins/tasks/networking/napalm_configure.py", line 32, in napalm_configure
    device.load_merge_candidate(filename=filename, config=configuration)
  File "/home/gns3/workspace/Nornir/.venv/lib/python3.6/site-packages/napalm/junos/junos.py", line 257, in load_merge_candidate
    self._load_candidate(filename, config, False)
  File "/home/gns3/workspace/Nornir/.venv/lib/python3.6/site-packages/napalm/junos/junos.py", line 247, in _load_candidate
    raise MergeConfigException(e.errs)
napalm.base.exceptions.MergeConfigException: [{'severity': 'error', 'source': None, 'edit_path': None, 'bad_element': 'base.j2', 'message': 'syntax error'}]

2020-04-24 16:37:51,722 - nornir.core.task -    ERROR -      start() - Host 'r2': task 'basic_configuration' failed with traceback:
Traceback (most recent call last):
  File "/home/gns3/workspace/Nornir/.venv/lib/python3.6/site-packages/nornir/core/task.py", line 85, in start
    r = self.task(self, **self.params)
  File "explore.py", line 24, in basic_configuration
    replace=False, configuration=task.host["config"])
  File "/home/gns3/workspace/Nornir/.venv/lib/python3.6/site-packages/nornir/core/task.py", line 147, in run
    raise NornirSubTaskError(task=task, result=r)
nornir.core.exceptions.NornirSubTaskError: Subtask: <function napalm_configure at 0x7fb0ed798950> (failed)


2020-04-24 16:38:48,697 -  nornir.core -     INFO -        run() - Running task 'basic_configuration' with args {} on 2 hosts
2020-04-24 16:38:49,723 - nornir.core.task -    ERROR -      start() - Host 'r1': task 'Loading Configuration on the device' failed with traceback:
Traceback (most recent call last):
  File "/home/gns3/workspace/Nornir/.venv/lib/python3.6/site-packages/jnpr/junos/device.py", line 777, in execute
    ignore_warning=ignore_warning)
  File "/home/gns3/workspace/Nornir/.venv/lib/python3.6/site-packages/jnpr/junos/decorators.py", line 169, in wrapper
    raise ex
  File "/home/gns3/workspace/Nornir/.venv/lib/python3.6/site-packages/jnpr/junos/decorators.py", line 116, in wrapper
    rsp = function(self, *args, **kwargs)
  File "/home/gns3/workspace/Nornir/.venv/lib/python3.6/site-packages/jnpr/junos/device.py", line 1339, in _rpc_reply
    return self._conn.rpc(rpc_cmd_e)._NCElement__doc
  File "/home/gns3/workspace/Nornir/.venv/lib/python3.6/site-packages/ncclient/manager.py", line 236, in execute
    huge_tree=self._huge_tree).request(*args, **kwds)
  File "/home/gns3/workspace/Nornir/.venv/lib/python3.6/site-packages/ncclient/operations/third_party/juniper/rpc.py", line 52, in request
    return self._request(rpc)
  File "/home/gns3/workspace/Nornir/.venv/lib/python3.6/site-packages/ncclient/operations/rpc.py", line 348, in _request
    raise self._reply.error
ncclient.operations.rpc.RPCError: syntax error

During handling of the above exception, another exception occurred:

Traceback (most recent call last):
  File "/home/gns3/workspace/Nornir/.venv/lib/python3.6/site-packages/jnpr/junos/utils/config.py", line 456, in try_load
    **rpc_xattrs)
  File "/home/gns3/workspace/Nornir/.venv/lib/python3.6/site-packages/jnpr/junos/rpcmeta.py", line 277, in load_config
    return self._junos.execute(rpc, ignore_warning=ignore_warning)
  File "/home/gns3/workspace/Nornir/.venv/lib/python3.6/site-packages/jnpr/junos/decorators.py", line 76, in wrapper
    return function(*args, **kwargs)
  File "/home/gns3/workspace/Nornir/.venv/lib/python3.6/site-packages/jnpr/junos/decorators.py", line 31, in wrapper
    return function(*args, **kwargs)
  File "/home/gns3/workspace/Nornir/.venv/lib/python3.6/site-packages/jnpr/junos/device.py", line 797, in execute
    errs=ex)
jnpr.junos.exception.RpcError: RpcError(severity: error, bad_element: base.j2, message: syntax error)

During handling of the above exception, another exception occurred:

Traceback (most recent call last):
  File "/home/gns3/workspace/Nornir/.venv/lib/python3.6/site-packages/napalm/junos/junos.py", line 241, in _load_candidate
    ignore_warning=self.ignore_warning,
  File "/home/gns3/workspace/Nornir/.venv/lib/python3.6/site-packages/jnpr/junos/utils/config.py", line 539, in load
    ignore_warning=ignore_warning)
  File "/home/gns3/workspace/Nornir/.venv/lib/python3.6/site-packages/jnpr/junos/utils/config.py", line 460, in try_load
    raise ConfigLoadError(cmd=err.cmd, rsp=err.rsp, errs=err.errs)
jnpr.junos.exception.ConfigLoadError: ConfigLoadError(severity: error, bad_element: base.j2, message: error: syntax error)

During handling of the above exception, another exception occurred:

Traceback (most recent call last):
  File "/home/gns3/workspace/Nornir/.venv/lib/python3.6/site-packages/nornir/core/task.py", line 85, in start
    r = self.task(self, **self.params)
  File "/home/gns3/workspace/Nornir/.venv/lib/python3.6/site-packages/nornir/plugins/tasks/networking/napalm_configure.py", line 32, in napalm_configure
    device.load_merge_candidate(filename=filename, config=configuration)
  File "/home/gns3/workspace/Nornir/.venv/lib/python3.6/site-packages/napalm/junos/junos.py", line 257, in load_merge_candidate
    self._load_candidate(filename, config, False)
  File "/home/gns3/workspace/Nornir/.venv/lib/python3.6/site-packages/napalm/junos/junos.py", line 247, in _load_candidate
    raise MergeConfigException(e.errs)
napalm.base.exceptions.MergeConfigException: [{'severity': 'error', 'source': None, 'edit_path': None, 'bad_element': 'base.j2', 'message': 'syntax error'}]

2020-04-24 16:38:49,724 - nornir.core.task -    ERROR -      start() - Host 'r1': task 'basic_configuration' failed with traceback:
Traceback (most recent call last):
  File "/home/gns3/workspace/Nornir/.venv/lib/python3.6/site-packages/nornir/core/task.py", line 85, in start
    r = self.task(self, **self.params)
  File "explore.py", line 24, in basic_configuration
    replace=False, configuration=task.host["config"])
  File "/home/gns3/workspace/Nornir/.venv/lib/python3.6/site-packages/nornir/core/task.py", line 147, in run
    raise NornirSubTaskError(task=task, result=r)
nornir.core.exceptions.NornirSubTaskError: Subtask: <function napalm_configure at 0x7f39eea75950> (failed)


2020-04-24 16:38:49,906 - nornir.core.task -    ERROR -      start() - Host 'r2': task 'Loading Configuration on the device' failed with traceback:
Traceback (most recent call last):
  File "/home/gns3/workspace/Nornir/.venv/lib/python3.6/site-packages/jnpr/junos/device.py", line 777, in execute
    ignore_warning=ignore_warning)
  File "/home/gns3/workspace/Nornir/.venv/lib/python3.6/site-packages/jnpr/junos/decorators.py", line 169, in wrapper
    raise ex
  File "/home/gns3/workspace/Nornir/.venv/lib/python3.6/site-packages/jnpr/junos/decorators.py", line 116, in wrapper
    rsp = function(self, *args, **kwargs)
  File "/home/gns3/workspace/Nornir/.venv/lib/python3.6/site-packages/jnpr/junos/device.py", line 1339, in _rpc_reply
    return self._conn.rpc(rpc_cmd_e)._NCElement__doc
  File "/home/gns3/workspace/Nornir/.venv/lib/python3.6/site-packages/ncclient/manager.py", line 236, in execute
    huge_tree=self._huge_tree).request(*args, **kwds)
  File "/home/gns3/workspace/Nornir/.venv/lib/python3.6/site-packages/ncclient/operations/third_party/juniper/rpc.py", line 52, in request
    return self._request(rpc)
  File "/home/gns3/workspace/Nornir/.venv/lib/python3.6/site-packages/ncclient/operations/rpc.py", line 348, in _request
    raise self._reply.error
ncclient.operations.rpc.RPCError: syntax error

During handling of the above exception, another exception occurred:

Traceback (most recent call last):
  File "/home/gns3/workspace/Nornir/.venv/lib/python3.6/site-packages/jnpr/junos/utils/config.py", line 456, in try_load
    **rpc_xattrs)
  File "/home/gns3/workspace/Nornir/.venv/lib/python3.6/site-packages/jnpr/junos/rpcmeta.py", line 277, in load_config
    return self._junos.execute(rpc, ignore_warning=ignore_warning)
  File "/home/gns3/workspace/Nornir/.venv/lib/python3.6/site-packages/jnpr/junos/decorators.py", line 76, in wrapper
    return function(*args, **kwargs)
  File "/home/gns3/workspace/Nornir/.venv/lib/python3.6/site-packages/jnpr/junos/decorators.py", line 31, in wrapper
    return function(*args, **kwargs)
  File "/home/gns3/workspace/Nornir/.venv/lib/python3.6/site-packages/jnpr/junos/device.py", line 797, in execute
    errs=ex)
jnpr.junos.exception.RpcError: RpcError(severity: error, bad_element: base.j2, message: syntax error)

During handling of the above exception, another exception occurred:

Traceback (most recent call last):
  File "/home/gns3/workspace/Nornir/.venv/lib/python3.6/site-packages/napalm/junos/junos.py", line 241, in _load_candidate
    ignore_warning=self.ignore_warning,
  File "/home/gns3/workspace/Nornir/.venv/lib/python3.6/site-packages/jnpr/junos/utils/config.py", line 539, in load
    ignore_warning=ignore_warning)
  File "/home/gns3/workspace/Nornir/.venv/lib/python3.6/site-packages/jnpr/junos/utils/config.py", line 460, in try_load
    raise ConfigLoadError(cmd=err.cmd, rsp=err.rsp, errs=err.errs)
jnpr.junos.exception.ConfigLoadError: ConfigLoadError(severity: error, bad_element: base.j2, message: error: syntax error)

During handling of the above exception, another exception occurred:

Traceback (most recent call last):
  File "/home/gns3/workspace/Nornir/.venv/lib/python3.6/site-packages/nornir/core/task.py", line 85, in start
    r = self.task(self, **self.params)
  File "/home/gns3/workspace/Nornir/.venv/lib/python3.6/site-packages/nornir/plugins/tasks/networking/napalm_configure.py", line 32, in napalm_configure
    device.load_merge_candidate(filename=filename, config=configuration)
  File "/home/gns3/workspace/Nornir/.venv/lib/python3.6/site-packages/napalm/junos/junos.py", line 257, in load_merge_candidate
    self._load_candidate(filename, config, False)
  File "/home/gns3/workspace/Nornir/.venv/lib/python3.6/site-packages/napalm/junos/junos.py", line 247, in _load_candidate
    raise MergeConfigException(e.errs)
napalm.base.exceptions.MergeConfigException: [{'severity': 'error', 'source': None, 'edit_path': None, 'bad_element': 'base.j2', 'message': 'syntax error'}]

2020-04-24 16:38:49,907 - nornir.core.task -    ERROR -      start() - Host 'r2': task 'basic_configuration' failed with traceback:
Traceback (most recent call last):
  File "/home/gns3/workspace/Nornir/.venv/lib/python3.6/site-packages/nornir/core/task.py", line 85, in start
    r = self.task(self, **self.params)
  File "explore.py", line 24, in basic_configuration
    replace=False, configuration=task.host["config"])
  File "/home/gns3/workspace/Nornir/.venv/lib/python3.6/site-packages/nornir/core/task.py", line 147, in run
    raise NornirSubTaskError(task=task, result=r)
nornir.core.exceptions.NornirSubTaskError: Subtask: <function napalm_configure at 0x7f39eea75950> (failed)


2020-04-24 16:40:24,960 -  nornir.core -     INFO -        run() - Running task 'basic_configuration' with args {} on 2 hosts
2020-04-24 16:45:16,163 -  nornir.core -     INFO -        run() - Running task 'basic_configuration' with args {} on 2 hosts
2020-04-24 16:46:08,893 -  nornir.core -     INFO -        run() - Running task 'basic_configuration' with args {} on 2 hosts
2020-04-24 16:46:29,110 -  nornir.core -     INFO -        run() - Running task 'basic_configuration' with args {} on 2 hosts
2020-04-24 16:48:58,349 -  nornir.core -     INFO -        run() - Running task 'basic_configuration' with args {} on 2 hosts
2020-04-24 16:49:34,558 -  nornir.core -     INFO -        run() - Running task 'basic_configuration' with args {} on 2 hosts
2020-04-24 16:53:02,373 -  nornir.core -     INFO -        run() - Running task 'basic_configuration' with args {} on 2 hosts
2020-04-24 17:08:47,793 -  nornir.core -     INFO -        run() - Running task 'basic_configuration' with args {} on 2 hosts
2020-04-24 17:08:47,797 - nornir.core.task -    ERROR -      start() - Host 'r3': task 'Base Configuration' failed with traceback:
Traceback (most recent call last):
  File "/home/gns3/workspace/Nornir/.venv/lib/python3.6/site-packages/nornir/core/task.py", line 85, in start
    r = self.task(self, **self.params)
  File "/home/gns3/workspace/Nornir/.venv/lib/python3.6/site-packages/nornir/plugins/tasks/text/template_file.py", line 35, in template_file
    **kwargs
  File "/home/gns3/workspace/Nornir/.venv/lib/python3.6/site-packages/nornir/core/helpers/jinja_helper.py", line 17, in render_from_file
    t = env.get_template(template)
  File "/home/gns3/workspace/Nornir/.venv/lib/python3.6/site-packages/jinja2/environment.py", line 883, in get_template
    return self._load_template(name, self.make_globals(globals))
  File "/home/gns3/workspace/Nornir/.venv/lib/python3.6/site-packages/jinja2/environment.py", line 857, in _load_template
    template = self.loader.load(self, name, globals)
  File "/home/gns3/workspace/Nornir/.venv/lib/python3.6/site-packages/jinja2/loaders.py", line 115, in load
    source, filename, uptodate = self.get_source(environment, name)
  File "/home/gns3/workspace/Nornir/.venv/lib/python3.6/site-packages/jinja2/loaders.py", line 197, in get_source
    raise TemplateNotFound(template)
jinja2.exceptions.TemplateNotFound: base.j2

2020-04-24 17:08:47,797 - nornir.core.task -    ERROR -      start() - Host 'r3': task 'basic_configuration' failed with traceback:
Traceback (most recent call last):
  File "/home/gns3/workspace/Nornir/.venv/lib/python3.6/site-packages/nornir/core/task.py", line 85, in start
    r = self.task(self, **self.params)
  File "explore.py", line 15, in basic_configuration
    template="base.j2", path=f"templates/{task.host.platform}")
  File "/home/gns3/workspace/Nornir/.venv/lib/python3.6/site-packages/nornir/core/task.py", line 147, in run
    raise NornirSubTaskError(task=task, result=r)
nornir.core.exceptions.NornirSubTaskError: Subtask: <function template_file at 0x7fd20c6a5598> (failed)


2020-04-24 17:08:47,798 - nornir.core.task -    ERROR -      start() - Host 'r5': task 'Base Configuration' failed with traceback:
Traceback (most recent call last):
  File "/home/gns3/workspace/Nornir/.venv/lib/python3.6/site-packages/nornir/core/task.py", line 85, in start
    r = self.task(self, **self.params)
  File "/home/gns3/workspace/Nornir/.venv/lib/python3.6/site-packages/nornir/plugins/tasks/text/template_file.py", line 35, in template_file
    **kwargs
  File "/home/gns3/workspace/Nornir/.venv/lib/python3.6/site-packages/nornir/core/helpers/jinja_helper.py", line 17, in render_from_file
    t = env.get_template(template)
  File "/home/gns3/workspace/Nornir/.venv/lib/python3.6/site-packages/jinja2/environment.py", line 883, in get_template
    return self._load_template(name, self.make_globals(globals))
  File "/home/gns3/workspace/Nornir/.venv/lib/python3.6/site-packages/jinja2/environment.py", line 857, in _load_template
    template = self.loader.load(self, name, globals)
  File "/home/gns3/workspace/Nornir/.venv/lib/python3.6/site-packages/jinja2/loaders.py", line 115, in load
    source, filename, uptodate = self.get_source(environment, name)
  File "/home/gns3/workspace/Nornir/.venv/lib/python3.6/site-packages/jinja2/loaders.py", line 197, in get_source
    raise TemplateNotFound(template)
jinja2.exceptions.TemplateNotFound: base.j2

2020-04-24 17:08:47,798 - nornir.core.task -    ERROR -      start() - Host 'r5': task 'basic_configuration' failed with traceback:
Traceback (most recent call last):
  File "/home/gns3/workspace/Nornir/.venv/lib/python3.6/site-packages/nornir/core/task.py", line 85, in start
    r = self.task(self, **self.params)
  File "explore.py", line 15, in basic_configuration
    template="base.j2", path=f"templates/{task.host.platform}")
  File "/home/gns3/workspace/Nornir/.venv/lib/python3.6/site-packages/nornir/core/task.py", line 147, in run
    raise NornirSubTaskError(task=task, result=r)
nornir.core.exceptions.NornirSubTaskError: Subtask: <function template_file at 0x7fd20c6a5598> (failed)


2020-04-24 19:47:18,565 -  nornir.core -     INFO -        run() - Running task 'basic_configuration' with args {} on 2 hosts
2020-04-24 19:47:18,574 - nornir.core.task -    ERROR -      start() - Host 'r3': task 'Base Configuration' failed with traceback:
Traceback (most recent call last):
  File "/home/gns3/workspace/Nornir/.venv/lib/python3.6/site-packages/nornir/core/task.py", line 85, in start
    r = self.task(self, **self.params)
  File "/home/gns3/workspace/Nornir/.venv/lib/python3.6/site-packages/nornir/plugins/tasks/text/template_file.py", line 35, in template_file
    **kwargs
  File "/home/gns3/workspace/Nornir/.venv/lib/python3.6/site-packages/nornir/core/helpers/jinja_helper.py", line 17, in render_from_file
    t = env.get_template(template)
  File "/home/gns3/workspace/Nornir/.venv/lib/python3.6/site-packages/jinja2/environment.py", line 883, in get_template
    return self._load_template(name, self.make_globals(globals))
  File "/home/gns3/workspace/Nornir/.venv/lib/python3.6/site-packages/jinja2/environment.py", line 857, in _load_template
    template = self.loader.load(self, name, globals)
  File "/home/gns3/workspace/Nornir/.venv/lib/python3.6/site-packages/jinja2/loaders.py", line 115, in load
    source, filename, uptodate = self.get_source(environment, name)
  File "/home/gns3/workspace/Nornir/.venv/lib/python3.6/site-packages/jinja2/loaders.py", line 197, in get_source
    raise TemplateNotFound(template)
jinja2.exceptions.TemplateNotFound: base.j2

2020-04-24 19:47:18,574 - nornir.core.task -    ERROR -      start() - Host 'r3': task 'basic_configuration' failed with traceback:
Traceback (most recent call last):
  File "/home/gns3/workspace/Nornir/.venv/lib/python3.6/site-packages/nornir/core/task.py", line 85, in start
    r = self.task(self, **self.params)
  File "explore.py", line 15, in basic_configuration
    template="base.j2", path=f"templates/{task.host.platform}")
  File "/home/gns3/workspace/Nornir/.venv/lib/python3.6/site-packages/nornir/core/task.py", line 147, in run
    raise NornirSubTaskError(task=task, result=r)
nornir.core.exceptions.NornirSubTaskError: Subtask: <function template_file at 0x7f64859f0598> (failed)


2020-04-24 19:47:18,575 - nornir.core.task -    ERROR -      start() - Host 'r5': task 'Base Configuration' failed with traceback:
Traceback (most recent call last):
  File "/home/gns3/workspace/Nornir/.venv/lib/python3.6/site-packages/nornir/core/task.py", line 85, in start
    r = self.task(self, **self.params)
  File "/home/gns3/workspace/Nornir/.venv/lib/python3.6/site-packages/nornir/plugins/tasks/text/template_file.py", line 35, in template_file
    **kwargs
  File "/home/gns3/workspace/Nornir/.venv/lib/python3.6/site-packages/nornir/core/helpers/jinja_helper.py", line 17, in render_from_file
    t = env.get_template(template)
  File "/home/gns3/workspace/Nornir/.venv/lib/python3.6/site-packages/jinja2/environment.py", line 883, in get_template
    return self._load_template(name, self.make_globals(globals))
  File "/home/gns3/workspace/Nornir/.venv/lib/python3.6/site-packages/jinja2/environment.py", line 857, in _load_template
    template = self.loader.load(self, name, globals)
  File "/home/gns3/workspace/Nornir/.venv/lib/python3.6/site-packages/jinja2/loaders.py", line 115, in load
    source, filename, uptodate = self.get_source(environment, name)
  File "/home/gns3/workspace/Nornir/.venv/lib/python3.6/site-packages/jinja2/loaders.py", line 197, in get_source
    raise TemplateNotFound(template)
jinja2.exceptions.TemplateNotFound: base.j2

2020-04-24 19:47:18,575 - nornir.core.task -    ERROR -      start() - Host 'r5': task 'basic_configuration' failed with traceback:
Traceback (most recent call last):
  File "/home/gns3/workspace/Nornir/.venv/lib/python3.6/site-packages/nornir/core/task.py", line 85, in start
    r = self.task(self, **self.params)
  File "explore.py", line 15, in basic_configuration
    template="base.j2", path=f"templates/{task.host.platform}")
  File "/home/gns3/workspace/Nornir/.venv/lib/python3.6/site-packages/nornir/core/task.py", line 147, in run
    raise NornirSubTaskError(task=task, result=r)
nornir.core.exceptions.NornirSubTaskError: Subtask: <function template_file at 0x7f64859f0598> (failed)


2020-04-24 19:48:05,977 -  nornir.core -     INFO -        run() - Running task 'basic_configuration' with args {'template_name': 'dns.j2'} on 2 hosts
2020-04-24 19:48:05,987 - nornir.core.task -    ERROR -      start() - Host 'r2': task 'Base Configuration' failed with traceback:
Traceback (most recent call last):
  File "/home/gns3/workspace/Nornir/.venv/lib/python3.6/site-packages/nornir/core/task.py", line 85, in start
    r = self.task(self, **self.params)
  File "/home/gns3/workspace/Nornir/.venv/lib/python3.6/site-packages/nornir/plugins/tasks/text/template_file.py", line 35, in template_file
    **kwargs
  File "/home/gns3/workspace/Nornir/.venv/lib/python3.6/site-packages/nornir/core/helpers/jinja_helper.py", line 18, in render_from_file
    return t.render(**kwargs)
  File "/home/gns3/workspace/Nornir/.venv/lib/python3.6/site-packages/jinja2/environment.py", line 1090, in render
    self.environment.handle_exception()
  File "/home/gns3/workspace/Nornir/.venv/lib/python3.6/site-packages/jinja2/environment.py", line 832, in handle_exception
    reraise(*rewrite_traceback_stack(source=source))
  File "/home/gns3/workspace/Nornir/.venv/lib/python3.6/site-packages/jinja2/_compat.py", line 28, in reraise
    raise value.with_traceback(tb)
  File "templates/junos/dns.j2", line 3, in top-level template code
    {% for server in host.servers %}
jinja2.exceptions.UndefinedError: 'nornir.core.inventory.Host object' has no attribute 'servers'

2020-04-24 19:48:05,987 - nornir.core.task -    ERROR -      start() - Host 'r2': task 'basic_configuration' failed with traceback:
Traceback (most recent call last):
  File "/home/gns3/workspace/Nornir/.venv/lib/python3.6/site-packages/nornir/core/task.py", line 85, in start
    r = self.task(self, **self.params)
  File "deploy_configs.py", line 10, in basic_configuration
    path=f"templates/{task.host.platform}")
  File "/home/gns3/workspace/Nornir/.venv/lib/python3.6/site-packages/nornir/core/task.py", line 147, in run
    raise NornirSubTaskError(task=task, result=r)
nornir.core.exceptions.NornirSubTaskError: Subtask: <function template_file at 0x7f668a9e9620> (failed)


2020-04-24 19:48:05,988 - nornir.core.task -    ERROR -      start() - Host 'r1': task 'Base Configuration' failed with traceback:
Traceback (most recent call last):
  File "/home/gns3/workspace/Nornir/.venv/lib/python3.6/site-packages/nornir/core/task.py", line 85, in start
    r = self.task(self, **self.params)
  File "/home/gns3/workspace/Nornir/.venv/lib/python3.6/site-packages/nornir/plugins/tasks/text/template_file.py", line 35, in template_file
    **kwargs
  File "/home/gns3/workspace/Nornir/.venv/lib/python3.6/site-packages/nornir/core/helpers/jinja_helper.py", line 18, in render_from_file
    return t.render(**kwargs)
  File "/home/gns3/workspace/Nornir/.venv/lib/python3.6/site-packages/jinja2/environment.py", line 1090, in render
    self.environment.handle_exception()
  File "/home/gns3/workspace/Nornir/.venv/lib/python3.6/site-packages/jinja2/environment.py", line 832, in handle_exception
    reraise(*rewrite_traceback_stack(source=source))
  File "/home/gns3/workspace/Nornir/.venv/lib/python3.6/site-packages/jinja2/_compat.py", line 28, in reraise
    raise value.with_traceback(tb)
  File "templates/junos/dns.j2", line 3, in top-level template code
    {% for server in host.servers %}
jinja2.exceptions.UndefinedError: 'nornir.core.inventory.Host object' has no attribute 'servers'

2020-04-24 19:48:05,988 - nornir.core.task -    ERROR -      start() - Host 'r1': task 'basic_configuration' failed with traceback:
Traceback (most recent call last):
  File "/home/gns3/workspace/Nornir/.venv/lib/python3.6/site-packages/nornir/core/task.py", line 85, in start
    r = self.task(self, **self.params)
  File "deploy_configs.py", line 10, in basic_configuration
    path=f"templates/{task.host.platform}")
  File "/home/gns3/workspace/Nornir/.venv/lib/python3.6/site-packages/nornir/core/task.py", line 147, in run
    raise NornirSubTaskError(task=task, result=r)
nornir.core.exceptions.NornirSubTaskError: Subtask: <function template_file at 0x7f668a9e9620> (failed)


2020-04-24 19:54:06,518 -  nornir.core -     INFO -        run() - Running task 'basic_configuration' with args {'template_name': 'dns.j2'} on 2 hosts
2020-04-24 20:35:57,103 -  nornir.core -     INFO -        run() - Running task 'basic_configuration' with args {'template_name': 'ntp.j2'} on 2 hosts
2020-04-24 21:34:22,020 -  nornir.core -     INFO -        run() - Running task 'basic_configuration' with args {'template_name': 'routing_options.j2'} on 2 hosts
2020-04-24 21:34:23,051 - nornir.core.task -    ERROR -      start() - Host 'r1': task 'Loading Configuration on the device' failed with traceback:
Traceback (most recent call last):
  File "/home/gns3/workspace/Nornir/.venv/lib/python3.6/site-packages/jnpr/junos/device.py", line 777, in execute
    ignore_warning=ignore_warning)
  File "/home/gns3/workspace/Nornir/.venv/lib/python3.6/site-packages/jnpr/junos/decorators.py", line 169, in wrapper
    raise ex
  File "/home/gns3/workspace/Nornir/.venv/lib/python3.6/site-packages/jnpr/junos/decorators.py", line 116, in wrapper
    rsp = function(self, *args, **kwargs)
  File "/home/gns3/workspace/Nornir/.venv/lib/python3.6/site-packages/jnpr/junos/device.py", line 1339, in _rpc_reply
    return self._conn.rpc(rpc_cmd_e)._NCElement__doc
  File "/home/gns3/workspace/Nornir/.venv/lib/python3.6/site-packages/ncclient/manager.py", line 236, in execute
    huge_tree=self._huge_tree).request(*args, **kwds)
  File "/home/gns3/workspace/Nornir/.venv/lib/python3.6/site-packages/ncclient/operations/third_party/juniper/rpc.py", line 52, in request
    return self._request(rpc)
  File "/home/gns3/workspace/Nornir/.venv/lib/python3.6/site-packages/ncclient/operations/rpc.py", line 346, in _request
    raise RPCError(to_ele(self._reply._raw), errs=errors)
ncclient.operations.rpc.RPCError: error: invalid input at '/24' in ip address '172.16.1.1/24'
warning: mgd: statement must contain additional statements

During handling of the above exception, another exception occurred:

Traceback (most recent call last):
  File "/home/gns3/workspace/Nornir/.venv/lib/python3.6/site-packages/jnpr/junos/utils/config.py", line 456, in try_load
    **rpc_xattrs)
  File "/home/gns3/workspace/Nornir/.venv/lib/python3.6/site-packages/jnpr/junos/rpcmeta.py", line 277, in load_config
    return self._junos.execute(rpc, ignore_warning=ignore_warning)
  File "/home/gns3/workspace/Nornir/.venv/lib/python3.6/site-packages/jnpr/junos/decorators.py", line 76, in wrapper
    return function(*args, **kwargs)
  File "/home/gns3/workspace/Nornir/.venv/lib/python3.6/site-packages/jnpr/junos/decorators.py", line 31, in wrapper
    return function(*args, **kwargs)
  File "/home/gns3/workspace/Nornir/.venv/lib/python3.6/site-packages/jnpr/junos/device.py", line 797, in execute
    errs=ex)
jnpr.junos.exception.RpcError: RpcError(severity: error, bad_element: 172.16.1.1/24, message: error: invalid input at '/24' in ip address '172.16.1.1/24'
warning: mgd: statement must contain additional statements)

During handling of the above exception, another exception occurred:

Traceback (most recent call last):
  File "/home/gns3/workspace/Nornir/.venv/lib/python3.6/site-packages/napalm/junos/junos.py", line 241, in _load_candidate
    ignore_warning=self.ignore_warning,
  File "/home/gns3/workspace/Nornir/.venv/lib/python3.6/site-packages/jnpr/junos/utils/config.py", line 539, in load
    ignore_warning=ignore_warning)
  File "/home/gns3/workspace/Nornir/.venv/lib/python3.6/site-packages/jnpr/junos/utils/config.py", line 460, in try_load
    raise ConfigLoadError(cmd=err.cmd, rsp=err.rsp, errs=err.errs)
jnpr.junos.exception.ConfigLoadError: ConfigLoadError(severity: error, bad_element: 172.16.1.1/24, message: error: invalid input at '/24' in ip address '172.16.1.1/24'
warning: mgd: statement must contain additional statements)

During handling of the above exception, another exception occurred:

Traceback (most recent call last):
  File "/home/gns3/workspace/Nornir/.venv/lib/python3.6/site-packages/nornir/core/task.py", line 85, in start
    r = self.task(self, **self.params)
  File "/home/gns3/workspace/Nornir/.venv/lib/python3.6/site-packages/nornir/plugins/tasks/networking/napalm_configure.py", line 32, in napalm_configure
    device.load_merge_candidate(filename=filename, config=configuration)
  File "/home/gns3/workspace/Nornir/.venv/lib/python3.6/site-packages/napalm/junos/junos.py", line 257, in load_merge_candidate
    self._load_candidate(filename, config, False)
  File "/home/gns3/workspace/Nornir/.venv/lib/python3.6/site-packages/napalm/junos/junos.py", line 247, in _load_candidate
    raise MergeConfigException(e.errs)
napalm.base.exceptions.MergeConfigException: [{'severity': 'error', 'source': None, 'edit_path': None, 'bad_element': '172.16.1.1/24', 'message': "invalid input at '/24' in ip address '172.16.1.1/24'"}, {'severity': 'warning', 'source': None, 'edit_path': None, 'bad_element': None, 'message': 'mgd: statement must contain additional statements'}]

2020-04-24 21:34:23,052 - nornir.core.task -    ERROR -      start() - Host 'r1': task 'basic_configuration' failed with traceback:
Traceback (most recent call last):
  File "/home/gns3/workspace/Nornir/.venv/lib/python3.6/site-packages/nornir/core/task.py", line 85, in start
    r = self.task(self, **self.params)
  File "deploy_configs.py", line 15, in basic_configuration
    replace=False, configuration=task.host["config"])
  File "/home/gns3/workspace/Nornir/.venv/lib/python3.6/site-packages/nornir/core/task.py", line 147, in run
    raise NornirSubTaskError(task=task, result=r)
nornir.core.exceptions.NornirSubTaskError: Subtask: <function napalm_configure at 0x7fab4832f9d8> (failed)


2020-04-24 21:34:23,150 - nornir.core.task -    ERROR -      start() - Host 'r2': task 'Loading Configuration on the device' failed with traceback:
Traceback (most recent call last):
  File "/home/gns3/workspace/Nornir/.venv/lib/python3.6/site-packages/jnpr/junos/device.py", line 777, in execute
    ignore_warning=ignore_warning)
  File "/home/gns3/workspace/Nornir/.venv/lib/python3.6/site-packages/jnpr/junos/decorators.py", line 169, in wrapper
    raise ex
  File "/home/gns3/workspace/Nornir/.venv/lib/python3.6/site-packages/jnpr/junos/decorators.py", line 116, in wrapper
    rsp = function(self, *args, **kwargs)
  File "/home/gns3/workspace/Nornir/.venv/lib/python3.6/site-packages/jnpr/junos/device.py", line 1339, in _rpc_reply
    return self._conn.rpc(rpc_cmd_e)._NCElement__doc
  File "/home/gns3/workspace/Nornir/.venv/lib/python3.6/site-packages/ncclient/manager.py", line 236, in execute
    huge_tree=self._huge_tree).request(*args, **kwds)
  File "/home/gns3/workspace/Nornir/.venv/lib/python3.6/site-packages/ncclient/operations/third_party/juniper/rpc.py", line 52, in request
    return self._request(rpc)
  File "/home/gns3/workspace/Nornir/.venv/lib/python3.6/site-packages/ncclient/operations/rpc.py", line 346, in _request
    raise RPCError(to_ele(self._reply._raw), errs=errors)
ncclient.operations.rpc.RPCError: error: invalid input at '/24' in ip address '172.16.1.1/24'
warning: mgd: statement must contain additional statements

During handling of the above exception, another exception occurred:

Traceback (most recent call last):
  File "/home/gns3/workspace/Nornir/.venv/lib/python3.6/site-packages/jnpr/junos/utils/config.py", line 456, in try_load
    **rpc_xattrs)
  File "/home/gns3/workspace/Nornir/.venv/lib/python3.6/site-packages/jnpr/junos/rpcmeta.py", line 277, in load_config
    return self._junos.execute(rpc, ignore_warning=ignore_warning)
  File "/home/gns3/workspace/Nornir/.venv/lib/python3.6/site-packages/jnpr/junos/decorators.py", line 76, in wrapper
    return function(*args, **kwargs)
  File "/home/gns3/workspace/Nornir/.venv/lib/python3.6/site-packages/jnpr/junos/decorators.py", line 31, in wrapper
    return function(*args, **kwargs)
  File "/home/gns3/workspace/Nornir/.venv/lib/python3.6/site-packages/jnpr/junos/device.py", line 797, in execute
    errs=ex)
jnpr.junos.exception.RpcError: RpcError(severity: error, bad_element: 172.16.1.1/24, message: error: invalid input at '/24' in ip address '172.16.1.1/24'
warning: mgd: statement must contain additional statements)

During handling of the above exception, another exception occurred:

Traceback (most recent call last):
  File "/home/gns3/workspace/Nornir/.venv/lib/python3.6/site-packages/napalm/junos/junos.py", line 241, in _load_candidate
    ignore_warning=self.ignore_warning,
  File "/home/gns3/workspace/Nornir/.venv/lib/python3.6/site-packages/jnpr/junos/utils/config.py", line 539, in load
    ignore_warning=ignore_warning)
  File "/home/gns3/workspace/Nornir/.venv/lib/python3.6/site-packages/jnpr/junos/utils/config.py", line 460, in try_load
    raise ConfigLoadError(cmd=err.cmd, rsp=err.rsp, errs=err.errs)
jnpr.junos.exception.ConfigLoadError: ConfigLoadError(severity: error, bad_element: 172.16.1.1/24, message: error: invalid input at '/24' in ip address '172.16.1.1/24'
warning: mgd: statement must contain additional statements)

During handling of the above exception, another exception occurred:

Traceback (most recent call last):
  File "/home/gns3/workspace/Nornir/.venv/lib/python3.6/site-packages/nornir/core/task.py", line 85, in start
    r = self.task(self, **self.params)
  File "/home/gns3/workspace/Nornir/.venv/lib/python3.6/site-packages/nornir/plugins/tasks/networking/napalm_configure.py", line 32, in napalm_configure
    device.load_merge_candidate(filename=filename, config=configuration)
  File "/home/gns3/workspace/Nornir/.venv/lib/python3.6/site-packages/napalm/junos/junos.py", line 257, in load_merge_candidate
    self._load_candidate(filename, config, False)
  File "/home/gns3/workspace/Nornir/.venv/lib/python3.6/site-packages/napalm/junos/junos.py", line 247, in _load_candidate
    raise MergeConfigException(e.errs)
napalm.base.exceptions.MergeConfigException: [{'severity': 'error', 'source': None, 'edit_path': None, 'bad_element': '172.16.1.1/24', 'message': "invalid input at '/24' in ip address '172.16.1.1/24'"}, {'severity': 'warning', 'source': None, 'edit_path': None, 'bad_element': None, 'message': 'mgd: statement must contain additional statements'}]

2020-04-24 21:34:23,150 - nornir.core.task -    ERROR -      start() - Host 'r2': task 'basic_configuration' failed with traceback:
Traceback (most recent call last):
  File "/home/gns3/workspace/Nornir/.venv/lib/python3.6/site-packages/nornir/core/task.py", line 85, in start
    r = self.task(self, **self.params)
  File "deploy_configs.py", line 15, in basic_configuration
    replace=False, configuration=task.host["config"])
  File "/home/gns3/workspace/Nornir/.venv/lib/python3.6/site-packages/nornir/core/task.py", line 147, in run
    raise NornirSubTaskError(task=task, result=r)
nornir.core.exceptions.NornirSubTaskError: Subtask: <function napalm_configure at 0x7fab4832f9d8> (failed)


2020-04-24 21:35:11,120 -  nornir.core -     INFO -        run() - Running task 'basic_configuration' with args {'template_name': 'routing_options.j2'} on 2 hosts
2020-04-24 21:53:57,585 -  nornir.core -     INFO -        run() - Running task 'basic_configuration' with args {'template_name': 'system.j2'} on 2 hosts
2020-04-24 21:53:57,601 - nornir.core.task -    ERROR -      start() - Host 'r1': task 'Base Configuration' failed with traceback:
Traceback (most recent call last):
  File "/home/gns3/workspace/Nornir/.venv/lib/python3.6/site-packages/nornir/core/task.py", line 85, in start
    r = self.task(self, **self.params)
  File "/home/gns3/workspace/Nornir/.venv/lib/python3.6/site-packages/nornir/plugins/tasks/text/template_file.py", line 35, in template_file
    **kwargs
  File "/home/gns3/workspace/Nornir/.venv/lib/python3.6/site-packages/nornir/core/helpers/jinja_helper.py", line 18, in render_from_file
    return t.render(**kwargs)
  File "/home/gns3/workspace/Nornir/.venv/lib/python3.6/site-packages/jinja2/environment.py", line 1090, in render
    self.environment.handle_exception()
  File "/home/gns3/workspace/Nornir/.venv/lib/python3.6/site-packages/jinja2/environment.py", line 832, in handle_exception
    reraise(*rewrite_traceback_stack(source=source))
  File "/home/gns3/workspace/Nornir/.venv/lib/python3.6/site-packages/jinja2/_compat.py", line 28, in reraise
    raise value.with_traceback(tb)
  File "templates/junos/system.j2", line 7, in top-level template code
    {% for class in host.user_classes %}
jinja2.exceptions.UndefinedError: 'nornir.core.inventory.Host object' has no attribute 'user_classes'

2020-04-24 21:53:57,601 - nornir.core.task -    ERROR -      start() - Host 'r1': task 'basic_configuration' failed with traceback:
Traceback (most recent call last):
  File "/home/gns3/workspace/Nornir/.venv/lib/python3.6/site-packages/nornir/core/task.py", line 85, in start
    r = self.task(self, **self.params)
  File "deploy_configs.py", line 10, in basic_configuration
    path=f"templates/{task.host.platform}")
  File "/home/gns3/workspace/Nornir/.venv/lib/python3.6/site-packages/nornir/core/task.py", line 147, in run
    raise NornirSubTaskError(task=task, result=r)
nornir.core.exceptions.NornirSubTaskError: Subtask: <function template_file at 0x7f8d4e0f7620> (failed)


2020-04-24 21:53:57,602 - nornir.core.task -    ERROR -      start() - Host 'r2': task 'Base Configuration' failed with traceback:
Traceback (most recent call last):
  File "/home/gns3/workspace/Nornir/.venv/lib/python3.6/site-packages/nornir/core/task.py", line 85, in start
    r = self.task(self, **self.params)
  File "/home/gns3/workspace/Nornir/.venv/lib/python3.6/site-packages/nornir/plugins/tasks/text/template_file.py", line 35, in template_file
    **kwargs
  File "/home/gns3/workspace/Nornir/.venv/lib/python3.6/site-packages/nornir/core/helpers/jinja_helper.py", line 18, in render_from_file
    return t.render(**kwargs)
  File "/home/gns3/workspace/Nornir/.venv/lib/python3.6/site-packages/jinja2/environment.py", line 1090, in render
    self.environment.handle_exception()
  File "/home/gns3/workspace/Nornir/.venv/lib/python3.6/site-packages/jinja2/environment.py", line 832, in handle_exception
    reraise(*rewrite_traceback_stack(source=source))
  File "/home/gns3/workspace/Nornir/.venv/lib/python3.6/site-packages/jinja2/_compat.py", line 28, in reraise
    raise value.with_traceback(tb)
  File "templates/junos/system.j2", line 7, in top-level template code
    {% for class in host.user_classes %}
jinja2.exceptions.UndefinedError: 'nornir.core.inventory.Host object' has no attribute 'user_classes'

2020-04-24 21:53:57,602 - nornir.core.task -    ERROR -      start() - Host 'r2': task 'basic_configuration' failed with traceback:
Traceback (most recent call last):
  File "/home/gns3/workspace/Nornir/.venv/lib/python3.6/site-packages/nornir/core/task.py", line 85, in start
    r = self.task(self, **self.params)
  File "deploy_configs.py", line 10, in basic_configuration
    path=f"templates/{task.host.platform}")
  File "/home/gns3/workspace/Nornir/.venv/lib/python3.6/site-packages/nornir/core/task.py", line 147, in run
    raise NornirSubTaskError(task=task, result=r)
nornir.core.exceptions.NornirSubTaskError: Subtask: <function template_file at 0x7f8d4e0f7620> (failed)


2020-04-24 21:55:25,888 -  nornir.core -     INFO -        run() - Running task 'basic_configuration' with args {'template_name': 'system.j2'} on 2 hosts
2020-04-24 21:55:25,905 - nornir.core.task -    ERROR -      start() - Host 'r1': task 'Base Configuration' failed with traceback:
Traceback (most recent call last):
  File "/home/gns3/workspace/Nornir/.venv/lib/python3.6/site-packages/nornir/core/task.py", line 85, in start
    r = self.task(self, **self.params)
  File "/home/gns3/workspace/Nornir/.venv/lib/python3.6/site-packages/nornir/plugins/tasks/text/template_file.py", line 35, in template_file
    **kwargs
  File "/home/gns3/workspace/Nornir/.venv/lib/python3.6/site-packages/nornir/core/helpers/jinja_helper.py", line 18, in render_from_file
    return t.render(**kwargs)
  File "/home/gns3/workspace/Nornir/.venv/lib/python3.6/site-packages/jinja2/environment.py", line 1090, in render
    self.environment.handle_exception()
  File "/home/gns3/workspace/Nornir/.venv/lib/python3.6/site-packages/jinja2/environment.py", line 832, in handle_exception
    reraise(*rewrite_traceback_stack(source=source))
  File "/home/gns3/workspace/Nornir/.venv/lib/python3.6/site-packages/jinja2/_compat.py", line 28, in reraise
    raise value.with_traceback(tb)
  File "templates/junos/system.j2", line 16, in top-level template code
    uid {{user_info.uid}};
jinja2.exceptions.UndefinedError: 'None' has no attribute 'uid'

2020-04-24 21:55:25,905 - nornir.core.task -    ERROR -      start() - Host 'r1': task 'basic_configuration' failed with traceback:
Traceback (most recent call last):
  File "/home/gns3/workspace/Nornir/.venv/lib/python3.6/site-packages/nornir/core/task.py", line 85, in start
    r = self.task(self, **self.params)
  File "deploy_configs.py", line 10, in basic_configuration
    path=f"templates/{task.host.platform}")
  File "/home/gns3/workspace/Nornir/.venv/lib/python3.6/site-packages/nornir/core/task.py", line 147, in run
    raise NornirSubTaskError(task=task, result=r)
nornir.core.exceptions.NornirSubTaskError: Subtask: <function template_file at 0x7f651c37c620> (failed)


2020-04-24 21:55:25,906 - nornir.core.task -    ERROR -      start() - Host 'r2': task 'Base Configuration' failed with traceback:
Traceback (most recent call last):
  File "/home/gns3/workspace/Nornir/.venv/lib/python3.6/site-packages/nornir/core/task.py", line 85, in start
    r = self.task(self, **self.params)
  File "/home/gns3/workspace/Nornir/.venv/lib/python3.6/site-packages/nornir/plugins/tasks/text/template_file.py", line 35, in template_file
    **kwargs
  File "/home/gns3/workspace/Nornir/.venv/lib/python3.6/site-packages/nornir/core/helpers/jinja_helper.py", line 18, in render_from_file
    return t.render(**kwargs)
  File "/home/gns3/workspace/Nornir/.venv/lib/python3.6/site-packages/jinja2/environment.py", line 1090, in render
    self.environment.handle_exception()
  File "/home/gns3/workspace/Nornir/.venv/lib/python3.6/site-packages/jinja2/environment.py", line 832, in handle_exception
    reraise(*rewrite_traceback_stack(source=source))
  File "/home/gns3/workspace/Nornir/.venv/lib/python3.6/site-packages/jinja2/_compat.py", line 28, in reraise
    raise value.with_traceback(tb)
  File "templates/junos/system.j2", line 16, in top-level template code
    uid {{user_info.uid}};
jinja2.exceptions.UndefinedError: 'None' has no attribute 'uid'

2020-04-24 21:55:25,906 - nornir.core.task -    ERROR -      start() - Host 'r2': task 'basic_configuration' failed with traceback:
Traceback (most recent call last):
  File "/home/gns3/workspace/Nornir/.venv/lib/python3.6/site-packages/nornir/core/task.py", line 85, in start
    r = self.task(self, **self.params)
  File "deploy_configs.py", line 10, in basic_configuration
    path=f"templates/{task.host.platform}")
  File "/home/gns3/workspace/Nornir/.venv/lib/python3.6/site-packages/nornir/core/task.py", line 147, in run
    raise NornirSubTaskError(task=task, result=r)
nornir.core.exceptions.NornirSubTaskError: Subtask: <function template_file at 0x7f651c37c620> (failed)


2020-04-24 21:56:01,163 -  nornir.core -     INFO -        run() - Running task 'basic_configuration' with args {'template_name': 'system.j2'} on 2 hosts
2020-04-24 22:01:07,778 -  nornir.core -     INFO -        run() - Running task 'basic_configuration' with args {'template_name': 'interfaces.j2'} on 2 hosts
2020-04-24 22:01:07,800 - nornir.core.task -    ERROR -      start() - Host 'r2': task 'Base Configuration' failed with traceback:
Traceback (most recent call last):
  File "/home/gns3/workspace/Nornir/.venv/lib/python3.6/site-packages/nornir/core/task.py", line 85, in start
    r = self.task(self, **self.params)
  File "/home/gns3/workspace/Nornir/.venv/lib/python3.6/site-packages/nornir/plugins/tasks/text/template_file.py", line 35, in template_file
    **kwargs
  File "/home/gns3/workspace/Nornir/.venv/lib/python3.6/site-packages/nornir/core/helpers/jinja_helper.py", line 18, in render_from_file
    return t.render(**kwargs)
  File "/home/gns3/workspace/Nornir/.venv/lib/python3.6/site-packages/jinja2/environment.py", line 1090, in render
    self.environment.handle_exception()
  File "/home/gns3/workspace/Nornir/.venv/lib/python3.6/site-packages/jinja2/environment.py", line 832, in handle_exception
    reraise(*rewrite_traceback_stack(source=source))
  File "/home/gns3/workspace/Nornir/.venv/lib/python3.6/site-packages/jinja2/_compat.py", line 28, in reraise
    raise value.with_traceback(tb)
  File "templates/junos/interfaces.j2", line 29, in top-level template code
    address {{pillar.loopbackv4}};
  File "/home/gns3/workspace/Nornir/.venv/lib/python3.6/site-packages/jinja2/environment.py", line 471, in getattr
    return getattr(obj, attribute)
jinja2.exceptions.UndefinedError: 'pillar' is undefined

2020-04-24 22:01:07,800 - nornir.core.task -    ERROR -      start() - Host 'r2': task 'basic_configuration' failed with traceback:
Traceback (most recent call last):
  File "/home/gns3/workspace/Nornir/.venv/lib/python3.6/site-packages/nornir/core/task.py", line 85, in start
    r = self.task(self, **self.params)
  File "deploy_configs.py", line 10, in basic_configuration
    path=f"templates/{task.host.platform}")
  File "/home/gns3/workspace/Nornir/.venv/lib/python3.6/site-packages/nornir/core/task.py", line 147, in run
    raise NornirSubTaskError(task=task, result=r)
nornir.core.exceptions.NornirSubTaskError: Subtask: <function template_file at 0x7f48d5d07620> (failed)


2020-04-24 22:01:07,801 - nornir.core.task -    ERROR -      start() - Host 'r1': task 'Base Configuration' failed with traceback:
Traceback (most recent call last):
  File "/home/gns3/workspace/Nornir/.venv/lib/python3.6/site-packages/nornir/core/task.py", line 85, in start
    r = self.task(self, **self.params)
  File "/home/gns3/workspace/Nornir/.venv/lib/python3.6/site-packages/nornir/plugins/tasks/text/template_file.py", line 35, in template_file
    **kwargs
  File "/home/gns3/workspace/Nornir/.venv/lib/python3.6/site-packages/nornir/core/helpers/jinja_helper.py", line 18, in render_from_file
    return t.render(**kwargs)
  File "/home/gns3/workspace/Nornir/.venv/lib/python3.6/site-packages/jinja2/environment.py", line 1090, in render
    self.environment.handle_exception()
  File "/home/gns3/workspace/Nornir/.venv/lib/python3.6/site-packages/jinja2/environment.py", line 832, in handle_exception
    reraise(*rewrite_traceback_stack(source=source))
  File "/home/gns3/workspace/Nornir/.venv/lib/python3.6/site-packages/jinja2/_compat.py", line 28, in reraise
    raise value.with_traceback(tb)
  File "templates/junos/interfaces.j2", line 29, in top-level template code
    address {{pillar.loopbackv4}};
  File "/home/gns3/workspace/Nornir/.venv/lib/python3.6/site-packages/jinja2/environment.py", line 471, in getattr
    return getattr(obj, attribute)
jinja2.exceptions.UndefinedError: 'pillar' is undefined

2020-04-24 22:01:07,801 - nornir.core.task -    ERROR -      start() - Host 'r1': task 'basic_configuration' failed with traceback:
Traceback (most recent call last):
  File "/home/gns3/workspace/Nornir/.venv/lib/python3.6/site-packages/nornir/core/task.py", line 85, in start
    r = self.task(self, **self.params)
  File "deploy_configs.py", line 10, in basic_configuration
    path=f"templates/{task.host.platform}")
  File "/home/gns3/workspace/Nornir/.venv/lib/python3.6/site-packages/nornir/core/task.py", line 147, in run
    raise NornirSubTaskError(task=task, result=r)
nornir.core.exceptions.NornirSubTaskError: Subtask: <function template_file at 0x7f48d5d07620> (failed)


2020-04-24 22:02:18,560 -  nornir.core -     INFO -        run() - Running task 'basic_configuration' with args {'template_name': 'interfaces.j2'} on 2 hosts
2020-04-24 22:02:19,628 - nornir.core.task -    ERROR -      start() - Host 'r1': task 'Loading Configuration on the device' failed with traceback:
Traceback (most recent call last):
  File "/home/gns3/workspace/Nornir/.venv/lib/python3.6/site-packages/jnpr/junos/device.py", line 777, in execute
    ignore_warning=ignore_warning)
  File "/home/gns3/workspace/Nornir/.venv/lib/python3.6/site-packages/jnpr/junos/decorators.py", line 169, in wrapper
    raise ex
  File "/home/gns3/workspace/Nornir/.venv/lib/python3.6/site-packages/jnpr/junos/decorators.py", line 116, in wrapper
    rsp = function(self, *args, **kwargs)
  File "/home/gns3/workspace/Nornir/.venv/lib/python3.6/site-packages/jnpr/junos/device.py", line 1339, in _rpc_reply
    return self._conn.rpc(rpc_cmd_e)._NCElement__doc
  File "/home/gns3/workspace/Nornir/.venv/lib/python3.6/site-packages/ncclient/manager.py", line 236, in execute
    huge_tree=self._huge_tree).request(*args, **kwds)
  File "/home/gns3/workspace/Nornir/.venv/lib/python3.6/site-packages/ncclient/operations/third_party/juniper/rpc.py", line 52, in request
    return self._request(rpc)
  File "/home/gns3/workspace/Nornir/.venv/lib/python3.6/site-packages/ncclient/operations/rpc.py", line 346, in _request
    raise RPCError(to_ele(self._reply._raw), errs=errors)
ncclient.operations.rpc.RPCError: error: syntax error
error: error recovery ignores input until this point
error: syntax error

During handling of the above exception, another exception occurred:

Traceback (most recent call last):
  File "/home/gns3/workspace/Nornir/.venv/lib/python3.6/site-packages/jnpr/junos/utils/config.py", line 456, in try_load
    **rpc_xattrs)
  File "/home/gns3/workspace/Nornir/.venv/lib/python3.6/site-packages/jnpr/junos/rpcmeta.py", line 277, in load_config
    return self._junos.execute(rpc, ignore_warning=ignore_warning)
  File "/home/gns3/workspace/Nornir/.venv/lib/python3.6/site-packages/jnpr/junos/decorators.py", line 76, in wrapper
    return function(*args, **kwargs)
  File "/home/gns3/workspace/Nornir/.venv/lib/python3.6/site-packages/jnpr/junos/decorators.py", line 31, in wrapper
    return function(*args, **kwargs)
  File "/home/gns3/workspace/Nornir/.venv/lib/python3.6/site-packages/jnpr/junos/device.py", line 797, in execute
    errs=ex)
jnpr.junos.exception.RpcError: RpcError(severity: error, bad_element: fxp0, message: error: syntax error
error: error recovery ignores input until this point
error: syntax error)

During handling of the above exception, another exception occurred:

Traceback (most recent call last):
  File "/home/gns3/workspace/Nornir/.venv/lib/python3.6/site-packages/napalm/junos/junos.py", line 241, in _load_candidate
    ignore_warning=self.ignore_warning,
  File "/home/gns3/workspace/Nornir/.venv/lib/python3.6/site-packages/jnpr/junos/utils/config.py", line 539, in load
    ignore_warning=ignore_warning)
  File "/home/gns3/workspace/Nornir/.venv/lib/python3.6/site-packages/jnpr/junos/utils/config.py", line 460, in try_load
    raise ConfigLoadError(cmd=err.cmd, rsp=err.rsp, errs=err.errs)
jnpr.junos.exception.ConfigLoadError: ConfigLoadError(severity: error, bad_element: fxp0, message: error: syntax error
error: error recovery ignores input until this point
error: syntax error)

During handling of the above exception, another exception occurred:

Traceback (most recent call last):
  File "/home/gns3/workspace/Nornir/.venv/lib/python3.6/site-packages/nornir/core/task.py", line 85, in start
    r = self.task(self, **self.params)
  File "/home/gns3/workspace/Nornir/.venv/lib/python3.6/site-packages/nornir/plugins/tasks/networking/napalm_configure.py", line 32, in napalm_configure
    device.load_merge_candidate(filename=filename, config=configuration)
  File "/home/gns3/workspace/Nornir/.venv/lib/python3.6/site-packages/napalm/junos/junos.py", line 257, in load_merge_candidate
    self._load_candidate(filename, config, False)
  File "/home/gns3/workspace/Nornir/.venv/lib/python3.6/site-packages/napalm/junos/junos.py", line 247, in _load_candidate
    raise MergeConfigException(e.errs)
napalm.base.exceptions.MergeConfigException: [{'severity': 'error', 'source': None, 'edit_path': None, 'bad_element': 'fxp0', 'message': 'syntax error'}, {'severity': 'error', 'source': None, 'edit_path': None, 'bad_element': '}', 'message': 'error recovery ignores input until this point'}, {'severity': 'error', 'source': None, 'edit_path': None, 'bad_element': None, 'message': 'syntax error'}]

2020-04-24 22:02:19,629 - nornir.core.task -    ERROR -      start() - Host 'r1': task 'basic_configuration' failed with traceback:
Traceback (most recent call last):
  File "/home/gns3/workspace/Nornir/.venv/lib/python3.6/site-packages/nornir/core/task.py", line 85, in start
    r = self.task(self, **self.params)
  File "deploy_configs.py", line 15, in basic_configuration
    replace=False, configuration=task.host["config"])
  File "/home/gns3/workspace/Nornir/.venv/lib/python3.6/site-packages/nornir/core/task.py", line 147, in run
    raise NornirSubTaskError(task=task, result=r)
nornir.core.exceptions.NornirSubTaskError: Subtask: <function napalm_configure at 0x7f89434e99d8> (failed)


2020-04-24 22:02:19,705 - nornir.core.task -    ERROR -      start() - Host 'r2': task 'Loading Configuration on the device' failed with traceback:
Traceback (most recent call last):
  File "/home/gns3/workspace/Nornir/.venv/lib/python3.6/site-packages/jnpr/junos/device.py", line 777, in execute
    ignore_warning=ignore_warning)
  File "/home/gns3/workspace/Nornir/.venv/lib/python3.6/site-packages/jnpr/junos/decorators.py", line 169, in wrapper
    raise ex
  File "/home/gns3/workspace/Nornir/.venv/lib/python3.6/site-packages/jnpr/junos/decorators.py", line 116, in wrapper
    rsp = function(self, *args, **kwargs)
  File "/home/gns3/workspace/Nornir/.venv/lib/python3.6/site-packages/jnpr/junos/device.py", line 1339, in _rpc_reply
    return self._conn.rpc(rpc_cmd_e)._NCElement__doc
  File "/home/gns3/workspace/Nornir/.venv/lib/python3.6/site-packages/ncclient/manager.py", line 236, in execute
    huge_tree=self._huge_tree).request(*args, **kwds)
  File "/home/gns3/workspace/Nornir/.venv/lib/python3.6/site-packages/ncclient/operations/third_party/juniper/rpc.py", line 52, in request
    return self._request(rpc)
  File "/home/gns3/workspace/Nornir/.venv/lib/python3.6/site-packages/ncclient/operations/rpc.py", line 346, in _request
    raise RPCError(to_ele(self._reply._raw), errs=errors)
ncclient.operations.rpc.RPCError: error: syntax error
error: error recovery ignores input until this point
error: syntax error

During handling of the above exception, another exception occurred:

Traceback (most recent call last):
  File "/home/gns3/workspace/Nornir/.venv/lib/python3.6/site-packages/jnpr/junos/utils/config.py", line 456, in try_load
    **rpc_xattrs)
  File "/home/gns3/workspace/Nornir/.venv/lib/python3.6/site-packages/jnpr/junos/rpcmeta.py", line 277, in load_config
    return self._junos.execute(rpc, ignore_warning=ignore_warning)
  File "/home/gns3/workspace/Nornir/.venv/lib/python3.6/site-packages/jnpr/junos/decorators.py", line 76, in wrapper
    return function(*args, **kwargs)
  File "/home/gns3/workspace/Nornir/.venv/lib/python3.6/site-packages/jnpr/junos/decorators.py", line 31, in wrapper
    return function(*args, **kwargs)
  File "/home/gns3/workspace/Nornir/.venv/lib/python3.6/site-packages/jnpr/junos/device.py", line 797, in execute
    errs=ex)
jnpr.junos.exception.RpcError: RpcError(severity: error, bad_element: fxp0, message: error: syntax error
error: error recovery ignores input until this point
error: syntax error)

During handling of the above exception, another exception occurred:

Traceback (most recent call last):
  File "/home/gns3/workspace/Nornir/.venv/lib/python3.6/site-packages/napalm/junos/junos.py", line 241, in _load_candidate
    ignore_warning=self.ignore_warning,
  File "/home/gns3/workspace/Nornir/.venv/lib/python3.6/site-packages/jnpr/junos/utils/config.py", line 539, in load
    ignore_warning=ignore_warning)
  File "/home/gns3/workspace/Nornir/.venv/lib/python3.6/site-packages/jnpr/junos/utils/config.py", line 460, in try_load
    raise ConfigLoadError(cmd=err.cmd, rsp=err.rsp, errs=err.errs)
jnpr.junos.exception.ConfigLoadError: ConfigLoadError(severity: error, bad_element: fxp0, message: error: syntax error
error: error recovery ignores input until this point
error: syntax error)

During handling of the above exception, another exception occurred:

Traceback (most recent call last):
  File "/home/gns3/workspace/Nornir/.venv/lib/python3.6/site-packages/nornir/core/task.py", line 85, in start
    r = self.task(self, **self.params)
  File "/home/gns3/workspace/Nornir/.venv/lib/python3.6/site-packages/nornir/plugins/tasks/networking/napalm_configure.py", line 32, in napalm_configure
    device.load_merge_candidate(filename=filename, config=configuration)
  File "/home/gns3/workspace/Nornir/.venv/lib/python3.6/site-packages/napalm/junos/junos.py", line 257, in load_merge_candidate
    self._load_candidate(filename, config, False)
  File "/home/gns3/workspace/Nornir/.venv/lib/python3.6/site-packages/napalm/junos/junos.py", line 247, in _load_candidate
    raise MergeConfigException(e.errs)
napalm.base.exceptions.MergeConfigException: [{'severity': 'error', 'source': None, 'edit_path': None, 'bad_element': 'fxp0', 'message': 'syntax error'}, {'severity': 'error', 'source': None, 'edit_path': None, 'bad_element': '}', 'message': 'error recovery ignores input until this point'}, {'severity': 'error', 'source': None, 'edit_path': None, 'bad_element': None, 'message': 'syntax error'}]

2020-04-24 22:02:19,706 - nornir.core.task -    ERROR -      start() - Host 'r2': task 'basic_configuration' failed with traceback:
Traceback (most recent call last):
  File "/home/gns3/workspace/Nornir/.venv/lib/python3.6/site-packages/nornir/core/task.py", line 85, in start
    r = self.task(self, **self.params)
  File "deploy_configs.py", line 15, in basic_configuration
    replace=False, configuration=task.host["config"])
  File "/home/gns3/workspace/Nornir/.venv/lib/python3.6/site-packages/nornir/core/task.py", line 147, in run
    raise NornirSubTaskError(task=task, result=r)
nornir.core.exceptions.NornirSubTaskError: Subtask: <function napalm_configure at 0x7f89434e99d8> (failed)


2020-04-24 22:03:58,248 -  nornir.core -     INFO -        run() - Running task 'basic_configuration' with args {'template_name': 'interfaces.j2'} on 2 hosts
2020-04-24 22:03:59,331 - nornir.core.task -    ERROR -      start() - Host 'r1': task 'Loading Configuration on the device' failed with traceback:
Traceback (most recent call last):
  File "/home/gns3/workspace/Nornir/.venv/lib/python3.6/site-packages/jnpr/junos/device.py", line 777, in execute
    ignore_warning=ignore_warning)
  File "/home/gns3/workspace/Nornir/.venv/lib/python3.6/site-packages/jnpr/junos/decorators.py", line 169, in wrapper
    raise ex
  File "/home/gns3/workspace/Nornir/.venv/lib/python3.6/site-packages/jnpr/junos/decorators.py", line 116, in wrapper
    rsp = function(self, *args, **kwargs)
  File "/home/gns3/workspace/Nornir/.venv/lib/python3.6/site-packages/jnpr/junos/device.py", line 1339, in _rpc_reply
    return self._conn.rpc(rpc_cmd_e)._NCElement__doc
  File "/home/gns3/workspace/Nornir/.venv/lib/python3.6/site-packages/ncclient/manager.py", line 236, in execute
    huge_tree=self._huge_tree).request(*args, **kwds)
  File "/home/gns3/workspace/Nornir/.venv/lib/python3.6/site-packages/ncclient/operations/third_party/juniper/rpc.py", line 52, in request
    return self._request(rpc)
  File "/home/gns3/workspace/Nornir/.venv/lib/python3.6/site-packages/ncclient/operations/rpc.py", line 346, in _request
    raise RPCError(to_ele(self._reply._raw), errs=errors)
ncclient.operations.rpc.RPCError: error: syntax error
error: error recovery ignores input until this point
error: syntax error

During handling of the above exception, another exception occurred:

Traceback (most recent call last):
  File "/home/gns3/workspace/Nornir/.venv/lib/python3.6/site-packages/jnpr/junos/utils/config.py", line 456, in try_load
    **rpc_xattrs)
  File "/home/gns3/workspace/Nornir/.venv/lib/python3.6/site-packages/jnpr/junos/rpcmeta.py", line 277, in load_config
    return self._junos.execute(rpc, ignore_warning=ignore_warning)
  File "/home/gns3/workspace/Nornir/.venv/lib/python3.6/site-packages/jnpr/junos/decorators.py", line 76, in wrapper
    return function(*args, **kwargs)
  File "/home/gns3/workspace/Nornir/.venv/lib/python3.6/site-packages/jnpr/junos/decorators.py", line 31, in wrapper
    return function(*args, **kwargs)
  File "/home/gns3/workspace/Nornir/.venv/lib/python3.6/site-packages/jnpr/junos/device.py", line 797, in execute
    errs=ex)
jnpr.junos.exception.RpcError: RpcError(severity: error, bad_element: fxp0, message: error: syntax error
error: error recovery ignores input until this point
error: syntax error)

During handling of the above exception, another exception occurred:

Traceback (most recent call last):
  File "/home/gns3/workspace/Nornir/.venv/lib/python3.6/site-packages/napalm/junos/junos.py", line 241, in _load_candidate
    ignore_warning=self.ignore_warning,
  File "/home/gns3/workspace/Nornir/.venv/lib/python3.6/site-packages/jnpr/junos/utils/config.py", line 539, in load
    ignore_warning=ignore_warning)
  File "/home/gns3/workspace/Nornir/.venv/lib/python3.6/site-packages/jnpr/junos/utils/config.py", line 460, in try_load
    raise ConfigLoadError(cmd=err.cmd, rsp=err.rsp, errs=err.errs)
jnpr.junos.exception.ConfigLoadError: ConfigLoadError(severity: error, bad_element: fxp0, message: error: syntax error
error: error recovery ignores input until this point
error: syntax error)

During handling of the above exception, another exception occurred:

Traceback (most recent call last):
  File "/home/gns3/workspace/Nornir/.venv/lib/python3.6/site-packages/nornir/core/task.py", line 85, in start
    r = self.task(self, **self.params)
  File "/home/gns3/workspace/Nornir/.venv/lib/python3.6/site-packages/nornir/plugins/tasks/networking/napalm_configure.py", line 32, in napalm_configure
    device.load_merge_candidate(filename=filename, config=configuration)
  File "/home/gns3/workspace/Nornir/.venv/lib/python3.6/site-packages/napalm/junos/junos.py", line 257, in load_merge_candidate
    self._load_candidate(filename, config, False)
  File "/home/gns3/workspace/Nornir/.venv/lib/python3.6/site-packages/napalm/junos/junos.py", line 247, in _load_candidate
    raise MergeConfigException(e.errs)
napalm.base.exceptions.MergeConfigException: [{'severity': 'error', 'source': None, 'edit_path': None, 'bad_element': 'fxp0', 'message': 'syntax error'}, {'severity': 'error', 'source': None, 'edit_path': None, 'bad_element': '}', 'message': 'error recovery ignores input until this point'}, {'severity': 'error', 'source': None, 'edit_path': None, 'bad_element': None, 'message': 'syntax error'}]

2020-04-24 22:03:59,332 - nornir.core.task -    ERROR -      start() - Host 'r1': task 'basic_configuration' failed with traceback:
Traceback (most recent call last):
  File "/home/gns3/workspace/Nornir/.venv/lib/python3.6/site-packages/nornir/core/task.py", line 85, in start
    r = self.task(self, **self.params)
  File "deploy_configs.py", line 15, in basic_configuration
    replace=False, configuration=task.host["config"])
  File "/home/gns3/workspace/Nornir/.venv/lib/python3.6/site-packages/nornir/core/task.py", line 147, in run
    raise NornirSubTaskError(task=task, result=r)
nornir.core.exceptions.NornirSubTaskError: Subtask: <function napalm_configure at 0x7efe5ea209d8> (failed)


2020-04-24 22:03:59,427 - nornir.core.task -    ERROR -      start() - Host 'r2': task 'Loading Configuration on the device' failed with traceback:
Traceback (most recent call last):
  File "/home/gns3/workspace/Nornir/.venv/lib/python3.6/site-packages/jnpr/junos/device.py", line 777, in execute
    ignore_warning=ignore_warning)
  File "/home/gns3/workspace/Nornir/.venv/lib/python3.6/site-packages/jnpr/junos/decorators.py", line 169, in wrapper
    raise ex
  File "/home/gns3/workspace/Nornir/.venv/lib/python3.6/site-packages/jnpr/junos/decorators.py", line 116, in wrapper
    rsp = function(self, *args, **kwargs)
  File "/home/gns3/workspace/Nornir/.venv/lib/python3.6/site-packages/jnpr/junos/device.py", line 1339, in _rpc_reply
    return self._conn.rpc(rpc_cmd_e)._NCElement__doc
  File "/home/gns3/workspace/Nornir/.venv/lib/python3.6/site-packages/ncclient/manager.py", line 236, in execute
    huge_tree=self._huge_tree).request(*args, **kwds)
  File "/home/gns3/workspace/Nornir/.venv/lib/python3.6/site-packages/ncclient/operations/third_party/juniper/rpc.py", line 52, in request
    return self._request(rpc)
  File "/home/gns3/workspace/Nornir/.venv/lib/python3.6/site-packages/ncclient/operations/rpc.py", line 346, in _request
    raise RPCError(to_ele(self._reply._raw), errs=errors)
ncclient.operations.rpc.RPCError: error: syntax error
error: error recovery ignores input until this point
error: syntax error

During handling of the above exception, another exception occurred:

Traceback (most recent call last):
  File "/home/gns3/workspace/Nornir/.venv/lib/python3.6/site-packages/jnpr/junos/utils/config.py", line 456, in try_load
    **rpc_xattrs)
  File "/home/gns3/workspace/Nornir/.venv/lib/python3.6/site-packages/jnpr/junos/rpcmeta.py", line 277, in load_config
    return self._junos.execute(rpc, ignore_warning=ignore_warning)
  File "/home/gns3/workspace/Nornir/.venv/lib/python3.6/site-packages/jnpr/junos/decorators.py", line 76, in wrapper
    return function(*args, **kwargs)
  File "/home/gns3/workspace/Nornir/.venv/lib/python3.6/site-packages/jnpr/junos/decorators.py", line 31, in wrapper
    return function(*args, **kwargs)
  File "/home/gns3/workspace/Nornir/.venv/lib/python3.6/site-packages/jnpr/junos/device.py", line 797, in execute
    errs=ex)
jnpr.junos.exception.RpcError: RpcError(severity: error, bad_element: fxp0, message: error: syntax error
error: error recovery ignores input until this point
error: syntax error)

During handling of the above exception, another exception occurred:

Traceback (most recent call last):
  File "/home/gns3/workspace/Nornir/.venv/lib/python3.6/site-packages/napalm/junos/junos.py", line 241, in _load_candidate
    ignore_warning=self.ignore_warning,
  File "/home/gns3/workspace/Nornir/.venv/lib/python3.6/site-packages/jnpr/junos/utils/config.py", line 539, in load
    ignore_warning=ignore_warning)
  File "/home/gns3/workspace/Nornir/.venv/lib/python3.6/site-packages/jnpr/junos/utils/config.py", line 460, in try_load
    raise ConfigLoadError(cmd=err.cmd, rsp=err.rsp, errs=err.errs)
jnpr.junos.exception.ConfigLoadError: ConfigLoadError(severity: error, bad_element: fxp0, message: error: syntax error
error: error recovery ignores input until this point
error: syntax error)

During handling of the above exception, another exception occurred:

Traceback (most recent call last):
  File "/home/gns3/workspace/Nornir/.venv/lib/python3.6/site-packages/nornir/core/task.py", line 85, in start
    r = self.task(self, **self.params)
  File "/home/gns3/workspace/Nornir/.venv/lib/python3.6/site-packages/nornir/plugins/tasks/networking/napalm_configure.py", line 32, in napalm_configure
    device.load_merge_candidate(filename=filename, config=configuration)
  File "/home/gns3/workspace/Nornir/.venv/lib/python3.6/site-packages/napalm/junos/junos.py", line 257, in load_merge_candidate
    self._load_candidate(filename, config, False)
  File "/home/gns3/workspace/Nornir/.venv/lib/python3.6/site-packages/napalm/junos/junos.py", line 247, in _load_candidate
    raise MergeConfigException(e.errs)
napalm.base.exceptions.MergeConfigException: [{'severity': 'error', 'source': None, 'edit_path': None, 'bad_element': 'fxp0', 'message': 'syntax error'}, {'severity': 'error', 'source': None, 'edit_path': None, 'bad_element': '}', 'message': 'error recovery ignores input until this point'}, {'severity': 'error', 'source': None, 'edit_path': None, 'bad_element': None, 'message': 'syntax error'}]

2020-04-24 22:03:59,428 - nornir.core.task -    ERROR -      start() - Host 'r2': task 'basic_configuration' failed with traceback:
Traceback (most recent call last):
  File "/home/gns3/workspace/Nornir/.venv/lib/python3.6/site-packages/nornir/core/task.py", line 85, in start
    r = self.task(self, **self.params)
  File "deploy_configs.py", line 15, in basic_configuration
    replace=False, configuration=task.host["config"])
  File "/home/gns3/workspace/Nornir/.venv/lib/python3.6/site-packages/nornir/core/task.py", line 147, in run
    raise NornirSubTaskError(task=task, result=r)
nornir.core.exceptions.NornirSubTaskError: Subtask: <function napalm_configure at 0x7efe5ea209d8> (failed)


2020-04-24 22:09:23,015 -  nornir.core -     INFO -        run() - Running task 'basic_configuration' with args {'template_name': 'interfaces.j2'} on 2 hosts
2020-04-24 22:09:24,077 - nornir.core.task -    ERROR -      start() - Host 'r1': task 'Loading Configuration on the device' failed with traceback:
Traceback (most recent call last):
  File "/home/gns3/workspace/Nornir/.venv/lib/python3.6/site-packages/jnpr/junos/device.py", line 777, in execute
    ignore_warning=ignore_warning)
  File "/home/gns3/workspace/Nornir/.venv/lib/python3.6/site-packages/jnpr/junos/decorators.py", line 169, in wrapper
    raise ex
  File "/home/gns3/workspace/Nornir/.venv/lib/python3.6/site-packages/jnpr/junos/decorators.py", line 116, in wrapper
    rsp = function(self, *args, **kwargs)
  File "/home/gns3/workspace/Nornir/.venv/lib/python3.6/site-packages/jnpr/junos/device.py", line 1339, in _rpc_reply
    return self._conn.rpc(rpc_cmd_e)._NCElement__doc
  File "/home/gns3/workspace/Nornir/.venv/lib/python3.6/site-packages/ncclient/manager.py", line 236, in execute
    huge_tree=self._huge_tree).request(*args, **kwds)
  File "/home/gns3/workspace/Nornir/.venv/lib/python3.6/site-packages/ncclient/operations/third_party/juniper/rpc.py", line 52, in request
    return self._request(rpc)
  File "/home/gns3/workspace/Nornir/.venv/lib/python3.6/site-packages/ncclient/operations/rpc.py", line 346, in _request
    raise RPCError(to_ele(self._reply._raw), errs=errors)
ncclient.operations.rpc.RPCError: error: syntax error
error: error recovery ignores input until this point
error: syntax error

During handling of the above exception, another exception occurred:

Traceback (most recent call last):
  File "/home/gns3/workspace/Nornir/.venv/lib/python3.6/site-packages/jnpr/junos/utils/config.py", line 456, in try_load
    **rpc_xattrs)
  File "/home/gns3/workspace/Nornir/.venv/lib/python3.6/site-packages/jnpr/junos/rpcmeta.py", line 277, in load_config
    return self._junos.execute(rpc, ignore_warning=ignore_warning)
  File "/home/gns3/workspace/Nornir/.venv/lib/python3.6/site-packages/jnpr/junos/decorators.py", line 76, in wrapper
    return function(*args, **kwargs)
  File "/home/gns3/workspace/Nornir/.venv/lib/python3.6/site-packages/jnpr/junos/decorators.py", line 31, in wrapper
    return function(*args, **kwargs)
  File "/home/gns3/workspace/Nornir/.venv/lib/python3.6/site-packages/jnpr/junos/device.py", line 797, in execute
    errs=ex)
jnpr.junos.exception.RpcError: RpcError(severity: error, bad_element: fxp0, message: error: syntax error
error: error recovery ignores input until this point
error: syntax error)

During handling of the above exception, another exception occurred:

Traceback (most recent call last):
  File "/home/gns3/workspace/Nornir/.venv/lib/python3.6/site-packages/napalm/junos/junos.py", line 241, in _load_candidate
    ignore_warning=self.ignore_warning,
  File "/home/gns3/workspace/Nornir/.venv/lib/python3.6/site-packages/jnpr/junos/utils/config.py", line 539, in load
    ignore_warning=ignore_warning)
  File "/home/gns3/workspace/Nornir/.venv/lib/python3.6/site-packages/jnpr/junos/utils/config.py", line 460, in try_load
    raise ConfigLoadError(cmd=err.cmd, rsp=err.rsp, errs=err.errs)
jnpr.junos.exception.ConfigLoadError: ConfigLoadError(severity: error, bad_element: fxp0, message: error: syntax error
error: error recovery ignores input until this point
error: syntax error)

During handling of the above exception, another exception occurred:

Traceback (most recent call last):
  File "/home/gns3/workspace/Nornir/.venv/lib/python3.6/site-packages/nornir/core/task.py", line 85, in start
    r = self.task(self, **self.params)
  File "/home/gns3/workspace/Nornir/.venv/lib/python3.6/site-packages/nornir/plugins/tasks/networking/napalm_configure.py", line 32, in napalm_configure
    device.load_merge_candidate(filename=filename, config=configuration)
  File "/home/gns3/workspace/Nornir/.venv/lib/python3.6/site-packages/napalm/junos/junos.py", line 257, in load_merge_candidate
    self._load_candidate(filename, config, False)
  File "/home/gns3/workspace/Nornir/.venv/lib/python3.6/site-packages/napalm/junos/junos.py", line 247, in _load_candidate
    raise MergeConfigException(e.errs)
napalm.base.exceptions.MergeConfigException: [{'severity': 'error', 'source': None, 'edit_path': None, 'bad_element': 'fxp0', 'message': 'syntax error'}, {'severity': 'error', 'source': None, 'edit_path': None, 'bad_element': '}', 'message': 'error recovery ignores input until this point'}, {'severity': 'error', 'source': None, 'edit_path': None, 'bad_element': None, 'message': 'syntax error'}]

2020-04-24 22:09:24,078 - nornir.core.task -    ERROR -      start() - Host 'r1': task 'basic_configuration' failed with traceback:
Traceback (most recent call last):
  File "/home/gns3/workspace/Nornir/.venv/lib/python3.6/site-packages/nornir/core/task.py", line 85, in start
    r = self.task(self, **self.params)
  File "deploy_configs.py", line 15, in basic_configuration
    replace=False, configuration=task.host["config"])
  File "/home/gns3/workspace/Nornir/.venv/lib/python3.6/site-packages/nornir/core/task.py", line 147, in run
    raise NornirSubTaskError(task=task, result=r)
nornir.core.exceptions.NornirSubTaskError: Subtask: <function napalm_configure at 0x7f7ae98be9d8> (failed)


2020-04-24 22:09:24,171 - nornir.core.task -    ERROR -      start() - Host 'r2': task 'Loading Configuration on the device' failed with traceback:
Traceback (most recent call last):
  File "/home/gns3/workspace/Nornir/.venv/lib/python3.6/site-packages/jnpr/junos/device.py", line 777, in execute
    ignore_warning=ignore_warning)
  File "/home/gns3/workspace/Nornir/.venv/lib/python3.6/site-packages/jnpr/junos/decorators.py", line 169, in wrapper
    raise ex
  File "/home/gns3/workspace/Nornir/.venv/lib/python3.6/site-packages/jnpr/junos/decorators.py", line 116, in wrapper
    rsp = function(self, *args, **kwargs)
  File "/home/gns3/workspace/Nornir/.venv/lib/python3.6/site-packages/jnpr/junos/device.py", line 1339, in _rpc_reply
    return self._conn.rpc(rpc_cmd_e)._NCElement__doc
  File "/home/gns3/workspace/Nornir/.venv/lib/python3.6/site-packages/ncclient/manager.py", line 236, in execute
    huge_tree=self._huge_tree).request(*args, **kwds)
  File "/home/gns3/workspace/Nornir/.venv/lib/python3.6/site-packages/ncclient/operations/third_party/juniper/rpc.py", line 52, in request
    return self._request(rpc)
  File "/home/gns3/workspace/Nornir/.venv/lib/python3.6/site-packages/ncclient/operations/rpc.py", line 346, in _request
    raise RPCError(to_ele(self._reply._raw), errs=errors)
ncclient.operations.rpc.RPCError: error: syntax error
error: error recovery ignores input until this point
error: syntax error

During handling of the above exception, another exception occurred:

Traceback (most recent call last):
  File "/home/gns3/workspace/Nornir/.venv/lib/python3.6/site-packages/jnpr/junos/utils/config.py", line 456, in try_load
    **rpc_xattrs)
  File "/home/gns3/workspace/Nornir/.venv/lib/python3.6/site-packages/jnpr/junos/rpcmeta.py", line 277, in load_config
    return self._junos.execute(rpc, ignore_warning=ignore_warning)
  File "/home/gns3/workspace/Nornir/.venv/lib/python3.6/site-packages/jnpr/junos/decorators.py", line 76, in wrapper
    return function(*args, **kwargs)
  File "/home/gns3/workspace/Nornir/.venv/lib/python3.6/site-packages/jnpr/junos/decorators.py", line 31, in wrapper
    return function(*args, **kwargs)
  File "/home/gns3/workspace/Nornir/.venv/lib/python3.6/site-packages/jnpr/junos/device.py", line 797, in execute
    errs=ex)
jnpr.junos.exception.RpcError: RpcError(severity: error, bad_element: fxp0, message: error: syntax error
error: error recovery ignores input until this point
error: syntax error)

During handling of the above exception, another exception occurred:

Traceback (most recent call last):
  File "/home/gns3/workspace/Nornir/.venv/lib/python3.6/site-packages/napalm/junos/junos.py", line 241, in _load_candidate
    ignore_warning=self.ignore_warning,
  File "/home/gns3/workspace/Nornir/.venv/lib/python3.6/site-packages/jnpr/junos/utils/config.py", line 539, in load
    ignore_warning=ignore_warning)
  File "/home/gns3/workspace/Nornir/.venv/lib/python3.6/site-packages/jnpr/junos/utils/config.py", line 460, in try_load
    raise ConfigLoadError(cmd=err.cmd, rsp=err.rsp, errs=err.errs)
jnpr.junos.exception.ConfigLoadError: ConfigLoadError(severity: error, bad_element: fxp0, message: error: syntax error
error: error recovery ignores input until this point
error: syntax error)

During handling of the above exception, another exception occurred:

Traceback (most recent call last):
  File "/home/gns3/workspace/Nornir/.venv/lib/python3.6/site-packages/nornir/core/task.py", line 85, in start
    r = self.task(self, **self.params)
  File "/home/gns3/workspace/Nornir/.venv/lib/python3.6/site-packages/nornir/plugins/tasks/networking/napalm_configure.py", line 32, in napalm_configure
    device.load_merge_candidate(filename=filename, config=configuration)
  File "/home/gns3/workspace/Nornir/.venv/lib/python3.6/site-packages/napalm/junos/junos.py", line 257, in load_merge_candidate
    self._load_candidate(filename, config, False)
  File "/home/gns3/workspace/Nornir/.venv/lib/python3.6/site-packages/napalm/junos/junos.py", line 247, in _load_candidate
    raise MergeConfigException(e.errs)
napalm.base.exceptions.MergeConfigException: [{'severity': 'error', 'source': None, 'edit_path': None, 'bad_element': 'fxp0', 'message': 'syntax error'}, {'severity': 'error', 'source': None, 'edit_path': None, 'bad_element': '}', 'message': 'error recovery ignores input until this point'}, {'severity': 'error', 'source': None, 'edit_path': None, 'bad_element': None, 'message': 'syntax error'}]

2020-04-24 22:09:24,172 - nornir.core.task -    ERROR -      start() - Host 'r2': task 'basic_configuration' failed with traceback:
Traceback (most recent call last):
  File "/home/gns3/workspace/Nornir/.venv/lib/python3.6/site-packages/nornir/core/task.py", line 85, in start
    r = self.task(self, **self.params)
  File "deploy_configs.py", line 15, in basic_configuration
    replace=False, configuration=task.host["config"])
  File "/home/gns3/workspace/Nornir/.venv/lib/python3.6/site-packages/nornir/core/task.py", line 147, in run
    raise NornirSubTaskError(task=task, result=r)
nornir.core.exceptions.NornirSubTaskError: Subtask: <function napalm_configure at 0x7f7ae98be9d8> (failed)


2020-04-24 22:19:25,714 -  nornir.core -     INFO -        run() - Running task 'basic_configuration' with args {'template_name': 'interfaces.j2'} on 2 hosts
2020-04-24 22:34:14,791 -  nornir.core -     INFO -        run() - Running task 'basic_configuration' with args {'template_name': 'ntp.j2'} on 2 hosts
2020-04-24 22:35:08,398 -  nornir.core -     INFO -        run() - Running task 'basic_configuration' with args {'template_name': 'ntp.j2'} on 2 hosts
2020-04-24 22:36:21,477 -  nornir.core -     INFO -        run() - Running task 'basic_configuration' with args {'template_name': 'ntp.j2'} on 2 hosts
2020-04-24 22:39:06,353 -  nornir.core -     INFO -        run() - Running task 'basic_configuration' with args {'template_name': 'dns.j2'} on 2 hosts
2020-04-24 22:45:39,733 -  nornir.core -     INFO -        run() - Running task 'basic_configuration' with args {'template_name': 'interfaces.j2'} on 2 hosts
2020-04-24 22:46:02,891 -  nornir.core -     INFO -        run() - Running task 'basic_configuration' with args {'template_name': 'interfaces.j2'} on 2 hosts
2020-04-24 23:22:33,863 -  nornir.core -     INFO -        run() - Running task 'basic_configuration' with args {'template_name': 'ntp.j2'} on 1 hosts
2020-04-24 23:23:55,088 -  nornir.core -     INFO -        run() - Running task 'basic_configuration' with args {'template_name': 'ntp.j2'} on 1 hosts
2020-04-24 23:24:20,697 -  nornir.core -     INFO -        run() - Running task 'basic_configuration' with args {'template_name': 'ntp.j2'} on 1 hosts
2020-04-24 23:24:48,814 - nornir.core.task -    ERROR -      start() - Host 'r4': task 'Loading Configuration on the device' failed with traceback:
Traceback (most recent call last):
  File "/home/gns3/.local/lib/python3.6/site-packages/paramiko/channel.py", line 699, in recv
    out = self.in_buffer.read(nbytes, self.timeout)
  File "/home/gns3/.local/lib/python3.6/site-packages/paramiko/buffered_pipe.py", line 164, in read
    raise PipeTimeout()
paramiko.buffered_pipe.PipeTimeout

During handling of the above exception, another exception occurred:

Traceback (most recent call last):
  File "/home/gns3/.local/lib/python3.6/site-packages/netmiko/base_connection.py", line 550, in _read_channel_expect
    new_data = self.remote_conn.recv(MAX_BUFFER)
  File "/home/gns3/.local/lib/python3.6/site-packages/paramiko/channel.py", line 701, in recv
    raise socket.timeout()
socket.timeout

During handling of the above exception, another exception occurred:

Traceback (most recent call last):
  File "/home/gns3/.local/lib/python3.6/site-packages/nornir/core/task.py", line 85, in start
    r = self.task(self, **self.params)
  File "/home/gns3/.local/lib/python3.6/site-packages/nornir/plugins/tasks/networking/napalm_configure.py", line 32, in napalm_configure
    device.load_merge_candidate(filename=filename, config=configuration)
  File "/home/gns3/.local/lib/python3.6/site-packages/napalm/iosxr/iosxr.py", line 111, in load_merge_candidate
    self.device.lock()
  File "/home/gns3/.local/lib/python3.6/site-packages/pyIOSXR/iosxr.py", line 476, in lock
    self._execute_rpc(rpc_command)
  File "/home/gns3/.local/lib/python3.6/site-packages/pyIOSXR/iosxr.py", line 365, in _execute_rpc
    response = self._send_command(xml_rpc_command, delay_factor=delay_factor)
  File "/home/gns3/.local/lib/python3.6/site-packages/pyIOSXR/iosxr.py", line 275, in _send_command
    max_loops=max_loops)
  File "/home/gns3/.local/lib/python3.6/site-packages/netmiko/base_connection.py", line 1470, in send_command_expect
    return self.send_command(*args, **kwargs)
  File "/home/gns3/.local/lib/python3.6/site-packages/netmiko/utilities.py", line 347, in wrapper_decorator
    return func(self, *args, **kwargs)
  File "/home/gns3/.local/lib/python3.6/site-packages/netmiko/base_connection.py", line 1389, in send_command
    new_data = self.read_until_pattern(pattern=re.escape(cmd))
  File "/home/gns3/.local/lib/python3.6/site-packages/netmiko/base_connection.py", line 627, in read_until_pattern
    return self._read_channel_expect(*args, **kwargs)
  File "/home/gns3/.local/lib/python3.6/site-packages/netmiko/base_connection.py", line 561, in _read_channel_expect
    "Timed-out reading channel, data not available."
netmiko.ssh_exception.NetmikoTimeoutException: Timed-out reading channel, data not available.

2020-04-24 23:24:48,815 - nornir.core.task -    ERROR -      start() - Host 'r4': task 'basic_configuration' failed with traceback:
Traceback (most recent call last):
  File "/home/gns3/.local/lib/python3.6/site-packages/nornir/core/task.py", line 85, in start
    r = self.task(self, **self.params)
  File "deploy_configs.py", line 15, in basic_configuration
    replace=False, configuration=task.host["config"])
  File "/home/gns3/.local/lib/python3.6/site-packages/nornir/core/task.py", line 147, in run
    raise NornirSubTaskError(task=task, result=r)
nornir.core.exceptions.NornirSubTaskError: Subtask: <function napalm_configure at 0x7f15314b2c80> (failed)


2020-04-24 23:25:14,320 -  nornir.core -     INFO -        run() - Running task 'basic_configuration' with args {'template_name': 'ntp.j2'} on 1 hosts
2020-04-24 23:25:14,325 - nornir.core.task -    ERROR -      start() - Host 'r3': task 'Base Configuration' failed with traceback:
Traceback (most recent call last):
  File "/home/gns3/.local/lib/python3.6/site-packages/nornir/core/task.py", line 85, in start
    r = self.task(self, **self.params)
  File "/home/gns3/.local/lib/python3.6/site-packages/nornir/plugins/tasks/text/template_file.py", line 35, in template_file
    **kwargs
  File "/home/gns3/.local/lib/python3.6/site-packages/nornir/core/helpers/jinja_helper.py", line 17, in render_from_file
    t = env.get_template(template)
  File "/home/gns3/.local/lib/python3.6/site-packages/jinja2/environment.py", line 883, in get_template
    return self._load_template(name, self.make_globals(globals))
  File "/home/gns3/.local/lib/python3.6/site-packages/jinja2/environment.py", line 857, in _load_template
    template = self.loader.load(self, name, globals)
  File "/home/gns3/.local/lib/python3.6/site-packages/jinja2/loaders.py", line 115, in load
    source, filename, uptodate = self.get_source(environment, name)
  File "/home/gns3/.local/lib/python3.6/site-packages/jinja2/loaders.py", line 197, in get_source
    raise TemplateNotFound(template)
jinja2.exceptions.TemplateNotFound: ntp.j2

2020-04-24 23:25:14,325 - nornir.core.task -    ERROR -      start() - Host 'r3': task 'basic_configuration' failed with traceback:
Traceback (most recent call last):
  File "/home/gns3/.local/lib/python3.6/site-packages/nornir/core/task.py", line 85, in start
    r = self.task(self, **self.params)
  File "deploy_configs.py", line 10, in basic_configuration
    path=f"templates/{task.host.platform}")
  File "/home/gns3/.local/lib/python3.6/site-packages/nornir/core/task.py", line 147, in run
    raise NornirSubTaskError(task=task, result=r)
nornir.core.exceptions.NornirSubTaskError: Subtask: <function template_file at 0x7fd1277df8c8> (failed)


2020-04-24 23:26:07,292 -  nornir.core -     INFO -        run() - Running task 'basic_configuration' with args {'template_name': 'dns.j2'} on 1 hosts
2020-04-24 23:26:35,562 - nornir.core.task -    ERROR -      start() - Host 'r4': task 'Loading Configuration on the device' failed with traceback:
Traceback (most recent call last):
  File "/home/gns3/.local/lib/python3.6/site-packages/paramiko/channel.py", line 699, in recv
    out = self.in_buffer.read(nbytes, self.timeout)
  File "/home/gns3/.local/lib/python3.6/site-packages/paramiko/buffered_pipe.py", line 164, in read
    raise PipeTimeout()
paramiko.buffered_pipe.PipeTimeout

During handling of the above exception, another exception occurred:

Traceback (most recent call last):
  File "/home/gns3/.local/lib/python3.6/site-packages/netmiko/base_connection.py", line 550, in _read_channel_expect
    new_data = self.remote_conn.recv(MAX_BUFFER)
  File "/home/gns3/.local/lib/python3.6/site-packages/paramiko/channel.py", line 701, in recv
    raise socket.timeout()
socket.timeout

During handling of the above exception, another exception occurred:

Traceback (most recent call last):
  File "/home/gns3/.local/lib/python3.6/site-packages/nornir/core/task.py", line 85, in start
    r = self.task(self, **self.params)
  File "/home/gns3/.local/lib/python3.6/site-packages/nornir/plugins/tasks/networking/napalm_configure.py", line 32, in napalm_configure
    device.load_merge_candidate(filename=filename, config=configuration)
  File "/home/gns3/.local/lib/python3.6/site-packages/napalm/iosxr/iosxr.py", line 111, in load_merge_candidate
    self.device.lock()
  File "/home/gns3/.local/lib/python3.6/site-packages/pyIOSXR/iosxr.py", line 476, in lock
    self._execute_rpc(rpc_command)
  File "/home/gns3/.local/lib/python3.6/site-packages/pyIOSXR/iosxr.py", line 365, in _execute_rpc
    response = self._send_command(xml_rpc_command, delay_factor=delay_factor)
  File "/home/gns3/.local/lib/python3.6/site-packages/pyIOSXR/iosxr.py", line 275, in _send_command
    max_loops=max_loops)
  File "/home/gns3/.local/lib/python3.6/site-packages/netmiko/base_connection.py", line 1470, in send_command_expect
    return self.send_command(*args, **kwargs)
  File "/home/gns3/.local/lib/python3.6/site-packages/netmiko/utilities.py", line 347, in wrapper_decorator
    return func(self, *args, **kwargs)
  File "/home/gns3/.local/lib/python3.6/site-packages/netmiko/base_connection.py", line 1389, in send_command
    new_data = self.read_until_pattern(pattern=re.escape(cmd))
  File "/home/gns3/.local/lib/python3.6/site-packages/netmiko/base_connection.py", line 627, in read_until_pattern
    return self._read_channel_expect(*args, **kwargs)
  File "/home/gns3/.local/lib/python3.6/site-packages/netmiko/base_connection.py", line 561, in _read_channel_expect
    "Timed-out reading channel, data not available."
netmiko.ssh_exception.NetmikoTimeoutException: Timed-out reading channel, data not available.

2020-04-24 23:26:35,562 - nornir.core.task -    ERROR -      start() - Host 'r4': task 'basic_configuration' failed with traceback:
Traceback (most recent call last):
  File "/home/gns3/.local/lib/python3.6/site-packages/nornir/core/task.py", line 85, in start
    r = self.task(self, **self.params)
  File "deploy_configs.py", line 15, in basic_configuration
    replace=False, configuration=task.host["config"])
  File "/home/gns3/.local/lib/python3.6/site-packages/nornir/core/task.py", line 147, in run
    raise NornirSubTaskError(task=task, result=r)
nornir.core.exceptions.NornirSubTaskError: Subtask: <function napalm_configure at 0x7f95e22e7c80> (failed)


2020-04-24 23:31:27,021 -  nornir.core -     INFO -        run() - Running task 'basic_configuration' with args {'template_name': 'dns.j2'} on 1 hosts
2020-04-24 23:31:27,063 - nornir.core.task -    ERROR -      start() - Host 'r3': task 'Loading Configuration on the device' failed with traceback:
Traceback (most recent call last):
  File "/home/gns3/.local/lib/python3.6/site-packages/pyeapi/eapilib.py", line 436, in send
    self.transport.endheaders(message_body=data)
  File "/usr/lib/python3.6/http/client.py", line 1259, in endheaders
    self._send_output(message_body, encode_chunked=encode_chunked)
  File "/usr/lib/python3.6/http/client.py", line 1038, in _send_output
    self.send(msg)
  File "/usr/lib/python3.6/http/client.py", line 976, in send
    self.connect()
  File "/usr/lib/python3.6/http/client.py", line 1417, in connect
    super().connect()
  File "/usr/lib/python3.6/http/client.py", line 948, in connect
    (self.host,self.port), self.timeout, self.source_address)
  File "/usr/lib/python3.6/socket.py", line 724, in create_connection
    raise err
  File "/usr/lib/python3.6/socket.py", line 713, in create_connection
    sock.connect(sa)
ConnectionRefusedError: [Errno 111] Connection refused

During handling of the above exception, another exception occurred:

Traceback (most recent call last):
  File "/home/gns3/.local/lib/python3.6/site-packages/napalm/eos/eos.py", line 164, in open
    self.device.run_commands(["show clock"], encoding="text")
  File "/home/gns3/.local/lib/python3.6/site-packages/pyeapi/client.py", line 743, in run_commands
    response = self._connection.execute(commands, encoding, **kwargs)
  File "/home/gns3/.local/lib/python3.6/site-packages/pyeapi/eapilib.py", line 550, in execute
    response = self.send(request)
  File "/home/gns3/.local/lib/python3.6/site-packages/pyeapi/eapilib.py", line 479, in send
    raise ConnectionError(str(self), error_msg)
pyeapi.eapilib.ConnectionError: Socket error during eAPI connection: [Errno 111] Connection refused

During handling of the above exception, another exception occurred:

Traceback (most recent call last):
  File "/home/gns3/.local/lib/python3.6/site-packages/nornir/core/task.py", line 85, in start
    r = self.task(self, **self.params)
  File "/home/gns3/.local/lib/python3.6/site-packages/nornir/plugins/tasks/networking/napalm_configure.py", line 27, in napalm_configure
    device = task.host.get_connection("napalm", task.nornir.config)
  File "/home/gns3/.local/lib/python3.6/site-packages/nornir/core/inventory.py", line 302, in get_connection
    extras=conn.extras,
  File "/home/gns3/.local/lib/python3.6/site-packages/nornir/core/inventory.py", line 352, in open_connection
    configuration=configuration,
  File "/home/gns3/.local/lib/python3.6/site-packages/nornir/plugins/connections/napalm.py", line 51, in open
    connection.open()
  File "/home/gns3/.local/lib/python3.6/site-packages/napalm/eos/eos.py", line 169, in open
    raise ConnectionException(py23_compat.text_type(ce))
napalm.base.exceptions.ConnectionException: Socket error during eAPI connection: [Errno 111] Connection refused

2020-04-24 23:31:27,063 - nornir.core.task -    ERROR -      start() - Host 'r3': task 'basic_configuration' failed with traceback:
Traceback (most recent call last):
  File "/home/gns3/.local/lib/python3.6/site-packages/nornir/core/task.py", line 85, in start
    r = self.task(self, **self.params)
  File "deploy_configs.py", line 15, in basic_configuration
    replace=False, configuration=task.host["config"])
  File "/home/gns3/.local/lib/python3.6/site-packages/nornir/core/task.py", line 147, in run
    raise NornirSubTaskError(task=task, result=r)
nornir.core.exceptions.NornirSubTaskError: Subtask: <function napalm_configure at 0x7f892a3f6c80> (failed)


2020-04-24 23:31:39,953 -  nornir.core -     INFO -        run() - Running task 'basic_configuration' with args {'template_name': 'dns.j2'} on 1 hosts
2020-04-24 23:34:40,784 -  nornir.core -     INFO -        run() - Running task 'basic_configuration' with args {'template_name': 'ntp.j2'} on 1 hosts
2020-04-24 23:34:53,115 -  nornir.core -     INFO -        run() - Running task 'basic_configuration' with args {'template_name': 'ntp.j2'} on 1 hosts
2020-04-24 23:48:08,870 -  nornir.core -     INFO -        run() - Running task 'basic_configuration' with args {'template_name': 'interfaces.j2'} on 2 hosts
2020-04-24 23:48:08,889 - nornir.core.task -    ERROR -      start() - Host 'r2': task 'Base Configuration' failed with traceback:
Traceback (most recent call last):
  File "/home/gns3/.local/lib/python3.6/site-packages/nornir/core/task.py", line 85, in start
    r = self.task(self, **self.params)
  File "/home/gns3/.local/lib/python3.6/site-packages/nornir/plugins/tasks/text/template_file.py", line 35, in template_file
    **kwargs
  File "/home/gns3/.local/lib/python3.6/site-packages/nornir/core/helpers/jinja_helper.py", line 18, in render_from_file
    return t.render(**kwargs)
  File "/home/gns3/.local/lib/python3.6/site-packages/jinja2/environment.py", line 1090, in render
    self.environment.handle_exception()
  File "/home/gns3/.local/lib/python3.6/site-packages/jinja2/environment.py", line 832, in handle_exception
    reraise(*rewrite_traceback_stack(source=source))
  File "/home/gns3/.local/lib/python3.6/site-packages/jinja2/_compat.py", line 28, in reraise
    raise value.with_traceback(tb)
  File "templates/junos/interfaces.j2", line 14, in top-level template code
    {% if address_dict.ipv6addr %}
jinja2.exceptions.UndefinedError: 'dict object' has no attribute 'ipv6addr'

2020-04-24 23:48:08,889 - nornir.core.task -    ERROR -      start() - Host 'r2': task 'basic_configuration' failed with traceback:
Traceback (most recent call last):
  File "/home/gns3/.local/lib/python3.6/site-packages/nornir/core/task.py", line 85, in start
    r = self.task(self, **self.params)
  File "deploy_configs.py", line 10, in basic_configuration
    path=f"templates/{task.host.platform}")
  File "/home/gns3/.local/lib/python3.6/site-packages/nornir/core/task.py", line 147, in run
    raise NornirSubTaskError(task=task, result=r)
nornir.core.exceptions.NornirSubTaskError: Subtask: <function template_file at 0x7f20eee558c8> (failed)


2020-04-24 23:53:56,123 -  nornir.core -     INFO -        run() - Running task 'basic_configuration' with args {'template_name': 'interfaces.j2'} on 2 hosts
2020-04-24 23:54:12,193 -  nornir.core -     INFO -        run() - Running task 'basic_configuration' with args {'template_name': 'interfaces.j2'} on 1 hosts
2020-04-24 23:55:28,433 -  nornir.core -     INFO -        run() - Running task 'basic_configuration' with args {'template_name': 'interfaces.j2'} on 1 hosts
2020-04-24 23:56:42,334 -  nornir.core -     INFO -        run() - Running task 'basic_configuration' with args {'template_name': 'interfaces.j2'} on 1 hosts
2020-04-24 23:57:10,563 - nornir.core.task -    ERROR -      start() - Host 'r4': task 'Loading Configuration on the device' failed with traceback:
Traceback (most recent call last):
  File "/home/gns3/.local/lib/python3.6/site-packages/paramiko/channel.py", line 699, in recv
    out = self.in_buffer.read(nbytes, self.timeout)
  File "/home/gns3/.local/lib/python3.6/site-packages/paramiko/buffered_pipe.py", line 164, in read
    raise PipeTimeout()
paramiko.buffered_pipe.PipeTimeout

During handling of the above exception, another exception occurred:

Traceback (most recent call last):
  File "/home/gns3/.local/lib/python3.6/site-packages/netmiko/base_connection.py", line 550, in _read_channel_expect
    new_data = self.remote_conn.recv(MAX_BUFFER)
  File "/home/gns3/.local/lib/python3.6/site-packages/paramiko/channel.py", line 701, in recv
    raise socket.timeout()
socket.timeout

During handling of the above exception, another exception occurred:

Traceback (most recent call last):
  File "/home/gns3/.local/lib/python3.6/site-packages/nornir/core/task.py", line 85, in start
    r = self.task(self, **self.params)
  File "/home/gns3/.local/lib/python3.6/site-packages/nornir/plugins/tasks/networking/napalm_configure.py", line 32, in napalm_configure
    device.load_merge_candidate(filename=filename, config=configuration)
  File "/home/gns3/.local/lib/python3.6/site-packages/napalm/iosxr/iosxr.py", line 111, in load_merge_candidate
    self.device.lock()
  File "/home/gns3/.local/lib/python3.6/site-packages/pyIOSXR/iosxr.py", line 476, in lock
    self._execute_rpc(rpc_command)
  File "/home/gns3/.local/lib/python3.6/site-packages/pyIOSXR/iosxr.py", line 365, in _execute_rpc
    response = self._send_command(xml_rpc_command, delay_factor=delay_factor)
  File "/home/gns3/.local/lib/python3.6/site-packages/pyIOSXR/iosxr.py", line 275, in _send_command
    max_loops=max_loops)
  File "/home/gns3/.local/lib/python3.6/site-packages/netmiko/base_connection.py", line 1470, in send_command_expect
    return self.send_command(*args, **kwargs)
  File "/home/gns3/.local/lib/python3.6/site-packages/netmiko/utilities.py", line 347, in wrapper_decorator
    return func(self, *args, **kwargs)
  File "/home/gns3/.local/lib/python3.6/site-packages/netmiko/base_connection.py", line 1389, in send_command
    new_data = self.read_until_pattern(pattern=re.escape(cmd))
  File "/home/gns3/.local/lib/python3.6/site-packages/netmiko/base_connection.py", line 627, in read_until_pattern
    return self._read_channel_expect(*args, **kwargs)
  File "/home/gns3/.local/lib/python3.6/site-packages/netmiko/base_connection.py", line 561, in _read_channel_expect
    "Timed-out reading channel, data not available."
netmiko.ssh_exception.NetmikoTimeoutException: Timed-out reading channel, data not available.

2020-04-24 23:57:10,564 - nornir.core.task -    ERROR -      start() - Host 'r4': task 'basic_configuration' failed with traceback:
Traceback (most recent call last):
  File "/home/gns3/.local/lib/python3.6/site-packages/nornir/core/task.py", line 85, in start
    r = self.task(self, **self.params)
  File "deploy_configs.py", line 15, in basic_configuration
    replace=False, configuration=task.host["config"])
  File "/home/gns3/.local/lib/python3.6/site-packages/nornir/core/task.py", line 147, in run
    raise NornirSubTaskError(task=task, result=r)
nornir.core.exceptions.NornirSubTaskError: Subtask: <function napalm_configure at 0x7f0fdd962c80> (failed)


2020-04-25 00:00:29,366 -  nornir.core -     INFO -        run() - Running task 'basic_configuration' with args {'template_name': 'system.j2'} on 2 hosts
2020-04-25 00:01:31,144 -  nornir.core -     INFO -        run() - Running task 'basic_configuration' with args {'template_name': 'dns.j2'} on 2 hosts
2020-04-25 00:01:56,273 -  nornir.core -     INFO -        run() - Running task 'basic_configuration' with args {'template_name': 'interfaces.j2'} on 2 hosts
2020-04-25 00:02:19,240 -  nornir.core -     INFO -        run() - Running task 'basic_configuration' with args {'template_name': 'ntp.j2'} on 1 hosts
2020-04-25 00:02:53,886 -  nornir.core -     INFO -        run() - Running task 'basic_configuration' with args {'template_name': 'ntp.j2'} on 2 hosts
2020-04-25 00:03:28,922 -  nornir.core -     INFO -        run() - Running task 'basic_configuration' with args {'template_name': 'routing_options.j2'} on 2 hosts
2020-04-25 00:04:03,229 -  nornir.core -     INFO -        run() - Running task 'basic_configuration' with args {'template_name': 'all.j2'} on 2 hosts
2020-04-25 00:04:03,236 - nornir.core.task -    ERROR -      start() - Host 'r2': task 'Base Configuration' failed with traceback:
Traceback (most recent call last):
  File "/home/gns3/.local/lib/python3.6/site-packages/nornir/core/task.py", line 85, in start
    r = self.task(self, **self.params)
  File "/home/gns3/.local/lib/python3.6/site-packages/nornir/plugins/tasks/text/template_file.py", line 35, in template_file
    **kwargs
  File "/home/gns3/.local/lib/python3.6/site-packages/nornir/core/helpers/jinja_helper.py", line 18, in render_from_file
    return t.render(**kwargs)
  File "/home/gns3/.local/lib/python3.6/site-packages/jinja2/environment.py", line 1090, in render
    self.environment.handle_exception()
  File "/home/gns3/.local/lib/python3.6/site-packages/jinja2/environment.py", line 832, in handle_exception
    reraise(*rewrite_traceback_stack(source=source))
  File "/home/gns3/.local/lib/python3.6/site-packages/jinja2/_compat.py", line 28, in reraise
    raise value.with_traceback(tb)
  File "templates/junos/all.j2", line 1, in top-level template code
    {% include "templates/junos/dns.j2" %}
  File "/home/gns3/.local/lib/python3.6/site-packages/jinja2/loaders.py", line 197, in get_source
    raise TemplateNotFound(template)
jinja2.exceptions.TemplateNotFound: templates/junos/dns.j2

2020-04-25 00:04:03,237 - nornir.core.task -    ERROR -      start() - Host 'r1': task 'Base Configuration' failed with traceback:
Traceback (most recent call last):
  File "/home/gns3/.local/lib/python3.6/site-packages/nornir/core/task.py", line 85, in start
    r = self.task(self, **self.params)
  File "/home/gns3/.local/lib/python3.6/site-packages/nornir/plugins/tasks/text/template_file.py", line 35, in template_file
    **kwargs
  File "/home/gns3/.local/lib/python3.6/site-packages/nornir/core/helpers/jinja_helper.py", line 18, in render_from_file
    return t.render(**kwargs)
  File "/home/gns3/.local/lib/python3.6/site-packages/jinja2/environment.py", line 1090, in render
    self.environment.handle_exception()
  File "/home/gns3/.local/lib/python3.6/site-packages/jinja2/environment.py", line 832, in handle_exception
    reraise(*rewrite_traceback_stack(source=source))
  File "/home/gns3/.local/lib/python3.6/site-packages/jinja2/_compat.py", line 28, in reraise
    raise value.with_traceback(tb)
  File "templates/junos/all.j2", line 1, in top-level template code
    {% include "templates/junos/dns.j2" %}
  File "/home/gns3/.local/lib/python3.6/site-packages/jinja2/loaders.py", line 197, in get_source
    raise TemplateNotFound(template)
jinja2.exceptions.TemplateNotFound: templates/junos/dns.j2

2020-04-25 00:04:03,237 - nornir.core.task -    ERROR -      start() - Host 'r1': task 'basic_configuration' failed with traceback:
Traceback (most recent call last):
  File "/home/gns3/.local/lib/python3.6/site-packages/nornir/core/task.py", line 85, in start
    r = self.task(self, **self.params)
  File "deploy_configs.py", line 10, in basic_configuration
    path=f"templates/{task.host.platform}")
  File "/home/gns3/.local/lib/python3.6/site-packages/nornir/core/task.py", line 147, in run
    raise NornirSubTaskError(task=task, result=r)
nornir.core.exceptions.NornirSubTaskError: Subtask: <function template_file at 0x7fad4595a8c8> (failed)


2020-04-25 00:04:03,237 - nornir.core.task -    ERROR -      start() - Host 'r2': task 'basic_configuration' failed with traceback:
Traceback (most recent call last):
  File "/home/gns3/.local/lib/python3.6/site-packages/nornir/core/task.py", line 85, in start
    r = self.task(self, **self.params)
  File "deploy_configs.py", line 10, in basic_configuration
    path=f"templates/{task.host.platform}")
  File "/home/gns3/.local/lib/python3.6/site-packages/nornir/core/task.py", line 147, in run
    raise NornirSubTaskError(task=task, result=r)
nornir.core.exceptions.NornirSubTaskError: Subtask: <function template_file at 0x7fad4595a8c8> (failed)


2020-04-25 00:04:57,595 -  nornir.core -     INFO -        run() - Running task 'basic_configuration' with args {'template_name': 'all.j2'} on 2 hosts
2020-04-25 00:04:58,280 - nornir.core.task -    ERROR -      start() - Host 'r2': task 'Loading Configuration on the device' failed with traceback:
Traceback (most recent call last):
  File "/home/gns3/.local/lib/python3.6/site-packages/jnpr/junos/device.py", line 777, in execute
    ignore_warning=ignore_warning)
  File "/home/gns3/.local/lib/python3.6/site-packages/jnpr/junos/decorators.py", line 169, in wrapper
    raise ex
  File "/home/gns3/.local/lib/python3.6/site-packages/jnpr/junos/decorators.py", line 116, in wrapper
    rsp = function(self, *args, **kwargs)
  File "/home/gns3/.local/lib/python3.6/site-packages/jnpr/junos/device.py", line 1339, in _rpc_reply
    return self._conn.rpc(rpc_cmd_e)._NCElement__doc
  File "/home/gns3/.local/lib/python3.6/site-packages/ncclient/manager.py", line 236, in execute
    huge_tree=self._huge_tree).request(*args, **kwds)
  File "/home/gns3/.local/lib/python3.6/site-packages/ncclient/operations/third_party/juniper/rpc.py", line 52, in request
    return self._request(rpc)
  File "/home/gns3/.local/lib/python3.6/site-packages/ncclient/operations/rpc.py", line 346, in _request
    raise RPCError(to_ele(self._reply._raw), errs=errors)
ncclient.operations.rpc.RPCError: error: syntax error
error: error recovery ignores input until this point
warning: mgd: statement has no contents; ignored

During handling of the above exception, another exception occurred:

Traceback (most recent call last):
  File "/home/gns3/.local/lib/python3.6/site-packages/jnpr/junos/utils/config.py", line 456, in try_load
    **rpc_xattrs)
  File "/home/gns3/.local/lib/python3.6/site-packages/jnpr/junos/rpcmeta.py", line 277, in load_config
    return self._junos.execute(rpc, ignore_warning=ignore_warning)
  File "/home/gns3/.local/lib/python3.6/site-packages/jnpr/junos/decorators.py", line 76, in wrapper
    return function(*args, **kwargs)
  File "/home/gns3/.local/lib/python3.6/site-packages/jnpr/junos/decorators.py", line 31, in wrapper
    return function(*args, **kwargs)
  File "/home/gns3/.local/lib/python3.6/site-packages/jnpr/junos/device.py", line 797, in execute
    errs=ex)
jnpr.junos.exception.RpcError: RpcError(severity: error, bad_element: forwarding-options, message: error: syntax error
error: error recovery ignores input until this point
warning: mgd: statement has no contents; ignored)

During handling of the above exception, another exception occurred:

Traceback (most recent call last):
  File "/home/gns3/.local/lib/python3.6/site-packages/napalm/junos/junos.py", line 241, in _load_candidate
    ignore_warning=self.ignore_warning,
  File "/home/gns3/.local/lib/python3.6/site-packages/jnpr/junos/utils/config.py", line 539, in load
    ignore_warning=ignore_warning)
  File "/home/gns3/.local/lib/python3.6/site-packages/jnpr/junos/utils/config.py", line 460, in try_load
    raise ConfigLoadError(cmd=err.cmd, rsp=err.rsp, errs=err.errs)
jnpr.junos.exception.ConfigLoadError: ConfigLoadError(severity: error, bad_element: forwarding-options, message: error: syntax error
error: error recovery ignores input until this point
warning: mgd: statement has no contents; ignored)

During handling of the above exception, another exception occurred:

Traceback (most recent call last):
  File "/home/gns3/.local/lib/python3.6/site-packages/nornir/core/task.py", line 85, in start
    r = self.task(self, **self.params)
  File "/home/gns3/.local/lib/python3.6/site-packages/nornir/plugins/tasks/networking/napalm_configure.py", line 32, in napalm_configure
    device.load_merge_candidate(filename=filename, config=configuration)
  File "/home/gns3/.local/lib/python3.6/site-packages/napalm/junos/junos.py", line 257, in load_merge_candidate
    self._load_candidate(filename, config, False)
  File "/home/gns3/.local/lib/python3.6/site-packages/napalm/junos/junos.py", line 247, in _load_candidate
    raise MergeConfigException(e.errs)
napalm.base.exceptions.MergeConfigException: [{'severity': 'error', 'source': None, 'edit_path': None, 'bad_element': 'forwarding-options', 'message': 'syntax error'}, {'severity': 'error', 'source': None, 'edit_path': None, 'bad_element': '}', 'message': 'error recovery ignores input until this point'}, {'severity': 'warning', 'source': None, 'edit_path': '[edit]', 'bad_element': 'security', 'message': 'mgd: statement has no contents; ignored'}]

2020-04-25 00:04:58,280 - nornir.core.task -    ERROR -      start() - Host 'r2': task 'basic_configuration' failed with traceback:
Traceback (most recent call last):
  File "/home/gns3/.local/lib/python3.6/site-packages/nornir/core/task.py", line 85, in start
    r = self.task(self, **self.params)
  File "deploy_configs.py", line 15, in basic_configuration
    replace=False, configuration=task.host["config"])
  File "/home/gns3/.local/lib/python3.6/site-packages/nornir/core/task.py", line 147, in run
    raise NornirSubTaskError(task=task, result=r)
nornir.core.exceptions.NornirSubTaskError: Subtask: <function napalm_configure at 0x7f56674a4c80> (failed)


2020-04-25 00:04:58,383 - nornir.core.task -    ERROR -      start() - Host 'r1': task 'Loading Configuration on the device' failed with traceback:
Traceback (most recent call last):
  File "/home/gns3/.local/lib/python3.6/site-packages/jnpr/junos/device.py", line 777, in execute
    ignore_warning=ignore_warning)
  File "/home/gns3/.local/lib/python3.6/site-packages/jnpr/junos/decorators.py", line 169, in wrapper
    raise ex
  File "/home/gns3/.local/lib/python3.6/site-packages/jnpr/junos/decorators.py", line 116, in wrapper
    rsp = function(self, *args, **kwargs)
  File "/home/gns3/.local/lib/python3.6/site-packages/jnpr/junos/device.py", line 1339, in _rpc_reply
    return self._conn.rpc(rpc_cmd_e)._NCElement__doc
  File "/home/gns3/.local/lib/python3.6/site-packages/ncclient/manager.py", line 236, in execute
    huge_tree=self._huge_tree).request(*args, **kwds)
  File "/home/gns3/.local/lib/python3.6/site-packages/ncclient/operations/third_party/juniper/rpc.py", line 52, in request
    return self._request(rpc)
  File "/home/gns3/.local/lib/python3.6/site-packages/ncclient/operations/rpc.py", line 346, in _request
    raise RPCError(to_ele(self._reply._raw), errs=errors)
ncclient.operations.rpc.RPCError: error: syntax error
error: error recovery ignores input until this point
warning: mgd: statement has no contents; ignored

During handling of the above exception, another exception occurred:

Traceback (most recent call last):
  File "/home/gns3/.local/lib/python3.6/site-packages/jnpr/junos/utils/config.py", line 456, in try_load
    **rpc_xattrs)
  File "/home/gns3/.local/lib/python3.6/site-packages/jnpr/junos/rpcmeta.py", line 277, in load_config
    return self._junos.execute(rpc, ignore_warning=ignore_warning)
  File "/home/gns3/.local/lib/python3.6/site-packages/jnpr/junos/decorators.py", line 76, in wrapper
    return function(*args, **kwargs)
  File "/home/gns3/.local/lib/python3.6/site-packages/jnpr/junos/decorators.py", line 31, in wrapper
    return function(*args, **kwargs)
  File "/home/gns3/.local/lib/python3.6/site-packages/jnpr/junos/device.py", line 797, in execute
    errs=ex)
jnpr.junos.exception.RpcError: RpcError(severity: error, bad_element: forwarding-options, message: error: syntax error
error: error recovery ignores input until this point
warning: mgd: statement has no contents; ignored)

During handling of the above exception, another exception occurred:

Traceback (most recent call last):
  File "/home/gns3/.local/lib/python3.6/site-packages/napalm/junos/junos.py", line 241, in _load_candidate
    ignore_warning=self.ignore_warning,
  File "/home/gns3/.local/lib/python3.6/site-packages/jnpr/junos/utils/config.py", line 539, in load
    ignore_warning=ignore_warning)
  File "/home/gns3/.local/lib/python3.6/site-packages/jnpr/junos/utils/config.py", line 460, in try_load
    raise ConfigLoadError(cmd=err.cmd, rsp=err.rsp, errs=err.errs)
jnpr.junos.exception.ConfigLoadError: ConfigLoadError(severity: error, bad_element: forwarding-options, message: error: syntax error
error: error recovery ignores input until this point
warning: mgd: statement has no contents; ignored)

During handling of the above exception, another exception occurred:

Traceback (most recent call last):
  File "/home/gns3/.local/lib/python3.6/site-packages/nornir/core/task.py", line 85, in start
    r = self.task(self, **self.params)
  File "/home/gns3/.local/lib/python3.6/site-packages/nornir/plugins/tasks/networking/napalm_configure.py", line 32, in napalm_configure
    device.load_merge_candidate(filename=filename, config=configuration)
  File "/home/gns3/.local/lib/python3.6/site-packages/napalm/junos/junos.py", line 257, in load_merge_candidate
    self._load_candidate(filename, config, False)
  File "/home/gns3/.local/lib/python3.6/site-packages/napalm/junos/junos.py", line 247, in _load_candidate
    raise MergeConfigException(e.errs)
napalm.base.exceptions.MergeConfigException: [{'severity': 'error', 'source': None, 'edit_path': None, 'bad_element': 'forwarding-options', 'message': 'syntax error'}, {'severity': 'error', 'source': None, 'edit_path': None, 'bad_element': '}', 'message': 'error recovery ignores input until this point'}, {'severity': 'warning', 'source': None, 'edit_path': '[edit]', 'bad_element': 'security', 'message': 'mgd: statement has no contents; ignored'}]

2020-04-25 00:04:58,383 - nornir.core.task -    ERROR -      start() - Host 'r1': task 'basic_configuration' failed with traceback:
Traceback (most recent call last):
  File "/home/gns3/.local/lib/python3.6/site-packages/nornir/core/task.py", line 85, in start
    r = self.task(self, **self.params)
  File "deploy_configs.py", line 15, in basic_configuration
    replace=False, configuration=task.host["config"])
  File "/home/gns3/.local/lib/python3.6/site-packages/nornir/core/task.py", line 147, in run
    raise NornirSubTaskError(task=task, result=r)
nornir.core.exceptions.NornirSubTaskError: Subtask: <function napalm_configure at 0x7f56674a4c80> (failed)


2020-04-25 00:05:27,255 -  nornir.core -     INFO -        run() - Running task 'basic_configuration' with args {'template_name': 'all.j2'} on 2 hosts
2020-04-25 00:28:20,220 -  nornir.core -     INFO -        run() - Running task 'basic_configuration' with args {'template_name': 'all.j2'} on 2 hosts
2020-04-25 00:31:56,979 -  nornir.core -     INFO -        run() - Running task 'napalm_get' with args {'getters': ['facts']} on 1 hosts
2020-04-25 00:32:25,268 - nornir.core.task -    ERROR -      start() - Host 'r4': task 'napalm_get' failed with traceback:
Traceback (most recent call last):
  File "/home/gns3/.local/lib/python3.6/site-packages/paramiko/channel.py", line 699, in recv
    out = self.in_buffer.read(nbytes, self.timeout)
  File "/home/gns3/.local/lib/python3.6/site-packages/paramiko/buffered_pipe.py", line 164, in read
    raise PipeTimeout()
paramiko.buffered_pipe.PipeTimeout

During handling of the above exception, another exception occurred:

Traceback (most recent call last):
  File "/home/gns3/.local/lib/python3.6/site-packages/netmiko/base_connection.py", line 550, in _read_channel_expect
    new_data = self.remote_conn.recv(MAX_BUFFER)
  File "/home/gns3/.local/lib/python3.6/site-packages/paramiko/channel.py", line 701, in recv
    raise socket.timeout()
socket.timeout

During handling of the above exception, another exception occurred:

Traceback (most recent call last):
  File "/home/gns3/.local/lib/python3.6/site-packages/nornir/core/task.py", line 85, in start
    r = self.task(self, **self.params)
  File "/home/gns3/.local/lib/python3.6/site-packages/nornir/plugins/tasks/networking/napalm_get.py", line 61, in napalm_get
    result[g] = method(**options)
  File "/home/gns3/.local/lib/python3.6/site-packages/napalm/iosxr/iosxr.py", line 163, in get_facts
    facts_rpc_reply = ETREE.fromstring(self.device.make_rpc_call(facts_rpc_request))
  File "/home/gns3/.local/lib/python3.6/site-packages/pyIOSXR/iosxr.py", line 151, in make_rpc_call
    result = self._execute_rpc(rpc_command)
  File "/home/gns3/.local/lib/python3.6/site-packages/pyIOSXR/iosxr.py", line 365, in _execute_rpc
    response = self._send_command(xml_rpc_command, delay_factor=delay_factor)
  File "/home/gns3/.local/lib/python3.6/site-packages/pyIOSXR/iosxr.py", line 275, in _send_command
    max_loops=max_loops)
  File "/home/gns3/.local/lib/python3.6/site-packages/netmiko/base_connection.py", line 1470, in send_command_expect
    return self.send_command(*args, **kwargs)
  File "/home/gns3/.local/lib/python3.6/site-packages/netmiko/utilities.py", line 347, in wrapper_decorator
    return func(self, *args, **kwargs)
  File "/home/gns3/.local/lib/python3.6/site-packages/netmiko/base_connection.py", line 1389, in send_command
    new_data = self.read_until_pattern(pattern=re.escape(cmd))
  File "/home/gns3/.local/lib/python3.6/site-packages/netmiko/base_connection.py", line 627, in read_until_pattern
    return self._read_channel_expect(*args, **kwargs)
  File "/home/gns3/.local/lib/python3.6/site-packages/netmiko/base_connection.py", line 561, in _read_channel_expect
    "Timed-out reading channel, data not available."
netmiko.ssh_exception.NetmikoTimeoutException: Timed-out reading channel, data not available.

2020-04-25 00:33:29,452 -  nornir.core -     INFO -        run() - Running task 'netmiko_send_command' with args {'command_string': 'sh ver'} on 4 hosts
2020-04-25 00:34:01,549 -  nornir.core -     INFO -        run() - Running task 'netmiko_send_command' with args {'command_string': 'sh ver'} on 1 hosts
2020-04-25 00:35:19,764 -  nornir.core -     INFO -        run() - Running task 'netmiko_send_command' with args {'command_string': 'sh ip int brief'} on 1 hosts
2020-04-25 00:37:29,607 -  nornir.core -     INFO -        run() - Running task 'netmiko_send_command' with args {'command_string': 'sh ip int brief'} on 1 hosts
2020-04-25 00:37:35,225 -  nornir.core -     INFO -        run() - Running task 'napalm_get' with args {'getters': ['facts']} on 1 hosts
2020-04-25 00:38:03,386 - nornir.core.task -    ERROR -      start() - Host 'r4': task 'napalm_get' failed with traceback:
Traceback (most recent call last):
  File "/home/gns3/.local/lib/python3.6/site-packages/paramiko/channel.py", line 699, in recv
    out = self.in_buffer.read(nbytes, self.timeout)
  File "/home/gns3/.local/lib/python3.6/site-packages/paramiko/buffered_pipe.py", line 164, in read
    raise PipeTimeout()
paramiko.buffered_pipe.PipeTimeout

During handling of the above exception, another exception occurred:

Traceback (most recent call last):
  File "/home/gns3/.local/lib/python3.6/site-packages/netmiko/base_connection.py", line 550, in _read_channel_expect
    new_data = self.remote_conn.recv(MAX_BUFFER)
  File "/home/gns3/.local/lib/python3.6/site-packages/paramiko/channel.py", line 701, in recv
    raise socket.timeout()
socket.timeout

During handling of the above exception, another exception occurred:

Traceback (most recent call last):
  File "/home/gns3/.local/lib/python3.6/site-packages/nornir/core/task.py", line 85, in start
    r = self.task(self, **self.params)
  File "/home/gns3/.local/lib/python3.6/site-packages/nornir/plugins/tasks/networking/napalm_get.py", line 61, in napalm_get
    result[g] = method(**options)
  File "/home/gns3/.local/lib/python3.6/site-packages/napalm/iosxr/iosxr.py", line 163, in get_facts
    facts_rpc_reply = ETREE.fromstring(self.device.make_rpc_call(facts_rpc_request))
  File "/home/gns3/.local/lib/python3.6/site-packages/pyIOSXR/iosxr.py", line 151, in make_rpc_call
    result = self._execute_rpc(rpc_command)
  File "/home/gns3/.local/lib/python3.6/site-packages/pyIOSXR/iosxr.py", line 365, in _execute_rpc
    response = self._send_command(xml_rpc_command, delay_factor=delay_factor)
  File "/home/gns3/.local/lib/python3.6/site-packages/pyIOSXR/iosxr.py", line 275, in _send_command
    max_loops=max_loops)
  File "/home/gns3/.local/lib/python3.6/site-packages/netmiko/base_connection.py", line 1470, in send_command_expect
    return self.send_command(*args, **kwargs)
  File "/home/gns3/.local/lib/python3.6/site-packages/netmiko/utilities.py", line 347, in wrapper_decorator
    return func(self, *args, **kwargs)
  File "/home/gns3/.local/lib/python3.6/site-packages/netmiko/base_connection.py", line 1389, in send_command
    new_data = self.read_until_pattern(pattern=re.escape(cmd))
  File "/home/gns3/.local/lib/python3.6/site-packages/netmiko/base_connection.py", line 627, in read_until_pattern
    return self._read_channel_expect(*args, **kwargs)
  File "/home/gns3/.local/lib/python3.6/site-packages/netmiko/base_connection.py", line 561, in _read_channel_expect
    "Timed-out reading channel, data not available."
netmiko.ssh_exception.NetmikoTimeoutException: Timed-out reading channel, data not available.

2020-04-25 01:10:49,740 -  nornir.core -     INFO -        run() - Running task 'basic_configuration' with args {'template_name': 'dns.j2'} on 1 hosts
2020-04-25 01:11:17,725 - nornir.core.task -    ERROR -      start() - Host 'r4': task 'Loading Configuration on the device' failed with traceback:
Traceback (most recent call last):
  File "/home/gns3/.local/lib/python3.6/site-packages/paramiko/channel.py", line 699, in recv
    out = self.in_buffer.read(nbytes, self.timeout)
  File "/home/gns3/.local/lib/python3.6/site-packages/paramiko/buffered_pipe.py", line 164, in read
    raise PipeTimeout()
paramiko.buffered_pipe.PipeTimeout

During handling of the above exception, another exception occurred:

Traceback (most recent call last):
  File "/home/gns3/.local/lib/python3.6/site-packages/netmiko/base_connection.py", line 550, in _read_channel_expect
    new_data = self.remote_conn.recv(MAX_BUFFER)
  File "/home/gns3/.local/lib/python3.6/site-packages/paramiko/channel.py", line 701, in recv
    raise socket.timeout()
socket.timeout

During handling of the above exception, another exception occurred:

Traceback (most recent call last):
  File "/home/gns3/.local/lib/python3.6/site-packages/nornir/core/task.py", line 85, in start
    r = self.task(self, **self.params)
  File "/home/gns3/.local/lib/python3.6/site-packages/nornir/plugins/tasks/networking/napalm_configure.py", line 32, in napalm_configure
    device.load_merge_candidate(filename=filename, config=configuration)
  File "/home/gns3/.local/lib/python3.6/site-packages/napalm/iosxr/iosxr.py", line 111, in load_merge_candidate
    self.device.lock()
  File "/home/gns3/.local/lib/python3.6/site-packages/pyIOSXR/iosxr.py", line 476, in lock
    self._execute_rpc(rpc_command)
  File "/home/gns3/.local/lib/python3.6/site-packages/pyIOSXR/iosxr.py", line 365, in _execute_rpc
    response = self._send_command(xml_rpc_command, delay_factor=delay_factor)
  File "/home/gns3/.local/lib/python3.6/site-packages/pyIOSXR/iosxr.py", line 275, in _send_command
    max_loops=max_loops)
  File "/home/gns3/.local/lib/python3.6/site-packages/netmiko/base_connection.py", line 1470, in send_command_expect
    return self.send_command(*args, **kwargs)
  File "/home/gns3/.local/lib/python3.6/site-packages/netmiko/utilities.py", line 347, in wrapper_decorator
    return func(self, *args, **kwargs)
  File "/home/gns3/.local/lib/python3.6/site-packages/netmiko/base_connection.py", line 1389, in send_command
    new_data = self.read_until_pattern(pattern=re.escape(cmd))
  File "/home/gns3/.local/lib/python3.6/site-packages/netmiko/base_connection.py", line 627, in read_until_pattern
    return self._read_channel_expect(*args, **kwargs)
  File "/home/gns3/.local/lib/python3.6/site-packages/netmiko/base_connection.py", line 561, in _read_channel_expect
    "Timed-out reading channel, data not available."
netmiko.ssh_exception.NetmikoTimeoutException: Timed-out reading channel, data not available.

2020-04-25 01:11:17,725 - nornir.core.task -    ERROR -      start() - Host 'r4': task 'basic_configuration' failed with traceback:
Traceback (most recent call last):
  File "/home/gns3/.local/lib/python3.6/site-packages/nornir/core/task.py", line 85, in start
    r = self.task(self, **self.params)
  File "deploy_configs.py", line 16, in basic_configuration
    replace=False, configuration=task.host["config"])
  File "/home/gns3/.local/lib/python3.6/site-packages/nornir/core/task.py", line 147, in run
    raise NornirSubTaskError(task=task, result=r)
nornir.core.exceptions.NornirSubTaskError: Subtask: <function napalm_configure at 0x7f8c76987d08> (failed)


2020-04-25 01:11:45,607 -  nornir.core -     INFO -        run() - Running task 'netmiko_send_command' with args {'command_string': 'sh ip int brief'} on 1 hosts
2020-04-25 01:14:42,339 -  nornir.core -     INFO -        run() - Running task 'netmiko_send_command' with args {'command_string': 'show version'} on 1 hosts
2020-04-25 01:14:48,541 -  nornir.core -     INFO -        run() - Running task 'netmiko_send_command' with args {'command_string': 'sh ip int brief'} on 1 hosts
2020-04-25 01:15:35,917 -  nornir.core -     INFO -        run() - Running task 'netmiko_send_command' with args {'command_string': 'show version'} on 1 hosts
2020-04-25 01:15:41,315 -  nornir.core -     INFO -        run() - Running task 'netmiko_send_command' with args {'command_string': 'sh ip int brief'} on 1 hosts
2020-04-25 01:16:45,933 -  nornir.core -     INFO -        run() - Running task 'netmiko_send_command' with args {'command_string': 'show version'} on 1 hosts
2020-04-25 01:16:52,174 -  nornir.core -     INFO -        run() - Running task 'netmiko_send_command' with args {'command_string': 'sh ip int brief'} on 1 hosts
2020-04-25 01:17:18,368 -  nornir.core -     INFO -        run() - Running task 'netmiko_send_command' with args {'command_string': 'show version'} on 1 hosts
2020-04-25 01:17:24,582 -  nornir.core -     INFO -        run() - Running task 'netmiko_send_command' with args {'command_string': 'sh ip int brief'} on 1 hosts
2020-04-25 01:17:25,562 -  nornir.core -     INFO -        run() - Running task 'napalm_get' with args {'getters': ['facts']} on 1 hosts
2020-04-25 01:17:53,641 - nornir.core.task -    ERROR -      start() - Host 'r4': task 'napalm_get' failed with traceback:
Traceback (most recent call last):
  File "/home/gns3/.local/lib/python3.6/site-packages/paramiko/channel.py", line 699, in recv
    out = self.in_buffer.read(nbytes, self.timeout)
  File "/home/gns3/.local/lib/python3.6/site-packages/paramiko/buffered_pipe.py", line 164, in read
    raise PipeTimeout()
paramiko.buffered_pipe.PipeTimeout

During handling of the above exception, another exception occurred:

Traceback (most recent call last):
  File "/home/gns3/.local/lib/python3.6/site-packages/netmiko/base_connection.py", line 550, in _read_channel_expect
    new_data = self.remote_conn.recv(MAX_BUFFER)
  File "/home/gns3/.local/lib/python3.6/site-packages/paramiko/channel.py", line 701, in recv
    raise socket.timeout()
socket.timeout

During handling of the above exception, another exception occurred:

Traceback (most recent call last):
  File "/home/gns3/.local/lib/python3.6/site-packages/nornir/core/task.py", line 85, in start
    r = self.task(self, **self.params)
  File "/home/gns3/.local/lib/python3.6/site-packages/nornir/plugins/tasks/networking/napalm_get.py", line 61, in napalm_get
    result[g] = method(**options)
  File "/home/gns3/.local/lib/python3.6/site-packages/napalm/iosxr/iosxr.py", line 163, in get_facts
    facts_rpc_reply = ETREE.fromstring(self.device.make_rpc_call(facts_rpc_request))
  File "/home/gns3/.local/lib/python3.6/site-packages/pyIOSXR/iosxr.py", line 151, in make_rpc_call
    result = self._execute_rpc(rpc_command)
  File "/home/gns3/.local/lib/python3.6/site-packages/pyIOSXR/iosxr.py", line 365, in _execute_rpc
    response = self._send_command(xml_rpc_command, delay_factor=delay_factor)
  File "/home/gns3/.local/lib/python3.6/site-packages/pyIOSXR/iosxr.py", line 275, in _send_command
    max_loops=max_loops)
  File "/home/gns3/.local/lib/python3.6/site-packages/netmiko/base_connection.py", line 1470, in send_command_expect
    return self.send_command(*args, **kwargs)
  File "/home/gns3/.local/lib/python3.6/site-packages/netmiko/utilities.py", line 347, in wrapper_decorator
    return func(self, *args, **kwargs)
  File "/home/gns3/.local/lib/python3.6/site-packages/netmiko/base_connection.py", line 1389, in send_command
    new_data = self.read_until_pattern(pattern=re.escape(cmd))
  File "/home/gns3/.local/lib/python3.6/site-packages/netmiko/base_connection.py", line 627, in read_until_pattern
    return self._read_channel_expect(*args, **kwargs)
  File "/home/gns3/.local/lib/python3.6/site-packages/netmiko/base_connection.py", line 561, in _read_channel_expect
    "Timed-out reading channel, data not available."
netmiko.ssh_exception.NetmikoTimeoutException: Timed-out reading channel, data not available.

2020-04-25 03:16:42,789 -  nornir.core -     INFO -        run() - Running task 'basic_configuration' with args {'template_name': 'all.j2'} on 2 hosts
2020-04-25 12:36:17,318 -  nornir.core -     INFO -        run() - Running task 'basic_configuration' with args {} on 1 hosts
2020-04-25 12:36:17,329 - nornir.core.task -    ERROR -      start() - Host 'r3': task 'Base Configuration' failed with traceback:
Traceback (most recent call last):
  File "/home/gns3/.local/lib/python3.6/site-packages/nornir/core/task.py", line 85, in start
    r = self.task(self, **self.params)
  File "/home/gns3/.local/lib/python3.6/site-packages/nornir/plugins/tasks/text/template_file.py", line 35, in template_file
    **kwargs
  File "/home/gns3/.local/lib/python3.6/site-packages/nornir/core/helpers/jinja_helper.py", line 17, in render_from_file
    t = env.get_template(template)
  File "/home/gns3/.local/lib/python3.6/site-packages/jinja2/environment.py", line 883, in get_template
    return self._load_template(name, self.make_globals(globals))
  File "/home/gns3/.local/lib/python3.6/site-packages/jinja2/environment.py", line 857, in _load_template
    template = self.loader.load(self, name, globals)
  File "/home/gns3/.local/lib/python3.6/site-packages/jinja2/loaders.py", line 115, in load
    source, filename, uptodate = self.get_source(environment, name)
  File "/home/gns3/.local/lib/python3.6/site-packages/jinja2/loaders.py", line 197, in get_source
    raise TemplateNotFound(template)
jinja2.exceptions.TemplateNotFound: base.j2

2020-04-25 12:36:17,330 - nornir.core.task -    ERROR -      start() - Host 'r3': task 'basic_configuration' failed with traceback:
Traceback (most recent call last):
  File "/home/gns3/.local/lib/python3.6/site-packages/nornir/core/task.py", line 85, in start
    r = self.task(self, **self.params)
  File "explore.py", line 15, in basic_configuration
    template="base.j2", path=f"templates/{task.host.platform}")
  File "/home/gns3/.local/lib/python3.6/site-packages/nornir/core/task.py", line 147, in run
    raise NornirSubTaskError(task=task, result=r)
nornir.core.exceptions.NornirSubTaskError: Subtask: <function template_file at 0x7f6868543840> (failed)


2020-04-25 12:37:19,639 -  nornir.core -     INFO -        run() - Running task 'basic_configuration' with args {} on 1 hosts
2020-04-25 12:37:19,641 - nornir.core.task -    ERROR -      start() - Host 'r3': task 'Base Configuration' failed with traceback:
Traceback (most recent call last):
  File "/home/gns3/.local/lib/python3.6/site-packages/nornir/core/task.py", line 85, in start
    r = self.task(self, **self.params)
  File "/home/gns3/.local/lib/python3.6/site-packages/nornir/plugins/tasks/text/template_file.py", line 35, in template_file
    **kwargs
  File "/home/gns3/.local/lib/python3.6/site-packages/nornir/core/helpers/jinja_helper.py", line 17, in render_from_file
    t = env.get_template(template)
  File "/home/gns3/.local/lib/python3.6/site-packages/jinja2/environment.py", line 883, in get_template
    return self._load_template(name, self.make_globals(globals))
  File "/home/gns3/.local/lib/python3.6/site-packages/jinja2/environment.py", line 857, in _load_template
    template = self.loader.load(self, name, globals)
  File "/home/gns3/.local/lib/python3.6/site-packages/jinja2/loaders.py", line 115, in load
    source, filename, uptodate = self.get_source(environment, name)
  File "/home/gns3/.local/lib/python3.6/site-packages/jinja2/loaders.py", line 197, in get_source
    raise TemplateNotFound(template)
jinja2.exceptions.TemplateNotFound: base.j2

2020-04-25 12:37:19,641 - nornir.core.task -    ERROR -      start() - Host 'r3': task 'basic_configuration' failed with traceback:
Traceback (most recent call last):
  File "/home/gns3/.local/lib/python3.6/site-packages/nornir/core/task.py", line 85, in start
    r = self.task(self, **self.params)
  File "explore.py", line 15, in basic_configuration
    template="base.j2", path=f"templates/{task.host.platform}")
  File "/home/gns3/.local/lib/python3.6/site-packages/nornir/core/task.py", line 147, in run
    raise NornirSubTaskError(task=task, result=r)
nornir.core.exceptions.NornirSubTaskError: Subtask: <function template_file at 0x7fa617752840> (failed)


2020-04-25 12:37:42,387 -  nornir.core -     INFO -        run() - Running task 'basic_configuration' with args {'template_name': 'all.j2'} on 2 hosts
2020-04-25 12:55:43,918 -  nornir.core -     INFO -        run() - Running task 'netmiko_send_command' with args {'command_string': 'show version'} on 1 hosts
2020-04-25 12:55:50,505 -  nornir.core -     INFO -        run() - Running task 'netmiko_send_command' with args {'command_string': 'sh ip int brief'} on 1 hosts
2020-04-25 12:55:51,493 -  nornir.core -     INFO -        run() - Running task 'napalm_get' with args {'getters': ['facts']} on 1 hosts
2020-04-25 12:56:19,796 - nornir.core.task -    ERROR -      start() - Host 'r4': task 'napalm_get' failed with traceback:
Traceback (most recent call last):
  File "/home/gns3/.local/lib/python3.6/site-packages/paramiko/channel.py", line 699, in recv
    out = self.in_buffer.read(nbytes, self.timeout)
  File "/home/gns3/.local/lib/python3.6/site-packages/paramiko/buffered_pipe.py", line 164, in read
    raise PipeTimeout()
paramiko.buffered_pipe.PipeTimeout

During handling of the above exception, another exception occurred:

Traceback (most recent call last):
  File "/home/gns3/.local/lib/python3.6/site-packages/netmiko/base_connection.py", line 550, in _read_channel_expect
    new_data = self.remote_conn.recv(MAX_BUFFER)
  File "/home/gns3/.local/lib/python3.6/site-packages/paramiko/channel.py", line 701, in recv
    raise socket.timeout()
socket.timeout

During handling of the above exception, another exception occurred:

Traceback (most recent call last):
  File "/home/gns3/.local/lib/python3.6/site-packages/nornir/core/task.py", line 85, in start
    r = self.task(self, **self.params)
  File "/home/gns3/.local/lib/python3.6/site-packages/nornir/plugins/tasks/networking/napalm_get.py", line 61, in napalm_get
    result[g] = method(**options)
  File "/home/gns3/.local/lib/python3.6/site-packages/napalm/iosxr/iosxr.py", line 163, in get_facts
    facts_rpc_reply = ETREE.fromstring(self.device.make_rpc_call(facts_rpc_request))
  File "/home/gns3/.local/lib/python3.6/site-packages/pyIOSXR/iosxr.py", line 151, in make_rpc_call
    result = self._execute_rpc(rpc_command)
  File "/home/gns3/.local/lib/python3.6/site-packages/pyIOSXR/iosxr.py", line 365, in _execute_rpc
    response = self._send_command(xml_rpc_command, delay_factor=delay_factor)
  File "/home/gns3/.local/lib/python3.6/site-packages/pyIOSXR/iosxr.py", line 275, in _send_command
    max_loops=max_loops)
  File "/home/gns3/.local/lib/python3.6/site-packages/netmiko/base_connection.py", line 1470, in send_command_expect
    return self.send_command(*args, **kwargs)
  File "/home/gns3/.local/lib/python3.6/site-packages/netmiko/utilities.py", line 347, in wrapper_decorator
    return func(self, *args, **kwargs)
  File "/home/gns3/.local/lib/python3.6/site-packages/netmiko/base_connection.py", line 1389, in send_command
    new_data = self.read_until_pattern(pattern=re.escape(cmd))
  File "/home/gns3/.local/lib/python3.6/site-packages/netmiko/base_connection.py", line 627, in read_until_pattern
    return self._read_channel_expect(*args, **kwargs)
  File "/home/gns3/.local/lib/python3.6/site-packages/netmiko/base_connection.py", line 561, in _read_channel_expect
    "Timed-out reading channel, data not available."
netmiko.ssh_exception.NetmikoTimeoutException: Timed-out reading channel, data not available.

2020-04-25 13:15:34,365 -  nornir.core -     INFO -        run() - Running task 'netmiko_send_command' with args {'command_string': 'show version'} on 2 hosts
2020-04-25 13:15:39,944 - nornir.core.task -    ERROR -      start() - Host 'r2': task 'netmiko_send_command' failed with traceback:
Traceback (most recent call last):
  File "/home/gns3/.local/lib/python3.6/site-packages/nornir/core/task.py", line 85, in start
    r = self.task(self, **self.params)
  File "/home/gns3/.local/lib/python3.6/site-packages/nornir/plugins/tasks/networking/netmiko_send_command.py", line 32, in netmiko_send_command
    result = net_connect.send_command(command_string, **kwargs)
  File "/home/gns3/.local/lib/python3.6/site-packages/netmiko/utilities.py", line 347, in wrapper_decorator
    return func(self, *args, **kwargs)
  File "/home/gns3/.local/lib/python3.6/site-packages/netmiko/base_connection.py", line 1382, in send_command
    self.write_channel(command_string)
  File "/home/gns3/.local/lib/python3.6/site-packages/netmiko/base_connection.py", line 436, in write_channel
    self._write_channel(out_data)
  File "/home/gns3/.local/lib/python3.6/site-packages/netmiko/base_connection.py", line 394, in _write_channel
    self.remote_conn.sendall(write_bytes(out_data, encoding=self.encoding))
  File "/home/gns3/.local/lib/python3.6/site-packages/paramiko/channel.py", line 846, in sendall
    sent = self.send(s)
  File "/home/gns3/.local/lib/python3.6/site-packages/paramiko/channel.py", line 801, in send
    return self._send(s, m)
  File "/home/gns3/.local/lib/python3.6/site-packages/paramiko/channel.py", line 1198, in _send
    raise socket.error("Socket is closed")
OSError: Socket is closed

2020-04-25 13:15:39,944 - nornir.core.task -    ERROR -      start() - Host 'r1': task 'netmiko_send_command' failed with traceback:
Traceback (most recent call last):
  File "/home/gns3/.local/lib/python3.6/site-packages/nornir/core/task.py", line 85, in start
    r = self.task(self, **self.params)
  File "/home/gns3/.local/lib/python3.6/site-packages/nornir/plugins/tasks/networking/netmiko_send_command.py", line 32, in netmiko_send_command
    result = net_connect.send_command(command_string, **kwargs)
  File "/home/gns3/.local/lib/python3.6/site-packages/netmiko/utilities.py", line 347, in wrapper_decorator
    return func(self, *args, **kwargs)
  File "/home/gns3/.local/lib/python3.6/site-packages/netmiko/base_connection.py", line 1382, in send_command
    self.write_channel(command_string)
  File "/home/gns3/.local/lib/python3.6/site-packages/netmiko/base_connection.py", line 436, in write_channel
    self._write_channel(out_data)
  File "/home/gns3/.local/lib/python3.6/site-packages/netmiko/base_connection.py", line 394, in _write_channel
    self.remote_conn.sendall(write_bytes(out_data, encoding=self.encoding))
  File "/home/gns3/.local/lib/python3.6/site-packages/paramiko/channel.py", line 846, in sendall
    sent = self.send(s)
  File "/home/gns3/.local/lib/python3.6/site-packages/paramiko/channel.py", line 801, in send
    return self._send(s, m)
  File "/home/gns3/.local/lib/python3.6/site-packages/paramiko/channel.py", line 1198, in _send
    raise socket.error("Socket is closed")
OSError: Socket is closed

2020-04-25 13:16:03,591 -  nornir.core -     INFO -        run() - Running task 'napalm_get' with args {'getters': ['facts']} on 2 hosts
2020-04-25 13:17:02,747 -  nornir.core -     INFO -        run() - Running task 'napalm_get' with args {'getters': ['facts']} on 2 hosts
2020-04-25 13:20:18,076 -  nornir.core -     INFO -        run() - Running task 'napalm_get' with args {'getters': ['facts'], 'severity_level': 20} on 2 hosts
2020-04-25 13:21:00,694 -  nornir.core -     INFO -        run() - Running task 'napalm_get' with args {'getters': ['facts'], 'severity_level': 20} on 2 hosts
2020-04-25 13:21:53,464 -  nornir.core -     INFO -        run() - Running task 'napalm_get' with args {'getters': ['facts'], 'severity_level': 20} on 2 hosts
2020-04-25 13:22:19,588 -  nornir.core -     INFO -        run() - Running task 'napalm_get' with args {'getters': ['facts'], 'severity_level': 20} on 2 hosts
2020-04-25 13:22:44,317 -  nornir.core -     INFO -        run() - Running task 'napalm_get' with args {'getters': ['facts'], 'severity_level': 20} on 2 hosts
2020-04-25 13:23:30,849 -  nornir.core -     INFO -        run() - Running task 'napalm_get' with args {'getters': ['facts'], 'severity_level': 20} on 2 hosts
2020-04-25 13:23:59,522 -  nornir.core -     INFO -        run() - Running task 'napalm_get' with args {'getters': ['facts'], 'severity_level': 20} on 2 hosts
2020-04-25 13:24:19,307 -  nornir.core -     INFO -        run() - Running task 'napalm_get' with args {'getters': ['facts'], 'severity_level': 20} on 2 hosts
2020-04-25 13:25:58,884 -  nornir.core -     INFO -        run() - Running task 'napalm_get' with args {'getters': ['facts'], 'severity_level': 20} on 2 hosts
2020-04-25 13:26:22,478 -  nornir.core -     INFO -        run() - Running task 'napalm_get' with args {'getters': ['facts'], 'severity_level': 20} on 2 hosts
2020-04-25 13:26:54,636 -  nornir.core -     INFO -        run() - Running task 'napalm_get' with args {'getters': ['facts'], 'severity_level': 20} on 2 hosts
2020-04-25 13:27:28,731 -  nornir.core -     INFO -        run() - Running task 'napalm_get' with args {'getters': ['facts'], 'severity_level': 20} on 2 hosts
2020-04-25 13:27:54,338 -  nornir.core -     INFO -        run() - Running task 'napalm_get' with args {'getters': ['facts'], 'severity_level': 20} on 2 hosts
2020-04-25 13:29:58,184 -  nornir.core -     INFO -        run() - Running task 'napalm_get' with args {'getters': ['facts'], 'severity_level': 20} on 2 hosts
2020-04-25 13:31:12,906 -  nornir.core -     INFO -        run() - Running task 'napalm_get' with args {'getters': ['facts'], 'severity_level': 20} on 2 hosts
2020-04-25 13:32:23,007 -  nornir.core -     INFO -        run() - Running task 'napalm_get' with args {'getters': ['interfaces', 'facts'], 'severity_level': 20} on 2 hosts
2020-04-25 13:33:00,496 -  nornir.core -     INFO -        run() - Running task 'napalm_get' with args {'getters': ['hostname', 'facts'], 'severity_level': 20} on 2 hosts
2020-04-25 13:33:00,831 - nornir.core.task -    ERROR -      start() - Host 'r1': task 'napalm_get' failed with traceback:
Traceback (most recent call last):
  File "/home/gns3/.local/lib/python3.6/site-packages/nornir/core/task.py", line 85, in start
    r = self.task(self, **self.params)
  File "/home/gns3/.local/lib/python3.6/site-packages/nornir/plugins/tasks/networking/napalm_get.py", line 60, in napalm_get
    method = getattr(device, getter)
AttributeError: 'JunOSDriver' object has no attribute 'get_hostname'

2020-04-25 13:33:00,839 - nornir.core.task -    ERROR -      start() - Host 'r2': task 'napalm_get' failed with traceback:
Traceback (most recent call last):
  File "/home/gns3/.local/lib/python3.6/site-packages/nornir/core/task.py", line 85, in start
    r = self.task(self, **self.params)
  File "/home/gns3/.local/lib/python3.6/site-packages/nornir/plugins/tasks/networking/napalm_get.py", line 60, in napalm_get
    method = getattr(device, getter)
AttributeError: 'JunOSDriver' object has no attribute 'get_hostname'

2020-04-25 13:34:36,882 -  nornir.core -     INFO -        run() - Running task 'napalm_get' with args {'getters': ['interfaces', 'facts'], 'severity_level': 20} on 2 hosts
2020-04-25 13:35:29,483 -  nornir.core -     INFO -        run() - Running task 'napalm_get' with args {'getters': ['interfaces', 'facts'], 'severity_level': 20} on 2 hosts
2020-04-25 13:35:53,462 -  nornir.core -     INFO -        run() - Running task 'napalm_get' with args {'getters': ['interfaces', 'facts'], 'severity_level': 20} on 2 hosts
2020-04-25 13:36:11,373 -  nornir.core -     INFO -        run() - Running task 'napalm_get' with args {'getters': ['interfaces', 'facts'], 'severity_level': 20} on 2 hosts
2020-04-25 13:36:53,787 -  nornir.core -     INFO -        run() - Running task 'napalm_get' with args {'getters': ['facts'], 'severity_level': 20} on 2 hosts
2020-04-25 13:37:06,979 -  nornir.core -     INFO -        run() - Running task 'napalm_get' with args {'getters': ['facts'], 'severity_level': 20} on 2 hosts
2020-04-25 13:39:33,115 -  nornir.core -     INFO -        run() - Running task 'napalm_get' with args {'getters': ['config'], 'severity_level': 20} on 2 hosts
2020-04-25 13:40:09,995 -  nornir.core -     INFO -        run() - Running task 'napalm_get' with args {'getters': ['config'], 'retrieve': 'all', 'severity_level': 20} on 2 hosts
2020-04-25 13:41:16,811 -  nornir.core -     INFO -        run() - Running task 'napalm_get' with args {'getters': ['config', 'interfaces'], 'getters_options': {'config': {'retrieve': 'all'}}, 'retrieve': 'all', 'severity_level': 20} on 2 hosts
2020-04-25 13:41:17,448 - nornir.core.task -    ERROR -      start() - Host 'r1': task 'napalm_get' failed with traceback:
Traceback (most recent call last):
  File "/home/gns3/.local/lib/python3.6/site-packages/nornir/core/task.py", line 85, in start
    r = self.task(self, **self.params)
  File "/home/gns3/.local/lib/python3.6/site-packages/nornir/plugins/tasks/networking/napalm_get.py", line 61, in napalm_get
    result[g] = method(**options)
TypeError: get_interfaces() got an unexpected keyword argument 'retrieve'

2020-04-25 13:41:17,545 - nornir.core.task -    ERROR -      start() - Host 'r2': task 'napalm_get' failed with traceback:
Traceback (most recent call last):
  File "/home/gns3/.local/lib/python3.6/site-packages/nornir/core/task.py", line 85, in start
    r = self.task(self, **self.params)
  File "/home/gns3/.local/lib/python3.6/site-packages/nornir/plugins/tasks/networking/napalm_get.py", line 61, in napalm_get
    result[g] = method(**options)
TypeError: get_interfaces() got an unexpected keyword argument 'retrieve'

2020-04-25 13:41:33,938 -  nornir.core -     INFO -        run() - Running task 'napalm_get' with args {'getters': ['config', 'interfaces'], 'getters_options': {'config': {'retrieve': 'all'}}, 'severity_level': 20} on 2 hosts
2020-04-25 14:07:07,050 -  nornir.core -     INFO -        run() - Running task 'napalm_get' with args {'getters': ['interfaces'], 'severity_level': 20} on 2 hosts
2020-04-25 14:07:58,358 -  nornir.core -     INFO -        run() - Running task 'napalm_get' with args {'getters': ['factsinterfaces'], 'severity_level': 20} on 2 hosts
2020-04-25 14:07:58,804 - nornir.core.task -    ERROR -      start() - Host 'r1': task 'napalm_get' failed with traceback:
Traceback (most recent call last):
  File "/home/gns3/.local/lib/python3.6/site-packages/nornir/core/task.py", line 85, in start
    r = self.task(self, **self.params)
  File "/home/gns3/.local/lib/python3.6/site-packages/nornir/plugins/tasks/networking/napalm_get.py", line 60, in napalm_get
    method = getattr(device, getter)
AttributeError: 'JunOSDriver' object has no attribute 'get_factsinterfaces'

2020-04-25 14:07:58,807 - nornir.core.task -    ERROR -      start() - Host 'r2': task 'napalm_get' failed with traceback:
Traceback (most recent call last):
  File "/home/gns3/.local/lib/python3.6/site-packages/nornir/core/task.py", line 85, in start
    r = self.task(self, **self.params)
  File "/home/gns3/.local/lib/python3.6/site-packages/nornir/plugins/tasks/networking/napalm_get.py", line 60, in napalm_get
    method = getattr(device, getter)
AttributeError: 'JunOSDriver' object has no attribute 'get_factsinterfaces'

2020-04-25 14:08:11,459 -  nornir.core -     INFO -        run() - Running task 'napalm_get' with args {'getters': ['facts', 'interfaces'], 'severity_level': 20} on 2 hosts
2020-04-25 14:11:35,629 -  nornir.core -     INFO -        run() - Running task 'napalm_get' with args {'getters': ['arp_table']} on 2 hosts
2020-04-25 14:12:29,427 -  nornir.core -     INFO -        run() - Running task 'napalm_get' with args {'getters': ['interfaces_ip']} on 2 hosts
2020-04-25 14:14:22,367 -  nornir.core -     INFO -        run() - Running task 'napalm_get' with args {'getters': ['interfaces_ip']} on 2 hosts
2020-04-25 14:14:22,974 -  nornir.core -     INFO -        run() - Running task 'napalm_get' with args {'getters': ['interfaces_ip']} on 1 hosts
2020-04-25 14:19:26,054 -  nornir.core -     INFO -        run() - Running task 'napalm_get' with args {'getters': ['users']} on 2 hosts
2020-04-25 14:19:26,610 - nornir.core.task -    ERROR -      start() - Host 'r1': task 'napalm_get' failed with traceback:
Traceback (most recent call last):
  File "/home/gns3/.local/lib/python3.6/site-packages/nornir/core/task.py", line 85, in start
    r = self.task(self, **self.params)
  File "/home/gns3/.local/lib/python3.6/site-packages/nornir/plugins/tasks/networking/napalm_get.py", line 61, in napalm_get
    result[g] = method(**options)
  File "/home/gns3/.local/lib/python3.6/site-packages/napalm/junos/junos.py", line 2116, in get_users
    root_user = self._get_root()
  File "/home/gns3/.local/lib/python3.6/site-packages/napalm/junos/junos.py", line 2081, in _get_root
    root_items = root_table.items()
  File "/home/gns3/.local/lib/python3.6/site-packages/jnpr/junos/factory/table.py", line 174, in items
    return list(zip(self.keys(), self.values()))
  File "/home/gns3/.local/lib/python3.6/site-packages/jnpr/junos/factory/table.py", line 150, in keys
    self._key_list = self._keys()
  File "/home/gns3/.local/lib/python3.6/site-packages/jnpr/junos/factory/table.py", line 134, in _keys
    return self._keys_simple(xpath + '/' + key_value)
  File "/home/gns3/.local/lib/python3.6/site-packages/jnpr/junos/factory/table.py", line 105, in _keys_simple
    return [x.text.strip() for x in self.xml.xpath(xpath)]
  File "/home/gns3/.local/lib/python3.6/site-packages/jnpr/junos/factory/table.py", line 105, in <listcomp>
    return [x.text.strip() for x in self.xml.xpath(xpath)]
AttributeError: 'NoneType' object has no attribute 'strip'

2020-04-25 14:19:26,708 - nornir.core.task -    ERROR -      start() - Host 'r2': task 'napalm_get' failed with traceback:
Traceback (most recent call last):
  File "/home/gns3/.local/lib/python3.6/site-packages/nornir/core/task.py", line 85, in start
    r = self.task(self, **self.params)
  File "/home/gns3/.local/lib/python3.6/site-packages/nornir/plugins/tasks/networking/napalm_get.py", line 61, in napalm_get
    result[g] = method(**options)
  File "/home/gns3/.local/lib/python3.6/site-packages/napalm/junos/junos.py", line 2116, in get_users
    root_user = self._get_root()
  File "/home/gns3/.local/lib/python3.6/site-packages/napalm/junos/junos.py", line 2081, in _get_root
    root_items = root_table.items()
  File "/home/gns3/.local/lib/python3.6/site-packages/jnpr/junos/factory/table.py", line 174, in items
    return list(zip(self.keys(), self.values()))
  File "/home/gns3/.local/lib/python3.6/site-packages/jnpr/junos/factory/table.py", line 150, in keys
    self._key_list = self._keys()
  File "/home/gns3/.local/lib/python3.6/site-packages/jnpr/junos/factory/table.py", line 134, in _keys
    return self._keys_simple(xpath + '/' + key_value)
  File "/home/gns3/.local/lib/python3.6/site-packages/jnpr/junos/factory/table.py", line 105, in _keys_simple
    return [x.text.strip() for x in self.xml.xpath(xpath)]
  File "/home/gns3/.local/lib/python3.6/site-packages/jnpr/junos/factory/table.py", line 105, in <listcomp>
    return [x.text.strip() for x in self.xml.xpath(xpath)]
AttributeError: 'NoneType' object has no attribute 'strip'

2020-04-25 14:19:26,709 -  nornir.core -     INFO -        run() - Running task 'napalm_get' with args {'getters': ['users']} on 1 hosts
2020-04-25 14:20:05,856 -  nornir.core -     INFO -        run() - Running task 'napalm_get' with args {'getters': ['users']} on 2 hosts
2020-04-25 14:20:06,447 - nornir.core.task -    ERROR -      start() - Host 'r2': task 'napalm_get' failed with traceback:
Traceback (most recent call last):
  File "/home/gns3/.local/lib/python3.6/site-packages/nornir/core/task.py", line 85, in start
    r = self.task(self, **self.params)
  File "/home/gns3/.local/lib/python3.6/site-packages/nornir/plugins/tasks/networking/napalm_get.py", line 61, in napalm_get
    result[g] = method(**options)
  File "/home/gns3/.local/lib/python3.6/site-packages/napalm/junos/junos.py", line 2116, in get_users
    root_user = self._get_root()
  File "/home/gns3/.local/lib/python3.6/site-packages/napalm/junos/junos.py", line 2081, in _get_root
    root_items = root_table.items()
  File "/home/gns3/.local/lib/python3.6/site-packages/jnpr/junos/factory/table.py", line 174, in items
    return list(zip(self.keys(), self.values()))
  File "/home/gns3/.local/lib/python3.6/site-packages/jnpr/junos/factory/table.py", line 150, in keys
    self._key_list = self._keys()
  File "/home/gns3/.local/lib/python3.6/site-packages/jnpr/junos/factory/table.py", line 134, in _keys
    return self._keys_simple(xpath + '/' + key_value)
  File "/home/gns3/.local/lib/python3.6/site-packages/jnpr/junos/factory/table.py", line 105, in _keys_simple
    return [x.text.strip() for x in self.xml.xpath(xpath)]
  File "/home/gns3/.local/lib/python3.6/site-packages/jnpr/junos/factory/table.py", line 105, in <listcomp>
    return [x.text.strip() for x in self.xml.xpath(xpath)]
AttributeError: 'NoneType' object has no attribute 'strip'

2020-04-25 14:20:06,501 - nornir.core.task -    ERROR -      start() - Host 'r1': task 'napalm_get' failed with traceback:
Traceback (most recent call last):
  File "/home/gns3/.local/lib/python3.6/site-packages/nornir/core/task.py", line 85, in start
    r = self.task(self, **self.params)
  File "/home/gns3/.local/lib/python3.6/site-packages/nornir/plugins/tasks/networking/napalm_get.py", line 61, in napalm_get
    result[g] = method(**options)
  File "/home/gns3/.local/lib/python3.6/site-packages/napalm/junos/junos.py", line 2116, in get_users
    root_user = self._get_root()
  File "/home/gns3/.local/lib/python3.6/site-packages/napalm/junos/junos.py", line 2081, in _get_root
    root_items = root_table.items()
  File "/home/gns3/.local/lib/python3.6/site-packages/jnpr/junos/factory/table.py", line 174, in items
    return list(zip(self.keys(), self.values()))
  File "/home/gns3/.local/lib/python3.6/site-packages/jnpr/junos/factory/table.py", line 150, in keys
    self._key_list = self._keys()
  File "/home/gns3/.local/lib/python3.6/site-packages/jnpr/junos/factory/table.py", line 134, in _keys
    return self._keys_simple(xpath + '/' + key_value)
  File "/home/gns3/.local/lib/python3.6/site-packages/jnpr/junos/factory/table.py", line 105, in _keys_simple
    return [x.text.strip() for x in self.xml.xpath(xpath)]
  File "/home/gns3/.local/lib/python3.6/site-packages/jnpr/junos/factory/table.py", line 105, in <listcomp>
    return [x.text.strip() for x in self.xml.xpath(xpath)]
AttributeError: 'NoneType' object has no attribute 'strip'

2020-04-25 14:20:06,501 -  nornir.core -     INFO -        run() - Running task 'napalm_get' with args {'getters': ['users']} on 1 hosts
2020-04-25 14:33:26,285 -  nornir.core -     INFO -        run() - Running task 'napalm_get' with args {'getters': ['interfaces_ip']} on 2 hosts
2020-04-25 14:33:26,973 -  nornir.core -     INFO -        run() - Running task 'napalm_get' with args {'getters': ['interfaces_ip']} on 1 hosts
